[2024-11-27 01:37:51,685][flwr][WARNING] - Both server and strategy were provided, ignoring strategy
[2024-11-27 01:37:51,685][flwr][INFO] - Starting Flower simulation, config: ServerConfig(num_rounds=30, round_timeout=None)
[2024-11-27 01:37:56,929][flwr][INFO] - Flower VCE: Ray initialized with resources: {'node:__internal_head__': 1.0, 'memory': 7116494439.0, 'accelerator_type:G': 1.0, 'GPU': 1.0, 'CPU': 12.0, 'node:192.168.1.62': 1.0, 'object_store_memory': 3558247219.0}
[2024-11-27 01:37:56,929][flwr][INFO] - Flower VCE: Resources for each Virtual Client: {'num_cpus': 4, 'num_gpus': 0.3}
[2024-11-27 01:37:56,939][flwr][INFO] - Flower VCE: Creating VirtualClientEngineActorPool with 3 actors
[2024-11-27 01:37:56,939][flwr][INFO] - Initializing global parameters
[2024-11-27 01:37:56,939][flwr][INFO] - Requesting initial parameters from one random client
[2024-11-27 01:38:01,762][flwr][INFO] - Received initial parameters from one random client
[2024-11-27 01:38:01,762][flwr][INFO] - Evaluating initial parameters
[2024-11-27 01:38:05,825][flwr][INFO] - initial parameters (loss, other metrics): 0.6997896017030228, {'accuracy': 0.46511627906976744}
[2024-11-27 01:38:05,825][flwr][INFO] - FL starting
[2024-11-27 01:38:05,825][flwr][DEBUG] - fit_round 1: strategy sampled 6 clients (out of 60)
[2024-11-27 01:38:17,954][flwr][DEBUG] - fit_round 1 received 6 results and 0 failures
[2024-11-27 01:38:18,135][flwr][WARNING] - No fit_metrics_aggregation_fn provided
[2024-11-27 01:38:22,553][flwr][INFO] - fit progress: (1, 0.7065572923468065, {'accuracy': 0.46511627906976744}, 16.72808632899978)
[2024-11-27 01:38:22,554][flwr][INFO] - evaluate_round 1: no clients selected, cancel
[2024-11-27 01:38:22,555][flwr][DEBUG] - fit_round 2: strategy sampled 6 clients (out of 60)
[2024-11-27 01:38:25,564][flwr][ERROR] - Traceback (most recent call last):
  File "/home/namvq/.cache/pypoetry/virtualenvs/niid-bench-orV17zke-py3.10/lib/python3.10/site-packages/flwr/simulation/ray_transport/ray_client_proxy.py", line 140, in _submit_job
    res = self.actor_pool.get_client_result(self.cid, timeout)
  File "/home/namvq/.cache/pypoetry/virtualenvs/niid-bench-orV17zke-py3.10/lib/python3.10/site-packages/flwr/simulation/ray_transport/ray_actor.py", line 402, in get_client_result
    return self._fetch_future_result(cid)
  File "/home/namvq/.cache/pypoetry/virtualenvs/niid-bench-orV17zke-py3.10/lib/python3.10/site-packages/flwr/simulation/ray_transport/ray_actor.py", line 288, in _fetch_future_result
    res_cid, res = ray.get(future)  # type: (str, ClientRes)
  File "/home/namvq/.cache/pypoetry/virtualenvs/niid-bench-orV17zke-py3.10/lib/python3.10/site-packages/ray/_private/auto_init_hook.py", line 24, in auto_init_wrapper
    return fn(*args, **kwargs)
  File "/home/namvq/.cache/pypoetry/virtualenvs/niid-bench-orV17zke-py3.10/lib/python3.10/site-packages/ray/_private/client_mode_hook.py", line 103, in wrapper
    return func(*args, **kwargs)
  File "/home/namvq/.cache/pypoetry/virtualenvs/niid-bench-orV17zke-py3.10/lib/python3.10/site-packages/ray/_private/worker.py", line 2524, in get
    raise value.as_instanceof_cause()
ray.exceptions.RayTaskError(ClientException): [36mray::DefaultActor.run()[39m (pid=20997, ip=192.168.1.62, actor_id=60eef54d0d630c807d62aaa901000000, repr=<flwr.simulation.ray_transport.ray_actor.DefaultActor object at 0x71e1a159f0d0>)
  File "/home/namvq/.cache/pypoetry/virtualenvs/niid-bench-orV17zke-py3.10/lib/python3.10/site-packages/flwr/simulation/ray_transport/ray_client_proxy.py", line 196, in fit
    return maybe_call_fit(
  File "/home/namvq/.cache/pypoetry/virtualenvs/niid-bench-orV17zke-py3.10/lib/python3.10/site-packages/flwr/client/client.py", line 217, in maybe_call_fit
    return client.fit(fit_ins)
  File "/home/namvq/.cache/pypoetry/virtualenvs/niid-bench-orV17zke-py3.10/lib/python3.10/site-packages/flwr/client/app.py", line 333, in _fit
    results = self.numpy_client.fit(parameters, ins.config)  # type: ignore
  File "/media/namvq/Data/code_flwr/niid_bench/niid_bench/client_fedavg.py", line 55, in fit
    train_fedavg(
  File "/media/namvq/Data/code_flwr/niid_bench/niid_bench/models.py", line 279, in train_fedavg
    net = _train_one_epoch(net, trainloader, device, criterion, optimizer)
  File "/media/namvq/Data/code_flwr/niid_bench/niid_bench/models.py", line 295, in _train_one_epoch
    loss.backward()
  File "/home/namvq/.cache/pypoetry/virtualenvs/niid-bench-orV17zke-py3.10/lib/python3.10/site-packages/torch/_tensor.py", line 396, in backward
    torch.autograd.backward(self, gradient, retain_graph, create_graph, inputs=inputs)
  File "/home/namvq/.cache/pypoetry/virtualenvs/niid-bench-orV17zke-py3.10/lib/python3.10/site-packages/torch/autograd/__init__.py", line 173, in backward
    Variable._execution_engine.run_backward(  # Calls into the C++ engine to run the backward pass
RuntimeError: CUDA out of memory. Tried to allocate 2.00 MiB (GPU 0; 3.81 GiB total capacity; 189.17 MiB already allocated; 7.00 MiB free; 232.00 MiB reserved in total by PyTorch) If reserved memory is >> allocated memory try setting max_split_size_mb to avoid fragmentation.  See documentation for Memory Management and PYTORCH_CUDA_ALLOC_CONF

The above exception was the direct cause of the following exception:

[36mray::DefaultActor.run()[39m (pid=20997, ip=192.168.1.62, actor_id=60eef54d0d630c807d62aaa901000000, repr=<flwr.simulation.ray_transport.ray_actor.DefaultActor object at 0x71e1a159f0d0>)
  File "/home/namvq/.cache/pypoetry/virtualenvs/niid-bench-orV17zke-py3.10/lib/python3.10/site-packages/flwr/simulation/ray_transport/ray_actor.py", line 72, in run
    raise ClientException(str(message)) from ex
flwr.simulation.ray_transport.ray_actor.ClientException: 
>>>>>>>A ClientException occurred.('\n\tSomething went wrong when running your client workload.\n\tClient 2 crashed when the DefaultActor was running its workload.\n\tException triggered on the client side: Traceback (most recent call last):\n  File "/home/namvq/.cache/pypoetry/virtualenvs/niid-bench-orV17zke-py3.10/lib/python3.10/site-packages/flwr/simulation/ray_transport/ray_actor.py", line 60, in run\n    job_results = job_fn()\n  File "/home/namvq/.cache/pypoetry/virtualenvs/niid-bench-orV17zke-py3.10/lib/python3.10/site-packages/flwr/simulation/ray_transport/ray_client_proxy.py", line 196, in fit\n    return maybe_call_fit(\n  File "/home/namvq/.cache/pypoetry/virtualenvs/niid-bench-orV17zke-py3.10/lib/python3.10/site-packages/flwr/client/client.py", line 217, in maybe_call_fit\n    return client.fit(fit_ins)\n  File "/home/namvq/.cache/pypoetry/virtualenvs/niid-bench-orV17zke-py3.10/lib/python3.10/site-packages/flwr/client/app.py", line 333, in _fit\n    results = self.numpy_client.fit(parameters, ins.config)  # type: ignore\n  File "/media/namvq/Data/code_flwr/niid_bench/niid_bench/client_fedavg.py", line 55, in fit\n    train_fedavg(\n  File "/media/namvq/Data/code_flwr/niid_bench/niid_bench/models.py", line 279, in train_fedavg\n    net = _train_one_epoch(net, trainloader, device, criterion, optimizer)\n  File "/media/namvq/Data/code_flwr/niid_bench/niid_bench/models.py", line 295, in _train_one_epoch\n    loss.backward()\n  File "/home/namvq/.cache/pypoetry/virtualenvs/niid-bench-orV17zke-py3.10/lib/python3.10/site-packages/torch/_tensor.py", line 396, in backward\n    torch.autograd.backward(self, gradient, retain_graph, create_graph, inputs=inputs)\n  File "/home/namvq/.cache/pypoetry/virtualenvs/niid-bench-orV17zke-py3.10/lib/python3.10/site-packages/torch/autograd/__init__.py", line 173, in backward\n    Variable._execution_engine.run_backward(  # Calls into the C++ engine to run the backward pass\nRuntimeError: CUDA out of memory. Tried to allocate 2.00 MiB (GPU 0; 3.81 GiB total capacity; 189.17 MiB already allocated; 7.00 MiB free; 232.00 MiB reserved in total by PyTorch) If reserved memory is >> allocated memory try setting max_split_size_mb to avoid fragmentation.  See documentation for Memory Management and PYTORCH_CUDA_ALLOC_CONF\n',)

[2024-11-27 01:38:25,565][flwr][ERROR] - [36mray::DefaultActor.run()[39m (pid=20997, ip=192.168.1.62, actor_id=60eef54d0d630c807d62aaa901000000, repr=<flwr.simulation.ray_transport.ray_actor.DefaultActor object at 0x71e1a159f0d0>)
  File "/home/namvq/.cache/pypoetry/virtualenvs/niid-bench-orV17zke-py3.10/lib/python3.10/site-packages/flwr/simulation/ray_transport/ray_client_proxy.py", line 196, in fit
    return maybe_call_fit(
  File "/home/namvq/.cache/pypoetry/virtualenvs/niid-bench-orV17zke-py3.10/lib/python3.10/site-packages/flwr/client/client.py", line 217, in maybe_call_fit
    return client.fit(fit_ins)
  File "/home/namvq/.cache/pypoetry/virtualenvs/niid-bench-orV17zke-py3.10/lib/python3.10/site-packages/flwr/client/app.py", line 333, in _fit
    results = self.numpy_client.fit(parameters, ins.config)  # type: ignore
  File "/media/namvq/Data/code_flwr/niid_bench/niid_bench/client_fedavg.py", line 55, in fit
    train_fedavg(
  File "/media/namvq/Data/code_flwr/niid_bench/niid_bench/models.py", line 279, in train_fedavg
    net = _train_one_epoch(net, trainloader, device, criterion, optimizer)
  File "/media/namvq/Data/code_flwr/niid_bench/niid_bench/models.py", line 295, in _train_one_epoch
    loss.backward()
  File "/home/namvq/.cache/pypoetry/virtualenvs/niid-bench-orV17zke-py3.10/lib/python3.10/site-packages/torch/_tensor.py", line 396, in backward
    torch.autograd.backward(self, gradient, retain_graph, create_graph, inputs=inputs)
  File "/home/namvq/.cache/pypoetry/virtualenvs/niid-bench-orV17zke-py3.10/lib/python3.10/site-packages/torch/autograd/__init__.py", line 173, in backward
    Variable._execution_engine.run_backward(  # Calls into the C++ engine to run the backward pass
RuntimeError: CUDA out of memory. Tried to allocate 2.00 MiB (GPU 0; 3.81 GiB total capacity; 189.17 MiB already allocated; 7.00 MiB free; 232.00 MiB reserved in total by PyTorch) If reserved memory is >> allocated memory try setting max_split_size_mb to avoid fragmentation.  See documentation for Memory Management and PYTORCH_CUDA_ALLOC_CONF

The above exception was the direct cause of the following exception:

[36mray::DefaultActor.run()[39m (pid=20997, ip=192.168.1.62, actor_id=60eef54d0d630c807d62aaa901000000, repr=<flwr.simulation.ray_transport.ray_actor.DefaultActor object at 0x71e1a159f0d0>)
  File "/home/namvq/.cache/pypoetry/virtualenvs/niid-bench-orV17zke-py3.10/lib/python3.10/site-packages/flwr/simulation/ray_transport/ray_actor.py", line 72, in run
    raise ClientException(str(message)) from ex
flwr.simulation.ray_transport.ray_actor.ClientException: 
>>>>>>>A ClientException occurred.('\n\tSomething went wrong when running your client workload.\n\tClient 2 crashed when the DefaultActor was running its workload.\n\tException triggered on the client side: Traceback (most recent call last):\n  File "/home/namvq/.cache/pypoetry/virtualenvs/niid-bench-orV17zke-py3.10/lib/python3.10/site-packages/flwr/simulation/ray_transport/ray_actor.py", line 60, in run\n    job_results = job_fn()\n  File "/home/namvq/.cache/pypoetry/virtualenvs/niid-bench-orV17zke-py3.10/lib/python3.10/site-packages/flwr/simulation/ray_transport/ray_client_proxy.py", line 196, in fit\n    return maybe_call_fit(\n  File "/home/namvq/.cache/pypoetry/virtualenvs/niid-bench-orV17zke-py3.10/lib/python3.10/site-packages/flwr/client/client.py", line 217, in maybe_call_fit\n    return client.fit(fit_ins)\n  File "/home/namvq/.cache/pypoetry/virtualenvs/niid-bench-orV17zke-py3.10/lib/python3.10/site-packages/flwr/client/app.py", line 333, in _fit\n    results = self.numpy_client.fit(parameters, ins.config)  # type: ignore\n  File "/media/namvq/Data/code_flwr/niid_bench/niid_bench/client_fedavg.py", line 55, in fit\n    train_fedavg(\n  File "/media/namvq/Data/code_flwr/niid_bench/niid_bench/models.py", line 279, in train_fedavg\n    net = _train_one_epoch(net, trainloader, device, criterion, optimizer)\n  File "/media/namvq/Data/code_flwr/niid_bench/niid_bench/models.py", line 295, in _train_one_epoch\n    loss.backward()\n  File "/home/namvq/.cache/pypoetry/virtualenvs/niid-bench-orV17zke-py3.10/lib/python3.10/site-packages/torch/_tensor.py", line 396, in backward\n    torch.autograd.backward(self, gradient, retain_graph, create_graph, inputs=inputs)\n  File "/home/namvq/.cache/pypoetry/virtualenvs/niid-bench-orV17zke-py3.10/lib/python3.10/site-packages/torch/autograd/__init__.py", line 173, in backward\n    Variable._execution_engine.run_backward(  # Calls into the C++ engine to run the backward pass\nRuntimeError: CUDA out of memory. Tried to allocate 2.00 MiB (GPU 0; 3.81 GiB total capacity; 189.17 MiB already allocated; 7.00 MiB free; 232.00 MiB reserved in total by PyTorch) If reserved memory is >> allocated memory try setting max_split_size_mb to avoid fragmentation.  See documentation for Memory Management and PYTORCH_CUDA_ALLOC_CONF\n',)
