[2024-11-19 00:41:21,426][flwr][WARNING] - Both server and strategy were provided, ignoring strategy
[2024-11-19 00:41:21,427][flwr][INFO] - Starting Flower simulation, config: ServerConfig(num_rounds=1, round_timeout=None)
[2024-11-19 00:41:27,134][flwr][INFO] - Flower VCE: Ray initialized with resources: {'CPU': 12.0, 'GPU': 1.0, 'accelerator_type:G': 1.0, 'object_store_memory': 3385426329.0, 'node:192.168.1.29': 1.0, 'node:__internal_head__': 1.0, 'memory': 6770852660.0}
[2024-11-19 00:41:27,134][flwr][INFO] - Flower VCE: Resources for each Virtual Client: {'num_cpus': 4, 'num_gpus': 0}
[2024-11-19 00:41:27,143][flwr][INFO] - Flower VCE: Creating VirtualClientEngineActorPool with 3 actors
[2024-11-19 00:41:27,143][flwr][INFO] - Initializing global parameters
[2024-11-19 00:41:27,143][flwr][INFO] - Requesting initial parameters from one random client
[2024-11-19 00:41:29,419][flwr][INFO] - Received initial parameters from one random client
[2024-11-19 00:41:29,446][flwr][INFO] - Evaluating initial parameters
[2024-11-19 00:41:41,897][flwr][INFO] - initial parameters (loss, other metrics): 0.8026784459749857, {'accuracy': 0.3173076923076923}
[2024-11-19 00:41:41,897][flwr][INFO] - FL starting
[2024-11-19 00:41:41,951][flwr][DEBUG] - fit_round 1: strategy sampled 10 clients (out of 20)
[2024-11-19 00:41:43,329][flwr][ERROR] - Traceback (most recent call last):
  File "/home/namvq/.cache/pypoetry/virtualenvs/niid-bench-orV17zke-py3.10/lib/python3.10/site-packages/flwr/simulation/ray_transport/ray_client_proxy.py", line 140, in _submit_job
    res = self.actor_pool.get_client_result(self.cid, timeout)
  File "/home/namvq/.cache/pypoetry/virtualenvs/niid-bench-orV17zke-py3.10/lib/python3.10/site-packages/flwr/simulation/ray_transport/ray_actor.py", line 402, in get_client_result
    return self._fetch_future_result(cid)
  File "/home/namvq/.cache/pypoetry/virtualenvs/niid-bench-orV17zke-py3.10/lib/python3.10/site-packages/flwr/simulation/ray_transport/ray_actor.py", line 288, in _fetch_future_result
    res_cid, res = ray.get(future)  # type: (str, ClientRes)
  File "/home/namvq/.cache/pypoetry/virtualenvs/niid-bench-orV17zke-py3.10/lib/python3.10/site-packages/ray/_private/auto_init_hook.py", line 24, in auto_init_wrapper
    return fn(*args, **kwargs)
  File "/home/namvq/.cache/pypoetry/virtualenvs/niid-bench-orV17zke-py3.10/lib/python3.10/site-packages/ray/_private/client_mode_hook.py", line 103, in wrapper
    return func(*args, **kwargs)
  File "/home/namvq/.cache/pypoetry/virtualenvs/niid-bench-orV17zke-py3.10/lib/python3.10/site-packages/ray/_private/worker.py", line 2524, in get
    raise value.as_instanceof_cause()
ray.exceptions.RayTaskError(ClientException): [36mray::DefaultActor.run()[39m (pid=25350, ip=192.168.1.29, actor_id=077df88ce403c97b122daa2401000000, repr=<flwr.simulation.ray_transport.ray_actor.DefaultActor object at 0x75b8f0116dd0>)
  File "/home/namvq/.cache/pypoetry/virtualenvs/niid-bench-orV17zke-py3.10/lib/python3.10/site-packages/flwr/simulation/ray_transport/ray_client_proxy.py", line 196, in fit
    return maybe_call_fit(
  File "/home/namvq/.cache/pypoetry/virtualenvs/niid-bench-orV17zke-py3.10/lib/python3.10/site-packages/flwr/client/client.py", line 217, in maybe_call_fit
    return client.fit(fit_ins)
  File "/home/namvq/.cache/pypoetry/virtualenvs/niid-bench-orV17zke-py3.10/lib/python3.10/site-packages/flwr/client/app.py", line 333, in _fit
    results = self.numpy_client.fit(parameters, ins.config)  # type: ignore
  File "/media/namvq/Data/code_flwr/niid_bench/niid_bench/client_scaffold.py", line 78, in fit
    train_scaffold(
  File "/media/namvq/Data/code_flwr/niid_bench/niid_bench/models.py", line 146, in train_scaffold
    net = _train_one_epoch_scaffold(
  File "/media/namvq/Data/code_flwr/niid_bench/niid_bench/models.py", line 168, in _train_one_epoch_scaffold
    optimizer.step_custom(server_cv, client_cv)
  File "/media/namvq/Data/code_flwr/niid_bench/niid_bench/models.py", line 98, in step_custom
    par.data.add_(s_cv - c_cv, alpha=-group["lr"])
RuntimeError: The size of tensor a (1280) must match the size of tensor b (3) at non-singleton dimension 3

The above exception was the direct cause of the following exception:

[36mray::DefaultActor.run()[39m (pid=25350, ip=192.168.1.29, actor_id=077df88ce403c97b122daa2401000000, repr=<flwr.simulation.ray_transport.ray_actor.DefaultActor object at 0x75b8f0116dd0>)
  File "/home/namvq/.cache/pypoetry/virtualenvs/niid-bench-orV17zke-py3.10/lib/python3.10/site-packages/flwr/simulation/ray_transport/ray_actor.py", line 72, in run
    raise ClientException(str(message)) from ex
flwr.simulation.ray_transport.ray_actor.ClientException: 
>>>>>>>A ClientException occurred.('\n\tSomething went wrong when running your client workload.\n\tClient 10 crashed when the DefaultActor was running its workload.\n\tException triggered on the client side: Traceback (most recent call last):\n  File "/home/namvq/.cache/pypoetry/virtualenvs/niid-bench-orV17zke-py3.10/lib/python3.10/site-packages/flwr/simulation/ray_transport/ray_actor.py", line 60, in run\n    job_results = job_fn()\n  File "/home/namvq/.cache/pypoetry/virtualenvs/niid-bench-orV17zke-py3.10/lib/python3.10/site-packages/flwr/simulation/ray_transport/ray_client_proxy.py", line 196, in fit\n    return maybe_call_fit(\n  File "/home/namvq/.cache/pypoetry/virtualenvs/niid-bench-orV17zke-py3.10/lib/python3.10/site-packages/flwr/client/client.py", line 217, in maybe_call_fit\n    return client.fit(fit_ins)\n  File "/home/namvq/.cache/pypoetry/virtualenvs/niid-bench-orV17zke-py3.10/lib/python3.10/site-packages/flwr/client/app.py", line 333, in _fit\n    results = self.numpy_client.fit(parameters, ins.config)  # type: ignore\n  File "/media/namvq/Data/code_flwr/niid_bench/niid_bench/client_scaffold.py", line 78, in fit\n    train_scaffold(\n  File "/media/namvq/Data/code_flwr/niid_bench/niid_bench/models.py", line 146, in train_scaffold\n    net = _train_one_epoch_scaffold(\n  File "/media/namvq/Data/code_flwr/niid_bench/niid_bench/models.py", line 168, in _train_one_epoch_scaffold\n    optimizer.step_custom(server_cv, client_cv)\n  File "/media/namvq/Data/code_flwr/niid_bench/niid_bench/models.py", line 98, in step_custom\n    par.data.add_(s_cv - c_cv, alpha=-group["lr"])\nRuntimeError: The size of tensor a (1280) must match the size of tensor b (3) at non-singleton dimension 3\n',)

[2024-11-19 00:41:43,330][flwr][ERROR] - [36mray::DefaultActor.run()[39m (pid=25350, ip=192.168.1.29, actor_id=077df88ce403c97b122daa2401000000, repr=<flwr.simulation.ray_transport.ray_actor.DefaultActor object at 0x75b8f0116dd0>)
  File "/home/namvq/.cache/pypoetry/virtualenvs/niid-bench-orV17zke-py3.10/lib/python3.10/site-packages/flwr/simulation/ray_transport/ray_client_proxy.py", line 196, in fit
    return maybe_call_fit(
  File "/home/namvq/.cache/pypoetry/virtualenvs/niid-bench-orV17zke-py3.10/lib/python3.10/site-packages/flwr/client/client.py", line 217, in maybe_call_fit
    return client.fit(fit_ins)
  File "/home/namvq/.cache/pypoetry/virtualenvs/niid-bench-orV17zke-py3.10/lib/python3.10/site-packages/flwr/client/app.py", line 333, in _fit
    results = self.numpy_client.fit(parameters, ins.config)  # type: ignore
  File "/media/namvq/Data/code_flwr/niid_bench/niid_bench/client_scaffold.py", line 78, in fit
    train_scaffold(
  File "/media/namvq/Data/code_flwr/niid_bench/niid_bench/models.py", line 146, in train_scaffold
    net = _train_one_epoch_scaffold(
  File "/media/namvq/Data/code_flwr/niid_bench/niid_bench/models.py", line 168, in _train_one_epoch_scaffold
    optimizer.step_custom(server_cv, client_cv)
  File "/media/namvq/Data/code_flwr/niid_bench/niid_bench/models.py", line 98, in step_custom
    par.data.add_(s_cv - c_cv, alpha=-group["lr"])
RuntimeError: The size of tensor a (1280) must match the size of tensor b (3) at non-singleton dimension 3

The above exception was the direct cause of the following exception:

[36mray::DefaultActor.run()[39m (pid=25350, ip=192.168.1.29, actor_id=077df88ce403c97b122daa2401000000, repr=<flwr.simulation.ray_transport.ray_actor.DefaultActor object at 0x75b8f0116dd0>)
  File "/home/namvq/.cache/pypoetry/virtualenvs/niid-bench-orV17zke-py3.10/lib/python3.10/site-packages/flwr/simulation/ray_transport/ray_actor.py", line 72, in run
    raise ClientException(str(message)) from ex
flwr.simulation.ray_transport.ray_actor.ClientException: 
>>>>>>>A ClientException occurred.('\n\tSomething went wrong when running your client workload.\n\tClient 10 crashed when the DefaultActor was running its workload.\n\tException triggered on the client side: Traceback (most recent call last):\n  File "/home/namvq/.cache/pypoetry/virtualenvs/niid-bench-orV17zke-py3.10/lib/python3.10/site-packages/flwr/simulation/ray_transport/ray_actor.py", line 60, in run\n    job_results = job_fn()\n  File "/home/namvq/.cache/pypoetry/virtualenvs/niid-bench-orV17zke-py3.10/lib/python3.10/site-packages/flwr/simulation/ray_transport/ray_client_proxy.py", line 196, in fit\n    return maybe_call_fit(\n  File "/home/namvq/.cache/pypoetry/virtualenvs/niid-bench-orV17zke-py3.10/lib/python3.10/site-packages/flwr/client/client.py", line 217, in maybe_call_fit\n    return client.fit(fit_ins)\n  File "/home/namvq/.cache/pypoetry/virtualenvs/niid-bench-orV17zke-py3.10/lib/python3.10/site-packages/flwr/client/app.py", line 333, in _fit\n    results = self.numpy_client.fit(parameters, ins.config)  # type: ignore\n  File "/media/namvq/Data/code_flwr/niid_bench/niid_bench/client_scaffold.py", line 78, in fit\n    train_scaffold(\n  File "/media/namvq/Data/code_flwr/niid_bench/niid_bench/models.py", line 146, in train_scaffold\n    net = _train_one_epoch_scaffold(\n  File "/media/namvq/Data/code_flwr/niid_bench/niid_bench/models.py", line 168, in _train_one_epoch_scaffold\n    optimizer.step_custom(server_cv, client_cv)\n  File "/media/namvq/Data/code_flwr/niid_bench/niid_bench/models.py", line 98, in step_custom\n    par.data.add_(s_cv - c_cv, alpha=-group["lr"])\nRuntimeError: The size of tensor a (1280) must match the size of tensor b (3) at non-singleton dimension 3\n',)
[2024-11-19 00:41:44,683][flwr][ERROR] - Traceback (most recent call last):
  File "/home/namvq/.cache/pypoetry/virtualenvs/niid-bench-orV17zke-py3.10/lib/python3.10/site-packages/flwr/simulation/ray_transport/ray_client_proxy.py", line 140, in _submit_job
    res = self.actor_pool.get_client_result(self.cid, timeout)
  File "/home/namvq/.cache/pypoetry/virtualenvs/niid-bench-orV17zke-py3.10/lib/python3.10/site-packages/flwr/simulation/ray_transport/ray_actor.py", line 402, in get_client_result
    return self._fetch_future_result(cid)
  File "/home/namvq/.cache/pypoetry/virtualenvs/niid-bench-orV17zke-py3.10/lib/python3.10/site-packages/flwr/simulation/ray_transport/ray_actor.py", line 288, in _fetch_future_result
    res_cid, res = ray.get(future)  # type: (str, ClientRes)
  File "/home/namvq/.cache/pypoetry/virtualenvs/niid-bench-orV17zke-py3.10/lib/python3.10/site-packages/ray/_private/auto_init_hook.py", line 24, in auto_init_wrapper
    return fn(*args, **kwargs)
  File "/home/namvq/.cache/pypoetry/virtualenvs/niid-bench-orV17zke-py3.10/lib/python3.10/site-packages/ray/_private/client_mode_hook.py", line 103, in wrapper
    return func(*args, **kwargs)
  File "/home/namvq/.cache/pypoetry/virtualenvs/niid-bench-orV17zke-py3.10/lib/python3.10/site-packages/ray/_private/worker.py", line 2524, in get
    raise value.as_instanceof_cause()
ray.exceptions.RayTaskError(ClientException): [36mray::DefaultActor.run()[39m (pid=25350, ip=192.168.1.29, actor_id=077df88ce403c97b122daa2401000000, repr=<flwr.simulation.ray_transport.ray_actor.DefaultActor object at 0x75b8f0116dd0>)
  File "/home/namvq/.cache/pypoetry/virtualenvs/niid-bench-orV17zke-py3.10/lib/python3.10/site-packages/flwr/simulation/ray_transport/ray_client_proxy.py", line 196, in fit
    return maybe_call_fit(
  File "/home/namvq/.cache/pypoetry/virtualenvs/niid-bench-orV17zke-py3.10/lib/python3.10/site-packages/flwr/client/client.py", line 217, in maybe_call_fit
    return client.fit(fit_ins)
  File "/home/namvq/.cache/pypoetry/virtualenvs/niid-bench-orV17zke-py3.10/lib/python3.10/site-packages/flwr/client/app.py", line 333, in _fit
    results = self.numpy_client.fit(parameters, ins.config)  # type: ignore
  File "/media/namvq/Data/code_flwr/niid_bench/niid_bench/client_scaffold.py", line 78, in fit
    train_scaffold(
  File "/media/namvq/Data/code_flwr/niid_bench/niid_bench/models.py", line 146, in train_scaffold
    net = _train_one_epoch_scaffold(
  File "/media/namvq/Data/code_flwr/niid_bench/niid_bench/models.py", line 168, in _train_one_epoch_scaffold
    optimizer.step_custom(server_cv, client_cv)
  File "/media/namvq/Data/code_flwr/niid_bench/niid_bench/models.py", line 98, in step_custom
    par.data.add_(s_cv - c_cv, alpha=-group["lr"])
RuntimeError: The size of tensor a (1280) must match the size of tensor b (3) at non-singleton dimension 3

The above exception was the direct cause of the following exception:

[36mray::DefaultActor.run()[39m (pid=25350, ip=192.168.1.29, actor_id=077df88ce403c97b122daa2401000000, repr=<flwr.simulation.ray_transport.ray_actor.DefaultActor object at 0x75b8f0116dd0>)
  File "/home/namvq/.cache/pypoetry/virtualenvs/niid-bench-orV17zke-py3.10/lib/python3.10/site-packages/flwr/simulation/ray_transport/ray_actor.py", line 72, in run
    raise ClientException(str(message)) from ex
flwr.simulation.ray_transport.ray_actor.ClientException: 
>>>>>>>A ClientException occurred.('\n\tSomething went wrong when running your client workload.\n\tClient 4 crashed when the DefaultActor was running its workload.\n\tException triggered on the client side: Traceback (most recent call last):\n  File "/home/namvq/.cache/pypoetry/virtualenvs/niid-bench-orV17zke-py3.10/lib/python3.10/site-packages/flwr/simulation/ray_transport/ray_actor.py", line 60, in run\n    job_results = job_fn()\n  File "/home/namvq/.cache/pypoetry/virtualenvs/niid-bench-orV17zke-py3.10/lib/python3.10/site-packages/flwr/simulation/ray_transport/ray_client_proxy.py", line 196, in fit\n    return maybe_call_fit(\n  File "/home/namvq/.cache/pypoetry/virtualenvs/niid-bench-orV17zke-py3.10/lib/python3.10/site-packages/flwr/client/client.py", line 217, in maybe_call_fit\n    return client.fit(fit_ins)\n  File "/home/namvq/.cache/pypoetry/virtualenvs/niid-bench-orV17zke-py3.10/lib/python3.10/site-packages/flwr/client/app.py", line 333, in _fit\n    results = self.numpy_client.fit(parameters, ins.config)  # type: ignore\n  File "/media/namvq/Data/code_flwr/niid_bench/niid_bench/client_scaffold.py", line 78, in fit\n    train_scaffold(\n  File "/media/namvq/Data/code_flwr/niid_bench/niid_bench/models.py", line 146, in train_scaffold\n    net = _train_one_epoch_scaffold(\n  File "/media/namvq/Data/code_flwr/niid_bench/niid_bench/models.py", line 168, in _train_one_epoch_scaffold\n    optimizer.step_custom(server_cv, client_cv)\n  File "/media/namvq/Data/code_flwr/niid_bench/niid_bench/models.py", line 98, in step_custom\n    par.data.add_(s_cv - c_cv, alpha=-group["lr"])\nRuntimeError: The size of tensor a (1280) must match the size of tensor b (3) at non-singleton dimension 3\n',)

[2024-11-19 00:41:44,687][flwr][ERROR] - [36mray::DefaultActor.run()[39m (pid=25350, ip=192.168.1.29, actor_id=077df88ce403c97b122daa2401000000, repr=<flwr.simulation.ray_transport.ray_actor.DefaultActor object at 0x75b8f0116dd0>)
  File "/home/namvq/.cache/pypoetry/virtualenvs/niid-bench-orV17zke-py3.10/lib/python3.10/site-packages/flwr/simulation/ray_transport/ray_client_proxy.py", line 196, in fit
    return maybe_call_fit(
  File "/home/namvq/.cache/pypoetry/virtualenvs/niid-bench-orV17zke-py3.10/lib/python3.10/site-packages/flwr/client/client.py", line 217, in maybe_call_fit
    return client.fit(fit_ins)
  File "/home/namvq/.cache/pypoetry/virtualenvs/niid-bench-orV17zke-py3.10/lib/python3.10/site-packages/flwr/client/app.py", line 333, in _fit
    results = self.numpy_client.fit(parameters, ins.config)  # type: ignore
  File "/media/namvq/Data/code_flwr/niid_bench/niid_bench/client_scaffold.py", line 78, in fit
    train_scaffold(
  File "/media/namvq/Data/code_flwr/niid_bench/niid_bench/models.py", line 146, in train_scaffold
    net = _train_one_epoch_scaffold(
  File "/media/namvq/Data/code_flwr/niid_bench/niid_bench/models.py", line 168, in _train_one_epoch_scaffold
    optimizer.step_custom(server_cv, client_cv)
  File "/media/namvq/Data/code_flwr/niid_bench/niid_bench/models.py", line 98, in step_custom
    par.data.add_(s_cv - c_cv, alpha=-group["lr"])
RuntimeError: The size of tensor a (1280) must match the size of tensor b (3) at non-singleton dimension 3

The above exception was the direct cause of the following exception:

[36mray::DefaultActor.run()[39m (pid=25350, ip=192.168.1.29, actor_id=077df88ce403c97b122daa2401000000, repr=<flwr.simulation.ray_transport.ray_actor.DefaultActor object at 0x75b8f0116dd0>)
  File "/home/namvq/.cache/pypoetry/virtualenvs/niid-bench-orV17zke-py3.10/lib/python3.10/site-packages/flwr/simulation/ray_transport/ray_actor.py", line 72, in run
    raise ClientException(str(message)) from ex
flwr.simulation.ray_transport.ray_actor.ClientException: 
>>>>>>>A ClientException occurred.('\n\tSomething went wrong when running your client workload.\n\tClient 4 crashed when the DefaultActor was running its workload.\n\tException triggered on the client side: Traceback (most recent call last):\n  File "/home/namvq/.cache/pypoetry/virtualenvs/niid-bench-orV17zke-py3.10/lib/python3.10/site-packages/flwr/simulation/ray_transport/ray_actor.py", line 60, in run\n    job_results = job_fn()\n  File "/home/namvq/.cache/pypoetry/virtualenvs/niid-bench-orV17zke-py3.10/lib/python3.10/site-packages/flwr/simulation/ray_transport/ray_client_proxy.py", line 196, in fit\n    return maybe_call_fit(\n  File "/home/namvq/.cache/pypoetry/virtualenvs/niid-bench-orV17zke-py3.10/lib/python3.10/site-packages/flwr/client/client.py", line 217, in maybe_call_fit\n    return client.fit(fit_ins)\n  File "/home/namvq/.cache/pypoetry/virtualenvs/niid-bench-orV17zke-py3.10/lib/python3.10/site-packages/flwr/client/app.py", line 333, in _fit\n    results = self.numpy_client.fit(parameters, ins.config)  # type: ignore\n  File "/media/namvq/Data/code_flwr/niid_bench/niid_bench/client_scaffold.py", line 78, in fit\n    train_scaffold(\n  File "/media/namvq/Data/code_flwr/niid_bench/niid_bench/models.py", line 146, in train_scaffold\n    net = _train_one_epoch_scaffold(\n  File "/media/namvq/Data/code_flwr/niid_bench/niid_bench/models.py", line 168, in _train_one_epoch_scaffold\n    optimizer.step_custom(server_cv, client_cv)\n  File "/media/namvq/Data/code_flwr/niid_bench/niid_bench/models.py", line 98, in step_custom\n    par.data.add_(s_cv - c_cv, alpha=-group["lr"])\nRuntimeError: The size of tensor a (1280) must match the size of tensor b (3) at non-singleton dimension 3\n',)
[2024-11-19 00:41:45,157][flwr][ERROR] - Traceback (most recent call last):
  File "/home/namvq/.cache/pypoetry/virtualenvs/niid-bench-orV17zke-py3.10/lib/python3.10/site-packages/flwr/simulation/ray_transport/ray_client_proxy.py", line 140, in _submit_job
    res = self.actor_pool.get_client_result(self.cid, timeout)
  File "/home/namvq/.cache/pypoetry/virtualenvs/niid-bench-orV17zke-py3.10/lib/python3.10/site-packages/flwr/simulation/ray_transport/ray_actor.py", line 402, in get_client_result
    return self._fetch_future_result(cid)
  File "/home/namvq/.cache/pypoetry/virtualenvs/niid-bench-orV17zke-py3.10/lib/python3.10/site-packages/flwr/simulation/ray_transport/ray_actor.py", line 288, in _fetch_future_result
    res_cid, res = ray.get(future)  # type: (str, ClientRes)
  File "/home/namvq/.cache/pypoetry/virtualenvs/niid-bench-orV17zke-py3.10/lib/python3.10/site-packages/ray/_private/auto_init_hook.py", line 24, in auto_init_wrapper
    return fn(*args, **kwargs)
  File "/home/namvq/.cache/pypoetry/virtualenvs/niid-bench-orV17zke-py3.10/lib/python3.10/site-packages/ray/_private/client_mode_hook.py", line 103, in wrapper
    return func(*args, **kwargs)
  File "/home/namvq/.cache/pypoetry/virtualenvs/niid-bench-orV17zke-py3.10/lib/python3.10/site-packages/ray/_private/worker.py", line 2524, in get
    raise value.as_instanceof_cause()
ray.exceptions.RayTaskError(ClientException): [36mray::DefaultActor.run()[39m (pid=25349, ip=192.168.1.29, actor_id=a184125d4faa0cad36fe8dc001000000, repr=<flwr.simulation.ray_transport.ray_actor.DefaultActor object at 0x7dab9199ae60>)
  File "/home/namvq/.cache/pypoetry/virtualenvs/niid-bench-orV17zke-py3.10/lib/python3.10/site-packages/flwr/simulation/ray_transport/ray_client_proxy.py", line 196, in fit
    return maybe_call_fit(
  File "/home/namvq/.cache/pypoetry/virtualenvs/niid-bench-orV17zke-py3.10/lib/python3.10/site-packages/flwr/client/client.py", line 217, in maybe_call_fit
    return client.fit(fit_ins)
  File "/home/namvq/.cache/pypoetry/virtualenvs/niid-bench-orV17zke-py3.10/lib/python3.10/site-packages/flwr/client/app.py", line 333, in _fit
    results = self.numpy_client.fit(parameters, ins.config)  # type: ignore
  File "/media/namvq/Data/code_flwr/niid_bench/niid_bench/client_scaffold.py", line 78, in fit
    train_scaffold(
  File "/media/namvq/Data/code_flwr/niid_bench/niid_bench/models.py", line 146, in train_scaffold
    net = _train_one_epoch_scaffold(
  File "/media/namvq/Data/code_flwr/niid_bench/niid_bench/models.py", line 168, in _train_one_epoch_scaffold
    optimizer.step_custom(server_cv, client_cv)
  File "/media/namvq/Data/code_flwr/niid_bench/niid_bench/models.py", line 98, in step_custom
    par.data.add_(s_cv - c_cv, alpha=-group["lr"])
RuntimeError: The size of tensor a (1280) must match the size of tensor b (3) at non-singleton dimension 3

The above exception was the direct cause of the following exception:

[36mray::DefaultActor.run()[39m (pid=25349, ip=192.168.1.29, actor_id=a184125d4faa0cad36fe8dc001000000, repr=<flwr.simulation.ray_transport.ray_actor.DefaultActor object at 0x7dab9199ae60>)
  File "/home/namvq/.cache/pypoetry/virtualenvs/niid-bench-orV17zke-py3.10/lib/python3.10/site-packages/flwr/simulation/ray_transport/ray_actor.py", line 72, in run
    raise ClientException(str(message)) from ex
flwr.simulation.ray_transport.ray_actor.ClientException: 
>>>>>>>A ClientException occurred.('\n\tSomething went wrong when running your client workload.\n\tClient 1 crashed when the DefaultActor was running its workload.\n\tException triggered on the client side: Traceback (most recent call last):\n  File "/home/namvq/.cache/pypoetry/virtualenvs/niid-bench-orV17zke-py3.10/lib/python3.10/site-packages/flwr/simulation/ray_transport/ray_actor.py", line 60, in run\n    job_results = job_fn()\n  File "/home/namvq/.cache/pypoetry/virtualenvs/niid-bench-orV17zke-py3.10/lib/python3.10/site-packages/flwr/simulation/ray_transport/ray_client_proxy.py", line 196, in fit\n    return maybe_call_fit(\n  File "/home/namvq/.cache/pypoetry/virtualenvs/niid-bench-orV17zke-py3.10/lib/python3.10/site-packages/flwr/client/client.py", line 217, in maybe_call_fit\n    return client.fit(fit_ins)\n  File "/home/namvq/.cache/pypoetry/virtualenvs/niid-bench-orV17zke-py3.10/lib/python3.10/site-packages/flwr/client/app.py", line 333, in _fit\n    results = self.numpy_client.fit(parameters, ins.config)  # type: ignore\n  File "/media/namvq/Data/code_flwr/niid_bench/niid_bench/client_scaffold.py", line 78, in fit\n    train_scaffold(\n  File "/media/namvq/Data/code_flwr/niid_bench/niid_bench/models.py", line 146, in train_scaffold\n    net = _train_one_epoch_scaffold(\n  File "/media/namvq/Data/code_flwr/niid_bench/niid_bench/models.py", line 168, in _train_one_epoch_scaffold\n    optimizer.step_custom(server_cv, client_cv)\n  File "/media/namvq/Data/code_flwr/niid_bench/niid_bench/models.py", line 98, in step_custom\n    par.data.add_(s_cv - c_cv, alpha=-group["lr"])\nRuntimeError: The size of tensor a (1280) must match the size of tensor b (3) at non-singleton dimension 3\n',)

[2024-11-19 00:41:45,157][flwr][ERROR] - [36mray::DefaultActor.run()[39m (pid=25349, ip=192.168.1.29, actor_id=a184125d4faa0cad36fe8dc001000000, repr=<flwr.simulation.ray_transport.ray_actor.DefaultActor object at 0x7dab9199ae60>)
  File "/home/namvq/.cache/pypoetry/virtualenvs/niid-bench-orV17zke-py3.10/lib/python3.10/site-packages/flwr/simulation/ray_transport/ray_client_proxy.py", line 196, in fit
    return maybe_call_fit(
  File "/home/namvq/.cache/pypoetry/virtualenvs/niid-bench-orV17zke-py3.10/lib/python3.10/site-packages/flwr/client/client.py", line 217, in maybe_call_fit
    return client.fit(fit_ins)
  File "/home/namvq/.cache/pypoetry/virtualenvs/niid-bench-orV17zke-py3.10/lib/python3.10/site-packages/flwr/client/app.py", line 333, in _fit
    results = self.numpy_client.fit(parameters, ins.config)  # type: ignore
  File "/media/namvq/Data/code_flwr/niid_bench/niid_bench/client_scaffold.py", line 78, in fit
    train_scaffold(
  File "/media/namvq/Data/code_flwr/niid_bench/niid_bench/models.py", line 146, in train_scaffold
    net = _train_one_epoch_scaffold(
  File "/media/namvq/Data/code_flwr/niid_bench/niid_bench/models.py", line 168, in _train_one_epoch_scaffold
    optimizer.step_custom(server_cv, client_cv)
  File "/media/namvq/Data/code_flwr/niid_bench/niid_bench/models.py", line 98, in step_custom
    par.data.add_(s_cv - c_cv, alpha=-group["lr"])
RuntimeError: The size of tensor a (1280) must match the size of tensor b (3) at non-singleton dimension 3

The above exception was the direct cause of the following exception:

[36mray::DefaultActor.run()[39m (pid=25349, ip=192.168.1.29, actor_id=a184125d4faa0cad36fe8dc001000000, repr=<flwr.simulation.ray_transport.ray_actor.DefaultActor object at 0x7dab9199ae60>)
  File "/home/namvq/.cache/pypoetry/virtualenvs/niid-bench-orV17zke-py3.10/lib/python3.10/site-packages/flwr/simulation/ray_transport/ray_actor.py", line 72, in run
    raise ClientException(str(message)) from ex
flwr.simulation.ray_transport.ray_actor.ClientException: 
>>>>>>>A ClientException occurred.('\n\tSomething went wrong when running your client workload.\n\tClient 1 crashed when the DefaultActor was running its workload.\n\tException triggered on the client side: Traceback (most recent call last):\n  File "/home/namvq/.cache/pypoetry/virtualenvs/niid-bench-orV17zke-py3.10/lib/python3.10/site-packages/flwr/simulation/ray_transport/ray_actor.py", line 60, in run\n    job_results = job_fn()\n  File "/home/namvq/.cache/pypoetry/virtualenvs/niid-bench-orV17zke-py3.10/lib/python3.10/site-packages/flwr/simulation/ray_transport/ray_client_proxy.py", line 196, in fit\n    return maybe_call_fit(\n  File "/home/namvq/.cache/pypoetry/virtualenvs/niid-bench-orV17zke-py3.10/lib/python3.10/site-packages/flwr/client/client.py", line 217, in maybe_call_fit\n    return client.fit(fit_ins)\n  File "/home/namvq/.cache/pypoetry/virtualenvs/niid-bench-orV17zke-py3.10/lib/python3.10/site-packages/flwr/client/app.py", line 333, in _fit\n    results = self.numpy_client.fit(parameters, ins.config)  # type: ignore\n  File "/media/namvq/Data/code_flwr/niid_bench/niid_bench/client_scaffold.py", line 78, in fit\n    train_scaffold(\n  File "/media/namvq/Data/code_flwr/niid_bench/niid_bench/models.py", line 146, in train_scaffold\n    net = _train_one_epoch_scaffold(\n  File "/media/namvq/Data/code_flwr/niid_bench/niid_bench/models.py", line 168, in _train_one_epoch_scaffold\n    optimizer.step_custom(server_cv, client_cv)\n  File "/media/namvq/Data/code_flwr/niid_bench/niid_bench/models.py", line 98, in step_custom\n    par.data.add_(s_cv - c_cv, alpha=-group["lr"])\nRuntimeError: The size of tensor a (1280) must match the size of tensor b (3) at non-singleton dimension 3\n',)
[2024-11-19 00:41:45,261][flwr][ERROR] - Traceback (most recent call last):
  File "/home/namvq/.cache/pypoetry/virtualenvs/niid-bench-orV17zke-py3.10/lib/python3.10/site-packages/flwr/simulation/ray_transport/ray_client_proxy.py", line 140, in _submit_job
    res = self.actor_pool.get_client_result(self.cid, timeout)
  File "/home/namvq/.cache/pypoetry/virtualenvs/niid-bench-orV17zke-py3.10/lib/python3.10/site-packages/flwr/simulation/ray_transport/ray_actor.py", line 402, in get_client_result
    return self._fetch_future_result(cid)
  File "/home/namvq/.cache/pypoetry/virtualenvs/niid-bench-orV17zke-py3.10/lib/python3.10/site-packages/flwr/simulation/ray_transport/ray_actor.py", line 288, in _fetch_future_result
    res_cid, res = ray.get(future)  # type: (str, ClientRes)
  File "/home/namvq/.cache/pypoetry/virtualenvs/niid-bench-orV17zke-py3.10/lib/python3.10/site-packages/ray/_private/auto_init_hook.py", line 24, in auto_init_wrapper
    return fn(*args, **kwargs)
  File "/home/namvq/.cache/pypoetry/virtualenvs/niid-bench-orV17zke-py3.10/lib/python3.10/site-packages/ray/_private/client_mode_hook.py", line 103, in wrapper
    return func(*args, **kwargs)
  File "/home/namvq/.cache/pypoetry/virtualenvs/niid-bench-orV17zke-py3.10/lib/python3.10/site-packages/ray/_private/worker.py", line 2524, in get
    raise value.as_instanceof_cause()
ray.exceptions.RayTaskError(ClientException): [36mray::DefaultActor.run()[39m (pid=25348, ip=192.168.1.29, actor_id=9fe6e3fbd5ce6028ac1aedb801000000, repr=<flwr.simulation.ray_transport.ray_actor.DefaultActor object at 0x7125e499ae60>)
  File "/home/namvq/.cache/pypoetry/virtualenvs/niid-bench-orV17zke-py3.10/lib/python3.10/site-packages/flwr/simulation/ray_transport/ray_client_proxy.py", line 196, in fit
    return maybe_call_fit(
  File "/home/namvq/.cache/pypoetry/virtualenvs/niid-bench-orV17zke-py3.10/lib/python3.10/site-packages/flwr/client/client.py", line 217, in maybe_call_fit
    return client.fit(fit_ins)
  File "/home/namvq/.cache/pypoetry/virtualenvs/niid-bench-orV17zke-py3.10/lib/python3.10/site-packages/flwr/client/app.py", line 333, in _fit
    results = self.numpy_client.fit(parameters, ins.config)  # type: ignore
  File "/media/namvq/Data/code_flwr/niid_bench/niid_bench/client_scaffold.py", line 78, in fit
    train_scaffold(
  File "/media/namvq/Data/code_flwr/niid_bench/niid_bench/models.py", line 146, in train_scaffold
    net = _train_one_epoch_scaffold(
  File "/media/namvq/Data/code_flwr/niid_bench/niid_bench/models.py", line 168, in _train_one_epoch_scaffold
    optimizer.step_custom(server_cv, client_cv)
  File "/media/namvq/Data/code_flwr/niid_bench/niid_bench/models.py", line 98, in step_custom
    par.data.add_(s_cv - c_cv, alpha=-group["lr"])
RuntimeError: The size of tensor a (1280) must match the size of tensor b (3) at non-singleton dimension 3

The above exception was the direct cause of the following exception:

[36mray::DefaultActor.run()[39m (pid=25348, ip=192.168.1.29, actor_id=9fe6e3fbd5ce6028ac1aedb801000000, repr=<flwr.simulation.ray_transport.ray_actor.DefaultActor object at 0x7125e499ae60>)
  File "/home/namvq/.cache/pypoetry/virtualenvs/niid-bench-orV17zke-py3.10/lib/python3.10/site-packages/flwr/simulation/ray_transport/ray_actor.py", line 72, in run
    raise ClientException(str(message)) from ex
flwr.simulation.ray_transport.ray_actor.ClientException: 
>>>>>>>A ClientException occurred.('\n\tSomething went wrong when running your client workload.\n\tClient 8 crashed when the DefaultActor was running its workload.\n\tException triggered on the client side: Traceback (most recent call last):\n  File "/home/namvq/.cache/pypoetry/virtualenvs/niid-bench-orV17zke-py3.10/lib/python3.10/site-packages/flwr/simulation/ray_transport/ray_actor.py", line 60, in run\n    job_results = job_fn()\n  File "/home/namvq/.cache/pypoetry/virtualenvs/niid-bench-orV17zke-py3.10/lib/python3.10/site-packages/flwr/simulation/ray_transport/ray_client_proxy.py", line 196, in fit\n    return maybe_call_fit(\n  File "/home/namvq/.cache/pypoetry/virtualenvs/niid-bench-orV17zke-py3.10/lib/python3.10/site-packages/flwr/client/client.py", line 217, in maybe_call_fit\n    return client.fit(fit_ins)\n  File "/home/namvq/.cache/pypoetry/virtualenvs/niid-bench-orV17zke-py3.10/lib/python3.10/site-packages/flwr/client/app.py", line 333, in _fit\n    results = self.numpy_client.fit(parameters, ins.config)  # type: ignore\n  File "/media/namvq/Data/code_flwr/niid_bench/niid_bench/client_scaffold.py", line 78, in fit\n    train_scaffold(\n  File "/media/namvq/Data/code_flwr/niid_bench/niid_bench/models.py", line 146, in train_scaffold\n    net = _train_one_epoch_scaffold(\n  File "/media/namvq/Data/code_flwr/niid_bench/niid_bench/models.py", line 168, in _train_one_epoch_scaffold\n    optimizer.step_custom(server_cv, client_cv)\n  File "/media/namvq/Data/code_flwr/niid_bench/niid_bench/models.py", line 98, in step_custom\n    par.data.add_(s_cv - c_cv, alpha=-group["lr"])\nRuntimeError: The size of tensor a (1280) must match the size of tensor b (3) at non-singleton dimension 3\n',)

[2024-11-19 00:41:45,261][flwr][ERROR] - [36mray::DefaultActor.run()[39m (pid=25348, ip=192.168.1.29, actor_id=9fe6e3fbd5ce6028ac1aedb801000000, repr=<flwr.simulation.ray_transport.ray_actor.DefaultActor object at 0x7125e499ae60>)
  File "/home/namvq/.cache/pypoetry/virtualenvs/niid-bench-orV17zke-py3.10/lib/python3.10/site-packages/flwr/simulation/ray_transport/ray_client_proxy.py", line 196, in fit
    return maybe_call_fit(
  File "/home/namvq/.cache/pypoetry/virtualenvs/niid-bench-orV17zke-py3.10/lib/python3.10/site-packages/flwr/client/client.py", line 217, in maybe_call_fit
    return client.fit(fit_ins)
  File "/home/namvq/.cache/pypoetry/virtualenvs/niid-bench-orV17zke-py3.10/lib/python3.10/site-packages/flwr/client/app.py", line 333, in _fit
    results = self.numpy_client.fit(parameters, ins.config)  # type: ignore
  File "/media/namvq/Data/code_flwr/niid_bench/niid_bench/client_scaffold.py", line 78, in fit
    train_scaffold(
  File "/media/namvq/Data/code_flwr/niid_bench/niid_bench/models.py", line 146, in train_scaffold
    net = _train_one_epoch_scaffold(
  File "/media/namvq/Data/code_flwr/niid_bench/niid_bench/models.py", line 168, in _train_one_epoch_scaffold
    optimizer.step_custom(server_cv, client_cv)
  File "/media/namvq/Data/code_flwr/niid_bench/niid_bench/models.py", line 98, in step_custom
    par.data.add_(s_cv - c_cv, alpha=-group["lr"])
RuntimeError: The size of tensor a (1280) must match the size of tensor b (3) at non-singleton dimension 3

The above exception was the direct cause of the following exception:

[36mray::DefaultActor.run()[39m (pid=25348, ip=192.168.1.29, actor_id=9fe6e3fbd5ce6028ac1aedb801000000, repr=<flwr.simulation.ray_transport.ray_actor.DefaultActor object at 0x7125e499ae60>)
  File "/home/namvq/.cache/pypoetry/virtualenvs/niid-bench-orV17zke-py3.10/lib/python3.10/site-packages/flwr/simulation/ray_transport/ray_actor.py", line 72, in run
    raise ClientException(str(message)) from ex
flwr.simulation.ray_transport.ray_actor.ClientException: 
>>>>>>>A ClientException occurred.('\n\tSomething went wrong when running your client workload.\n\tClient 8 crashed when the DefaultActor was running its workload.\n\tException triggered on the client side: Traceback (most recent call last):\n  File "/home/namvq/.cache/pypoetry/virtualenvs/niid-bench-orV17zke-py3.10/lib/python3.10/site-packages/flwr/simulation/ray_transport/ray_actor.py", line 60, in run\n    job_results = job_fn()\n  File "/home/namvq/.cache/pypoetry/virtualenvs/niid-bench-orV17zke-py3.10/lib/python3.10/site-packages/flwr/simulation/ray_transport/ray_client_proxy.py", line 196, in fit\n    return maybe_call_fit(\n  File "/home/namvq/.cache/pypoetry/virtualenvs/niid-bench-orV17zke-py3.10/lib/python3.10/site-packages/flwr/client/client.py", line 217, in maybe_call_fit\n    return client.fit(fit_ins)\n  File "/home/namvq/.cache/pypoetry/virtualenvs/niid-bench-orV17zke-py3.10/lib/python3.10/site-packages/flwr/client/app.py", line 333, in _fit\n    results = self.numpy_client.fit(parameters, ins.config)  # type: ignore\n  File "/media/namvq/Data/code_flwr/niid_bench/niid_bench/client_scaffold.py", line 78, in fit\n    train_scaffold(\n  File "/media/namvq/Data/code_flwr/niid_bench/niid_bench/models.py", line 146, in train_scaffold\n    net = _train_one_epoch_scaffold(\n  File "/media/namvq/Data/code_flwr/niid_bench/niid_bench/models.py", line 168, in _train_one_epoch_scaffold\n    optimizer.step_custom(server_cv, client_cv)\n  File "/media/namvq/Data/code_flwr/niid_bench/niid_bench/models.py", line 98, in step_custom\n    par.data.add_(s_cv - c_cv, alpha=-group["lr"])\nRuntimeError: The size of tensor a (1280) must match the size of tensor b (3) at non-singleton dimension 3\n',)
[2024-11-19 00:41:46,460][flwr][ERROR] - Traceback (most recent call last):
  File "/home/namvq/.cache/pypoetry/virtualenvs/niid-bench-orV17zke-py3.10/lib/python3.10/site-packages/flwr/simulation/ray_transport/ray_client_proxy.py", line 140, in _submit_job
    res = self.actor_pool.get_client_result(self.cid, timeout)
  File "/home/namvq/.cache/pypoetry/virtualenvs/niid-bench-orV17zke-py3.10/lib/python3.10/site-packages/flwr/simulation/ray_transport/ray_actor.py", line 402, in get_client_result
    return self._fetch_future_result(cid)
  File "/home/namvq/.cache/pypoetry/virtualenvs/niid-bench-orV17zke-py3.10/lib/python3.10/site-packages/flwr/simulation/ray_transport/ray_actor.py", line 288, in _fetch_future_result
    res_cid, res = ray.get(future)  # type: (str, ClientRes)
  File "/home/namvq/.cache/pypoetry/virtualenvs/niid-bench-orV17zke-py3.10/lib/python3.10/site-packages/ray/_private/auto_init_hook.py", line 24, in auto_init_wrapper
    return fn(*args, **kwargs)
  File "/home/namvq/.cache/pypoetry/virtualenvs/niid-bench-orV17zke-py3.10/lib/python3.10/site-packages/ray/_private/client_mode_hook.py", line 103, in wrapper
    return func(*args, **kwargs)
  File "/home/namvq/.cache/pypoetry/virtualenvs/niid-bench-orV17zke-py3.10/lib/python3.10/site-packages/ray/_private/worker.py", line 2524, in get
    raise value.as_instanceof_cause()
ray.exceptions.RayTaskError(ClientException): [36mray::DefaultActor.run()[39m (pid=25350, ip=192.168.1.29, actor_id=077df88ce403c97b122daa2401000000, repr=<flwr.simulation.ray_transport.ray_actor.DefaultActor object at 0x75b8f0116dd0>)
  File "/home/namvq/.cache/pypoetry/virtualenvs/niid-bench-orV17zke-py3.10/lib/python3.10/site-packages/flwr/simulation/ray_transport/ray_client_proxy.py", line 196, in fit
    return maybe_call_fit(
  File "/home/namvq/.cache/pypoetry/virtualenvs/niid-bench-orV17zke-py3.10/lib/python3.10/site-packages/flwr/client/client.py", line 217, in maybe_call_fit
    return client.fit(fit_ins)
  File "/home/namvq/.cache/pypoetry/virtualenvs/niid-bench-orV17zke-py3.10/lib/python3.10/site-packages/flwr/client/app.py", line 333, in _fit
    results = self.numpy_client.fit(parameters, ins.config)  # type: ignore
  File "/media/namvq/Data/code_flwr/niid_bench/niid_bench/client_scaffold.py", line 78, in fit
    train_scaffold(
  File "/media/namvq/Data/code_flwr/niid_bench/niid_bench/models.py", line 146, in train_scaffold
    net = _train_one_epoch_scaffold(
  File "/media/namvq/Data/code_flwr/niid_bench/niid_bench/models.py", line 168, in _train_one_epoch_scaffold
    optimizer.step_custom(server_cv, client_cv)
  File "/media/namvq/Data/code_flwr/niid_bench/niid_bench/models.py", line 98, in step_custom
    par.data.add_(s_cv - c_cv, alpha=-group["lr"])
RuntimeError: The size of tensor a (1280) must match the size of tensor b (3) at non-singleton dimension 3

The above exception was the direct cause of the following exception:

[36mray::DefaultActor.run()[39m (pid=25350, ip=192.168.1.29, actor_id=077df88ce403c97b122daa2401000000, repr=<flwr.simulation.ray_transport.ray_actor.DefaultActor object at 0x75b8f0116dd0>)
  File "/home/namvq/.cache/pypoetry/virtualenvs/niid-bench-orV17zke-py3.10/lib/python3.10/site-packages/flwr/simulation/ray_transport/ray_actor.py", line 72, in run
    raise ClientException(str(message)) from ex
flwr.simulation.ray_transport.ray_actor.ClientException: 
>>>>>>>A ClientException occurred.('\n\tSomething went wrong when running your client workload.\n\tClient 18 crashed when the DefaultActor was running its workload.\n\tException triggered on the client side: Traceback (most recent call last):\n  File "/home/namvq/.cache/pypoetry/virtualenvs/niid-bench-orV17zke-py3.10/lib/python3.10/site-packages/flwr/simulation/ray_transport/ray_actor.py", line 60, in run\n    job_results = job_fn()\n  File "/home/namvq/.cache/pypoetry/virtualenvs/niid-bench-orV17zke-py3.10/lib/python3.10/site-packages/flwr/simulation/ray_transport/ray_client_proxy.py", line 196, in fit\n    return maybe_call_fit(\n  File "/home/namvq/.cache/pypoetry/virtualenvs/niid-bench-orV17zke-py3.10/lib/python3.10/site-packages/flwr/client/client.py", line 217, in maybe_call_fit\n    return client.fit(fit_ins)\n  File "/home/namvq/.cache/pypoetry/virtualenvs/niid-bench-orV17zke-py3.10/lib/python3.10/site-packages/flwr/client/app.py", line 333, in _fit\n    results = self.numpy_client.fit(parameters, ins.config)  # type: ignore\n  File "/media/namvq/Data/code_flwr/niid_bench/niid_bench/client_scaffold.py", line 78, in fit\n    train_scaffold(\n  File "/media/namvq/Data/code_flwr/niid_bench/niid_bench/models.py", line 146, in train_scaffold\n    net = _train_one_epoch_scaffold(\n  File "/media/namvq/Data/code_flwr/niid_bench/niid_bench/models.py", line 168, in _train_one_epoch_scaffold\n    optimizer.step_custom(server_cv, client_cv)\n  File "/media/namvq/Data/code_flwr/niid_bench/niid_bench/models.py", line 98, in step_custom\n    par.data.add_(s_cv - c_cv, alpha=-group["lr"])\nRuntimeError: The size of tensor a (1280) must match the size of tensor b (3) at non-singleton dimension 3\n',)

[2024-11-19 00:41:46,461][flwr][ERROR] - [36mray::DefaultActor.run()[39m (pid=25350, ip=192.168.1.29, actor_id=077df88ce403c97b122daa2401000000, repr=<flwr.simulation.ray_transport.ray_actor.DefaultActor object at 0x75b8f0116dd0>)
  File "/home/namvq/.cache/pypoetry/virtualenvs/niid-bench-orV17zke-py3.10/lib/python3.10/site-packages/flwr/simulation/ray_transport/ray_client_proxy.py", line 196, in fit
    return maybe_call_fit(
  File "/home/namvq/.cache/pypoetry/virtualenvs/niid-bench-orV17zke-py3.10/lib/python3.10/site-packages/flwr/client/client.py", line 217, in maybe_call_fit
    return client.fit(fit_ins)
  File "/home/namvq/.cache/pypoetry/virtualenvs/niid-bench-orV17zke-py3.10/lib/python3.10/site-packages/flwr/client/app.py", line 333, in _fit
    results = self.numpy_client.fit(parameters, ins.config)  # type: ignore
  File "/media/namvq/Data/code_flwr/niid_bench/niid_bench/client_scaffold.py", line 78, in fit
    train_scaffold(
  File "/media/namvq/Data/code_flwr/niid_bench/niid_bench/models.py", line 146, in train_scaffold
    net = _train_one_epoch_scaffold(
  File "/media/namvq/Data/code_flwr/niid_bench/niid_bench/models.py", line 168, in _train_one_epoch_scaffold
    optimizer.step_custom(server_cv, client_cv)
  File "/media/namvq/Data/code_flwr/niid_bench/niid_bench/models.py", line 98, in step_custom
    par.data.add_(s_cv - c_cv, alpha=-group["lr"])
RuntimeError: The size of tensor a (1280) must match the size of tensor b (3) at non-singleton dimension 3

The above exception was the direct cause of the following exception:

[36mray::DefaultActor.run()[39m (pid=25350, ip=192.168.1.29, actor_id=077df88ce403c97b122daa2401000000, repr=<flwr.simulation.ray_transport.ray_actor.DefaultActor object at 0x75b8f0116dd0>)
  File "/home/namvq/.cache/pypoetry/virtualenvs/niid-bench-orV17zke-py3.10/lib/python3.10/site-packages/flwr/simulation/ray_transport/ray_actor.py", line 72, in run
    raise ClientException(str(message)) from ex
flwr.simulation.ray_transport.ray_actor.ClientException: 
>>>>>>>A ClientException occurred.('\n\tSomething went wrong when running your client workload.\n\tClient 18 crashed when the DefaultActor was running its workload.\n\tException triggered on the client side: Traceback (most recent call last):\n  File "/home/namvq/.cache/pypoetry/virtualenvs/niid-bench-orV17zke-py3.10/lib/python3.10/site-packages/flwr/simulation/ray_transport/ray_actor.py", line 60, in run\n    job_results = job_fn()\n  File "/home/namvq/.cache/pypoetry/virtualenvs/niid-bench-orV17zke-py3.10/lib/python3.10/site-packages/flwr/simulation/ray_transport/ray_client_proxy.py", line 196, in fit\n    return maybe_call_fit(\n  File "/home/namvq/.cache/pypoetry/virtualenvs/niid-bench-orV17zke-py3.10/lib/python3.10/site-packages/flwr/client/client.py", line 217, in maybe_call_fit\n    return client.fit(fit_ins)\n  File "/home/namvq/.cache/pypoetry/virtualenvs/niid-bench-orV17zke-py3.10/lib/python3.10/site-packages/flwr/client/app.py", line 333, in _fit\n    results = self.numpy_client.fit(parameters, ins.config)  # type: ignore\n  File "/media/namvq/Data/code_flwr/niid_bench/niid_bench/client_scaffold.py", line 78, in fit\n    train_scaffold(\n  File "/media/namvq/Data/code_flwr/niid_bench/niid_bench/models.py", line 146, in train_scaffold\n    net = _train_one_epoch_scaffold(\n  File "/media/namvq/Data/code_flwr/niid_bench/niid_bench/models.py", line 168, in _train_one_epoch_scaffold\n    optimizer.step_custom(server_cv, client_cv)\n  File "/media/namvq/Data/code_flwr/niid_bench/niid_bench/models.py", line 98, in step_custom\n    par.data.add_(s_cv - c_cv, alpha=-group["lr"])\nRuntimeError: The size of tensor a (1280) must match the size of tensor b (3) at non-singleton dimension 3\n',)
[2024-11-19 00:41:46,902][flwr][ERROR] - Traceback (most recent call last):
  File "/home/namvq/.cache/pypoetry/virtualenvs/niid-bench-orV17zke-py3.10/lib/python3.10/site-packages/flwr/simulation/ray_transport/ray_client_proxy.py", line 140, in _submit_job
    res = self.actor_pool.get_client_result(self.cid, timeout)
  File "/home/namvq/.cache/pypoetry/virtualenvs/niid-bench-orV17zke-py3.10/lib/python3.10/site-packages/flwr/simulation/ray_transport/ray_actor.py", line 402, in get_client_result
    return self._fetch_future_result(cid)
  File "/home/namvq/.cache/pypoetry/virtualenvs/niid-bench-orV17zke-py3.10/lib/python3.10/site-packages/flwr/simulation/ray_transport/ray_actor.py", line 288, in _fetch_future_result
    res_cid, res = ray.get(future)  # type: (str, ClientRes)
  File "/home/namvq/.cache/pypoetry/virtualenvs/niid-bench-orV17zke-py3.10/lib/python3.10/site-packages/ray/_private/auto_init_hook.py", line 24, in auto_init_wrapper
    return fn(*args, **kwargs)
  File "/home/namvq/.cache/pypoetry/virtualenvs/niid-bench-orV17zke-py3.10/lib/python3.10/site-packages/ray/_private/client_mode_hook.py", line 103, in wrapper
    return func(*args, **kwargs)
  File "/home/namvq/.cache/pypoetry/virtualenvs/niid-bench-orV17zke-py3.10/lib/python3.10/site-packages/ray/_private/worker.py", line 2524, in get
    raise value.as_instanceof_cause()
ray.exceptions.RayTaskError(ClientException): [36mray::DefaultActor.run()[39m (pid=25349, ip=192.168.1.29, actor_id=a184125d4faa0cad36fe8dc001000000, repr=<flwr.simulation.ray_transport.ray_actor.DefaultActor object at 0x7dab9199ae60>)
  File "/home/namvq/.cache/pypoetry/virtualenvs/niid-bench-orV17zke-py3.10/lib/python3.10/site-packages/flwr/simulation/ray_transport/ray_client_proxy.py", line 196, in fit
    return maybe_call_fit(
  File "/home/namvq/.cache/pypoetry/virtualenvs/niid-bench-orV17zke-py3.10/lib/python3.10/site-packages/flwr/client/client.py", line 217, in maybe_call_fit
    return client.fit(fit_ins)
  File "/home/namvq/.cache/pypoetry/virtualenvs/niid-bench-orV17zke-py3.10/lib/python3.10/site-packages/flwr/client/app.py", line 333, in _fit
    results = self.numpy_client.fit(parameters, ins.config)  # type: ignore
  File "/media/namvq/Data/code_flwr/niid_bench/niid_bench/client_scaffold.py", line 78, in fit
    train_scaffold(
  File "/media/namvq/Data/code_flwr/niid_bench/niid_bench/models.py", line 146, in train_scaffold
    net = _train_one_epoch_scaffold(
  File "/media/namvq/Data/code_flwr/niid_bench/niid_bench/models.py", line 168, in _train_one_epoch_scaffold
    optimizer.step_custom(server_cv, client_cv)
  File "/media/namvq/Data/code_flwr/niid_bench/niid_bench/models.py", line 98, in step_custom
    par.data.add_(s_cv - c_cv, alpha=-group["lr"])
RuntimeError: The size of tensor a (1280) must match the size of tensor b (3) at non-singleton dimension 3

The above exception was the direct cause of the following exception:

[36mray::DefaultActor.run()[39m (pid=25349, ip=192.168.1.29, actor_id=a184125d4faa0cad36fe8dc001000000, repr=<flwr.simulation.ray_transport.ray_actor.DefaultActor object at 0x7dab9199ae60>)
  File "/home/namvq/.cache/pypoetry/virtualenvs/niid-bench-orV17zke-py3.10/lib/python3.10/site-packages/flwr/simulation/ray_transport/ray_actor.py", line 72, in run
    raise ClientException(str(message)) from ex
flwr.simulation.ray_transport.ray_actor.ClientException: 
>>>>>>>A ClientException occurred.('\n\tSomething went wrong when running your client workload.\n\tClient 12 crashed when the DefaultActor was running its workload.\n\tException triggered on the client side: Traceback (most recent call last):\n  File "/home/namvq/.cache/pypoetry/virtualenvs/niid-bench-orV17zke-py3.10/lib/python3.10/site-packages/flwr/simulation/ray_transport/ray_actor.py", line 60, in run\n    job_results = job_fn()\n  File "/home/namvq/.cache/pypoetry/virtualenvs/niid-bench-orV17zke-py3.10/lib/python3.10/site-packages/flwr/simulation/ray_transport/ray_client_proxy.py", line 196, in fit\n    return maybe_call_fit(\n  File "/home/namvq/.cache/pypoetry/virtualenvs/niid-bench-orV17zke-py3.10/lib/python3.10/site-packages/flwr/client/client.py", line 217, in maybe_call_fit\n    return client.fit(fit_ins)\n  File "/home/namvq/.cache/pypoetry/virtualenvs/niid-bench-orV17zke-py3.10/lib/python3.10/site-packages/flwr/client/app.py", line 333, in _fit\n    results = self.numpy_client.fit(parameters, ins.config)  # type: ignore\n  File "/media/namvq/Data/code_flwr/niid_bench/niid_bench/client_scaffold.py", line 78, in fit\n    train_scaffold(\n  File "/media/namvq/Data/code_flwr/niid_bench/niid_bench/models.py", line 146, in train_scaffold\n    net = _train_one_epoch_scaffold(\n  File "/media/namvq/Data/code_flwr/niid_bench/niid_bench/models.py", line 168, in _train_one_epoch_scaffold\n    optimizer.step_custom(server_cv, client_cv)\n  File "/media/namvq/Data/code_flwr/niid_bench/niid_bench/models.py", line 98, in step_custom\n    par.data.add_(s_cv - c_cv, alpha=-group["lr"])\nRuntimeError: The size of tensor a (1280) must match the size of tensor b (3) at non-singleton dimension 3\n',)

[2024-11-19 00:41:46,902][flwr][ERROR] - [36mray::DefaultActor.run()[39m (pid=25349, ip=192.168.1.29, actor_id=a184125d4faa0cad36fe8dc001000000, repr=<flwr.simulation.ray_transport.ray_actor.DefaultActor object at 0x7dab9199ae60>)
  File "/home/namvq/.cache/pypoetry/virtualenvs/niid-bench-orV17zke-py3.10/lib/python3.10/site-packages/flwr/simulation/ray_transport/ray_client_proxy.py", line 196, in fit
    return maybe_call_fit(
  File "/home/namvq/.cache/pypoetry/virtualenvs/niid-bench-orV17zke-py3.10/lib/python3.10/site-packages/flwr/client/client.py", line 217, in maybe_call_fit
    return client.fit(fit_ins)
  File "/home/namvq/.cache/pypoetry/virtualenvs/niid-bench-orV17zke-py3.10/lib/python3.10/site-packages/flwr/client/app.py", line 333, in _fit
    results = self.numpy_client.fit(parameters, ins.config)  # type: ignore
  File "/media/namvq/Data/code_flwr/niid_bench/niid_bench/client_scaffold.py", line 78, in fit
    train_scaffold(
  File "/media/namvq/Data/code_flwr/niid_bench/niid_bench/models.py", line 146, in train_scaffold
    net = _train_one_epoch_scaffold(
  File "/media/namvq/Data/code_flwr/niid_bench/niid_bench/models.py", line 168, in _train_one_epoch_scaffold
    optimizer.step_custom(server_cv, client_cv)
  File "/media/namvq/Data/code_flwr/niid_bench/niid_bench/models.py", line 98, in step_custom
    par.data.add_(s_cv - c_cv, alpha=-group["lr"])
RuntimeError: The size of tensor a (1280) must match the size of tensor b (3) at non-singleton dimension 3

The above exception was the direct cause of the following exception:

[36mray::DefaultActor.run()[39m (pid=25349, ip=192.168.1.29, actor_id=a184125d4faa0cad36fe8dc001000000, repr=<flwr.simulation.ray_transport.ray_actor.DefaultActor object at 0x7dab9199ae60>)
  File "/home/namvq/.cache/pypoetry/virtualenvs/niid-bench-orV17zke-py3.10/lib/python3.10/site-packages/flwr/simulation/ray_transport/ray_actor.py", line 72, in run
    raise ClientException(str(message)) from ex
flwr.simulation.ray_transport.ray_actor.ClientException: 
>>>>>>>A ClientException occurred.('\n\tSomething went wrong when running your client workload.\n\tClient 12 crashed when the DefaultActor was running its workload.\n\tException triggered on the client side: Traceback (most recent call last):\n  File "/home/namvq/.cache/pypoetry/virtualenvs/niid-bench-orV17zke-py3.10/lib/python3.10/site-packages/flwr/simulation/ray_transport/ray_actor.py", line 60, in run\n    job_results = job_fn()\n  File "/home/namvq/.cache/pypoetry/virtualenvs/niid-bench-orV17zke-py3.10/lib/python3.10/site-packages/flwr/simulation/ray_transport/ray_client_proxy.py", line 196, in fit\n    return maybe_call_fit(\n  File "/home/namvq/.cache/pypoetry/virtualenvs/niid-bench-orV17zke-py3.10/lib/python3.10/site-packages/flwr/client/client.py", line 217, in maybe_call_fit\n    return client.fit(fit_ins)\n  File "/home/namvq/.cache/pypoetry/virtualenvs/niid-bench-orV17zke-py3.10/lib/python3.10/site-packages/flwr/client/app.py", line 333, in _fit\n    results = self.numpy_client.fit(parameters, ins.config)  # type: ignore\n  File "/media/namvq/Data/code_flwr/niid_bench/niid_bench/client_scaffold.py", line 78, in fit\n    train_scaffold(\n  File "/media/namvq/Data/code_flwr/niid_bench/niid_bench/models.py", line 146, in train_scaffold\n    net = _train_one_epoch_scaffold(\n  File "/media/namvq/Data/code_flwr/niid_bench/niid_bench/models.py", line 168, in _train_one_epoch_scaffold\n    optimizer.step_custom(server_cv, client_cv)\n  File "/media/namvq/Data/code_flwr/niid_bench/niid_bench/models.py", line 98, in step_custom\n    par.data.add_(s_cv - c_cv, alpha=-group["lr"])\nRuntimeError: The size of tensor a (1280) must match the size of tensor b (3) at non-singleton dimension 3\n',)
[2024-11-19 00:41:47,123][flwr][ERROR] - Traceback (most recent call last):
  File "/home/namvq/.cache/pypoetry/virtualenvs/niid-bench-orV17zke-py3.10/lib/python3.10/site-packages/flwr/simulation/ray_transport/ray_client_proxy.py", line 140, in _submit_job
    res = self.actor_pool.get_client_result(self.cid, timeout)
  File "/home/namvq/.cache/pypoetry/virtualenvs/niid-bench-orV17zke-py3.10/lib/python3.10/site-packages/flwr/simulation/ray_transport/ray_actor.py", line 402, in get_client_result
    return self._fetch_future_result(cid)
  File "/home/namvq/.cache/pypoetry/virtualenvs/niid-bench-orV17zke-py3.10/lib/python3.10/site-packages/flwr/simulation/ray_transport/ray_actor.py", line 288, in _fetch_future_result
    res_cid, res = ray.get(future)  # type: (str, ClientRes)
  File "/home/namvq/.cache/pypoetry/virtualenvs/niid-bench-orV17zke-py3.10/lib/python3.10/site-packages/ray/_private/auto_init_hook.py", line 24, in auto_init_wrapper
    return fn(*args, **kwargs)
  File "/home/namvq/.cache/pypoetry/virtualenvs/niid-bench-orV17zke-py3.10/lib/python3.10/site-packages/ray/_private/client_mode_hook.py", line 103, in wrapper
    return func(*args, **kwargs)
  File "/home/namvq/.cache/pypoetry/virtualenvs/niid-bench-orV17zke-py3.10/lib/python3.10/site-packages/ray/_private/worker.py", line 2524, in get
    raise value.as_instanceof_cause()
ray.exceptions.RayTaskError(ClientException): [36mray::DefaultActor.run()[39m (pid=25348, ip=192.168.1.29, actor_id=9fe6e3fbd5ce6028ac1aedb801000000, repr=<flwr.simulation.ray_transport.ray_actor.DefaultActor object at 0x7125e499ae60>)
  File "/home/namvq/.cache/pypoetry/virtualenvs/niid-bench-orV17zke-py3.10/lib/python3.10/site-packages/flwr/simulation/ray_transport/ray_client_proxy.py", line 196, in fit
    return maybe_call_fit(
  File "/home/namvq/.cache/pypoetry/virtualenvs/niid-bench-orV17zke-py3.10/lib/python3.10/site-packages/flwr/client/client.py", line 217, in maybe_call_fit
    return client.fit(fit_ins)
  File "/home/namvq/.cache/pypoetry/virtualenvs/niid-bench-orV17zke-py3.10/lib/python3.10/site-packages/flwr/client/app.py", line 333, in _fit
    results = self.numpy_client.fit(parameters, ins.config)  # type: ignore
  File "/media/namvq/Data/code_flwr/niid_bench/niid_bench/client_scaffold.py", line 78, in fit
    train_scaffold(
  File "/media/namvq/Data/code_flwr/niid_bench/niid_bench/models.py", line 146, in train_scaffold
    net = _train_one_epoch_scaffold(
  File "/media/namvq/Data/code_flwr/niid_bench/niid_bench/models.py", line 168, in _train_one_epoch_scaffold
    optimizer.step_custom(server_cv, client_cv)
  File "/media/namvq/Data/code_flwr/niid_bench/niid_bench/models.py", line 98, in step_custom
    par.data.add_(s_cv - c_cv, alpha=-group["lr"])
RuntimeError: The size of tensor a (1280) must match the size of tensor b (3) at non-singleton dimension 3

The above exception was the direct cause of the following exception:

[36mray::DefaultActor.run()[39m (pid=25348, ip=192.168.1.29, actor_id=9fe6e3fbd5ce6028ac1aedb801000000, repr=<flwr.simulation.ray_transport.ray_actor.DefaultActor object at 0x7125e499ae60>)
  File "/home/namvq/.cache/pypoetry/virtualenvs/niid-bench-orV17zke-py3.10/lib/python3.10/site-packages/flwr/simulation/ray_transport/ray_actor.py", line 72, in run
    raise ClientException(str(message)) from ex
flwr.simulation.ray_transport.ray_actor.ClientException: 
>>>>>>>A ClientException occurred.('\n\tSomething went wrong when running your client workload.\n\tClient 19 crashed when the DefaultActor was running its workload.\n\tException triggered on the client side: Traceback (most recent call last):\n  File "/home/namvq/.cache/pypoetry/virtualenvs/niid-bench-orV17zke-py3.10/lib/python3.10/site-packages/flwr/simulation/ray_transport/ray_actor.py", line 60, in run\n    job_results = job_fn()\n  File "/home/namvq/.cache/pypoetry/virtualenvs/niid-bench-orV17zke-py3.10/lib/python3.10/site-packages/flwr/simulation/ray_transport/ray_client_proxy.py", line 196, in fit\n    return maybe_call_fit(\n  File "/home/namvq/.cache/pypoetry/virtualenvs/niid-bench-orV17zke-py3.10/lib/python3.10/site-packages/flwr/client/client.py", line 217, in maybe_call_fit\n    return client.fit(fit_ins)\n  File "/home/namvq/.cache/pypoetry/virtualenvs/niid-bench-orV17zke-py3.10/lib/python3.10/site-packages/flwr/client/app.py", line 333, in _fit\n    results = self.numpy_client.fit(parameters, ins.config)  # type: ignore\n  File "/media/namvq/Data/code_flwr/niid_bench/niid_bench/client_scaffold.py", line 78, in fit\n    train_scaffold(\n  File "/media/namvq/Data/code_flwr/niid_bench/niid_bench/models.py", line 146, in train_scaffold\n    net = _train_one_epoch_scaffold(\n  File "/media/namvq/Data/code_flwr/niid_bench/niid_bench/models.py", line 168, in _train_one_epoch_scaffold\n    optimizer.step_custom(server_cv, client_cv)\n  File "/media/namvq/Data/code_flwr/niid_bench/niid_bench/models.py", line 98, in step_custom\n    par.data.add_(s_cv - c_cv, alpha=-group["lr"])\nRuntimeError: The size of tensor a (1280) must match the size of tensor b (3) at non-singleton dimension 3\n',)

[2024-11-19 00:41:47,123][flwr][ERROR] - [36mray::DefaultActor.run()[39m (pid=25348, ip=192.168.1.29, actor_id=9fe6e3fbd5ce6028ac1aedb801000000, repr=<flwr.simulation.ray_transport.ray_actor.DefaultActor object at 0x7125e499ae60>)
  File "/home/namvq/.cache/pypoetry/virtualenvs/niid-bench-orV17zke-py3.10/lib/python3.10/site-packages/flwr/simulation/ray_transport/ray_client_proxy.py", line 196, in fit
    return maybe_call_fit(
  File "/home/namvq/.cache/pypoetry/virtualenvs/niid-bench-orV17zke-py3.10/lib/python3.10/site-packages/flwr/client/client.py", line 217, in maybe_call_fit
    return client.fit(fit_ins)
  File "/home/namvq/.cache/pypoetry/virtualenvs/niid-bench-orV17zke-py3.10/lib/python3.10/site-packages/flwr/client/app.py", line 333, in _fit
    results = self.numpy_client.fit(parameters, ins.config)  # type: ignore
  File "/media/namvq/Data/code_flwr/niid_bench/niid_bench/client_scaffold.py", line 78, in fit
    train_scaffold(
  File "/media/namvq/Data/code_flwr/niid_bench/niid_bench/models.py", line 146, in train_scaffold
    net = _train_one_epoch_scaffold(
  File "/media/namvq/Data/code_flwr/niid_bench/niid_bench/models.py", line 168, in _train_one_epoch_scaffold
    optimizer.step_custom(server_cv, client_cv)
  File "/media/namvq/Data/code_flwr/niid_bench/niid_bench/models.py", line 98, in step_custom
    par.data.add_(s_cv - c_cv, alpha=-group["lr"])
RuntimeError: The size of tensor a (1280) must match the size of tensor b (3) at non-singleton dimension 3

The above exception was the direct cause of the following exception:

[36mray::DefaultActor.run()[39m (pid=25348, ip=192.168.1.29, actor_id=9fe6e3fbd5ce6028ac1aedb801000000, repr=<flwr.simulation.ray_transport.ray_actor.DefaultActor object at 0x7125e499ae60>)
  File "/home/namvq/.cache/pypoetry/virtualenvs/niid-bench-orV17zke-py3.10/lib/python3.10/site-packages/flwr/simulation/ray_transport/ray_actor.py", line 72, in run
    raise ClientException(str(message)) from ex
flwr.simulation.ray_transport.ray_actor.ClientException: 
>>>>>>>A ClientException occurred.('\n\tSomething went wrong when running your client workload.\n\tClient 19 crashed when the DefaultActor was running its workload.\n\tException triggered on the client side: Traceback (most recent call last):\n  File "/home/namvq/.cache/pypoetry/virtualenvs/niid-bench-orV17zke-py3.10/lib/python3.10/site-packages/flwr/simulation/ray_transport/ray_actor.py", line 60, in run\n    job_results = job_fn()\n  File "/home/namvq/.cache/pypoetry/virtualenvs/niid-bench-orV17zke-py3.10/lib/python3.10/site-packages/flwr/simulation/ray_transport/ray_client_proxy.py", line 196, in fit\n    return maybe_call_fit(\n  File "/home/namvq/.cache/pypoetry/virtualenvs/niid-bench-orV17zke-py3.10/lib/python3.10/site-packages/flwr/client/client.py", line 217, in maybe_call_fit\n    return client.fit(fit_ins)\n  File "/home/namvq/.cache/pypoetry/virtualenvs/niid-bench-orV17zke-py3.10/lib/python3.10/site-packages/flwr/client/app.py", line 333, in _fit\n    results = self.numpy_client.fit(parameters, ins.config)  # type: ignore\n  File "/media/namvq/Data/code_flwr/niid_bench/niid_bench/client_scaffold.py", line 78, in fit\n    train_scaffold(\n  File "/media/namvq/Data/code_flwr/niid_bench/niid_bench/models.py", line 146, in train_scaffold\n    net = _train_one_epoch_scaffold(\n  File "/media/namvq/Data/code_flwr/niid_bench/niid_bench/models.py", line 168, in _train_one_epoch_scaffold\n    optimizer.step_custom(server_cv, client_cv)\n  File "/media/namvq/Data/code_flwr/niid_bench/niid_bench/models.py", line 98, in step_custom\n    par.data.add_(s_cv - c_cv, alpha=-group["lr"])\nRuntimeError: The size of tensor a (1280) must match the size of tensor b (3) at non-singleton dimension 3\n',)
[2024-11-19 00:41:48,088][flwr][ERROR] - Traceback (most recent call last):
  File "/home/namvq/.cache/pypoetry/virtualenvs/niid-bench-orV17zke-py3.10/lib/python3.10/site-packages/flwr/simulation/ray_transport/ray_client_proxy.py", line 140, in _submit_job
    res = self.actor_pool.get_client_result(self.cid, timeout)
  File "/home/namvq/.cache/pypoetry/virtualenvs/niid-bench-orV17zke-py3.10/lib/python3.10/site-packages/flwr/simulation/ray_transport/ray_actor.py", line 402, in get_client_result
    return self._fetch_future_result(cid)
  File "/home/namvq/.cache/pypoetry/virtualenvs/niid-bench-orV17zke-py3.10/lib/python3.10/site-packages/flwr/simulation/ray_transport/ray_actor.py", line 288, in _fetch_future_result
    res_cid, res = ray.get(future)  # type: (str, ClientRes)
  File "/home/namvq/.cache/pypoetry/virtualenvs/niid-bench-orV17zke-py3.10/lib/python3.10/site-packages/ray/_private/auto_init_hook.py", line 24, in auto_init_wrapper
    return fn(*args, **kwargs)
  File "/home/namvq/.cache/pypoetry/virtualenvs/niid-bench-orV17zke-py3.10/lib/python3.10/site-packages/ray/_private/client_mode_hook.py", line 103, in wrapper
    return func(*args, **kwargs)
  File "/home/namvq/.cache/pypoetry/virtualenvs/niid-bench-orV17zke-py3.10/lib/python3.10/site-packages/ray/_private/worker.py", line 2524, in get
    raise value.as_instanceof_cause()
ray.exceptions.RayTaskError(ClientException): [36mray::DefaultActor.run()[39m (pid=25350, ip=192.168.1.29, actor_id=077df88ce403c97b122daa2401000000, repr=<flwr.simulation.ray_transport.ray_actor.DefaultActor object at 0x75b8f0116dd0>)
  File "/home/namvq/.cache/pypoetry/virtualenvs/niid-bench-orV17zke-py3.10/lib/python3.10/site-packages/flwr/simulation/ray_transport/ray_client_proxy.py", line 196, in fit
    return maybe_call_fit(
  File "/home/namvq/.cache/pypoetry/virtualenvs/niid-bench-orV17zke-py3.10/lib/python3.10/site-packages/flwr/client/client.py", line 217, in maybe_call_fit
    return client.fit(fit_ins)
  File "/home/namvq/.cache/pypoetry/virtualenvs/niid-bench-orV17zke-py3.10/lib/python3.10/site-packages/flwr/client/app.py", line 333, in _fit
    results = self.numpy_client.fit(parameters, ins.config)  # type: ignore
  File "/media/namvq/Data/code_flwr/niid_bench/niid_bench/client_scaffold.py", line 78, in fit
    train_scaffold(
  File "/media/namvq/Data/code_flwr/niid_bench/niid_bench/models.py", line 146, in train_scaffold
    net = _train_one_epoch_scaffold(
  File "/media/namvq/Data/code_flwr/niid_bench/niid_bench/models.py", line 168, in _train_one_epoch_scaffold
    optimizer.step_custom(server_cv, client_cv)
  File "/media/namvq/Data/code_flwr/niid_bench/niid_bench/models.py", line 98, in step_custom
    par.data.add_(s_cv - c_cv, alpha=-group["lr"])
RuntimeError: The size of tensor a (1280) must match the size of tensor b (3) at non-singleton dimension 3

The above exception was the direct cause of the following exception:

[36mray::DefaultActor.run()[39m (pid=25350, ip=192.168.1.29, actor_id=077df88ce403c97b122daa2401000000, repr=<flwr.simulation.ray_transport.ray_actor.DefaultActor object at 0x75b8f0116dd0>)
  File "/home/namvq/.cache/pypoetry/virtualenvs/niid-bench-orV17zke-py3.10/lib/python3.10/site-packages/flwr/simulation/ray_transport/ray_actor.py", line 72, in run
    raise ClientException(str(message)) from ex
flwr.simulation.ray_transport.ray_actor.ClientException: 
>>>>>>>A ClientException occurred.('\n\tSomething went wrong when running your client workload.\n\tClient 15 crashed when the DefaultActor was running its workload.\n\tException triggered on the client side: Traceback (most recent call last):\n  File "/home/namvq/.cache/pypoetry/virtualenvs/niid-bench-orV17zke-py3.10/lib/python3.10/site-packages/flwr/simulation/ray_transport/ray_actor.py", line 60, in run\n    job_results = job_fn()\n  File "/home/namvq/.cache/pypoetry/virtualenvs/niid-bench-orV17zke-py3.10/lib/python3.10/site-packages/flwr/simulation/ray_transport/ray_client_proxy.py", line 196, in fit\n    return maybe_call_fit(\n  File "/home/namvq/.cache/pypoetry/virtualenvs/niid-bench-orV17zke-py3.10/lib/python3.10/site-packages/flwr/client/client.py", line 217, in maybe_call_fit\n    return client.fit(fit_ins)\n  File "/home/namvq/.cache/pypoetry/virtualenvs/niid-bench-orV17zke-py3.10/lib/python3.10/site-packages/flwr/client/app.py", line 333, in _fit\n    results = self.numpy_client.fit(parameters, ins.config)  # type: ignore\n  File "/media/namvq/Data/code_flwr/niid_bench/niid_bench/client_scaffold.py", line 78, in fit\n    train_scaffold(\n  File "/media/namvq/Data/code_flwr/niid_bench/niid_bench/models.py", line 146, in train_scaffold\n    net = _train_one_epoch_scaffold(\n  File "/media/namvq/Data/code_flwr/niid_bench/niid_bench/models.py", line 168, in _train_one_epoch_scaffold\n    optimizer.step_custom(server_cv, client_cv)\n  File "/media/namvq/Data/code_flwr/niid_bench/niid_bench/models.py", line 98, in step_custom\n    par.data.add_(s_cv - c_cv, alpha=-group["lr"])\nRuntimeError: The size of tensor a (1280) must match the size of tensor b (3) at non-singleton dimension 3\n',)

[2024-11-19 00:41:48,088][flwr][ERROR] - [36mray::DefaultActor.run()[39m (pid=25350, ip=192.168.1.29, actor_id=077df88ce403c97b122daa2401000000, repr=<flwr.simulation.ray_transport.ray_actor.DefaultActor object at 0x75b8f0116dd0>)
  File "/home/namvq/.cache/pypoetry/virtualenvs/niid-bench-orV17zke-py3.10/lib/python3.10/site-packages/flwr/simulation/ray_transport/ray_client_proxy.py", line 196, in fit
    return maybe_call_fit(
  File "/home/namvq/.cache/pypoetry/virtualenvs/niid-bench-orV17zke-py3.10/lib/python3.10/site-packages/flwr/client/client.py", line 217, in maybe_call_fit
    return client.fit(fit_ins)
  File "/home/namvq/.cache/pypoetry/virtualenvs/niid-bench-orV17zke-py3.10/lib/python3.10/site-packages/flwr/client/app.py", line 333, in _fit
    results = self.numpy_client.fit(parameters, ins.config)  # type: ignore
  File "/media/namvq/Data/code_flwr/niid_bench/niid_bench/client_scaffold.py", line 78, in fit
    train_scaffold(
  File "/media/namvq/Data/code_flwr/niid_bench/niid_bench/models.py", line 146, in train_scaffold
    net = _train_one_epoch_scaffold(
  File "/media/namvq/Data/code_flwr/niid_bench/niid_bench/models.py", line 168, in _train_one_epoch_scaffold
    optimizer.step_custom(server_cv, client_cv)
  File "/media/namvq/Data/code_flwr/niid_bench/niid_bench/models.py", line 98, in step_custom
    par.data.add_(s_cv - c_cv, alpha=-group["lr"])
RuntimeError: The size of tensor a (1280) must match the size of tensor b (3) at non-singleton dimension 3

The above exception was the direct cause of the following exception:

[36mray::DefaultActor.run()[39m (pid=25350, ip=192.168.1.29, actor_id=077df88ce403c97b122daa2401000000, repr=<flwr.simulation.ray_transport.ray_actor.DefaultActor object at 0x75b8f0116dd0>)
  File "/home/namvq/.cache/pypoetry/virtualenvs/niid-bench-orV17zke-py3.10/lib/python3.10/site-packages/flwr/simulation/ray_transport/ray_actor.py", line 72, in run
    raise ClientException(str(message)) from ex
flwr.simulation.ray_transport.ray_actor.ClientException: 
>>>>>>>A ClientException occurred.('\n\tSomething went wrong when running your client workload.\n\tClient 15 crashed when the DefaultActor was running its workload.\n\tException triggered on the client side: Traceback (most recent call last):\n  File "/home/namvq/.cache/pypoetry/virtualenvs/niid-bench-orV17zke-py3.10/lib/python3.10/site-packages/flwr/simulation/ray_transport/ray_actor.py", line 60, in run\n    job_results = job_fn()\n  File "/home/namvq/.cache/pypoetry/virtualenvs/niid-bench-orV17zke-py3.10/lib/python3.10/site-packages/flwr/simulation/ray_transport/ray_client_proxy.py", line 196, in fit\n    return maybe_call_fit(\n  File "/home/namvq/.cache/pypoetry/virtualenvs/niid-bench-orV17zke-py3.10/lib/python3.10/site-packages/flwr/client/client.py", line 217, in maybe_call_fit\n    return client.fit(fit_ins)\n  File "/home/namvq/.cache/pypoetry/virtualenvs/niid-bench-orV17zke-py3.10/lib/python3.10/site-packages/flwr/client/app.py", line 333, in _fit\n    results = self.numpy_client.fit(parameters, ins.config)  # type: ignore\n  File "/media/namvq/Data/code_flwr/niid_bench/niid_bench/client_scaffold.py", line 78, in fit\n    train_scaffold(\n  File "/media/namvq/Data/code_flwr/niid_bench/niid_bench/models.py", line 146, in train_scaffold\n    net = _train_one_epoch_scaffold(\n  File "/media/namvq/Data/code_flwr/niid_bench/niid_bench/models.py", line 168, in _train_one_epoch_scaffold\n    optimizer.step_custom(server_cv, client_cv)\n  File "/media/namvq/Data/code_flwr/niid_bench/niid_bench/models.py", line 98, in step_custom\n    par.data.add_(s_cv - c_cv, alpha=-group["lr"])\nRuntimeError: The size of tensor a (1280) must match the size of tensor b (3) at non-singleton dimension 3\n',)
[2024-11-19 00:41:48,429][flwr][ERROR] - Traceback (most recent call last):
  File "/home/namvq/.cache/pypoetry/virtualenvs/niid-bench-orV17zke-py3.10/lib/python3.10/site-packages/flwr/simulation/ray_transport/ray_client_proxy.py", line 140, in _submit_job
    res = self.actor_pool.get_client_result(self.cid, timeout)
  File "/home/namvq/.cache/pypoetry/virtualenvs/niid-bench-orV17zke-py3.10/lib/python3.10/site-packages/flwr/simulation/ray_transport/ray_actor.py", line 402, in get_client_result
    return self._fetch_future_result(cid)
  File "/home/namvq/.cache/pypoetry/virtualenvs/niid-bench-orV17zke-py3.10/lib/python3.10/site-packages/flwr/simulation/ray_transport/ray_actor.py", line 288, in _fetch_future_result
    res_cid, res = ray.get(future)  # type: (str, ClientRes)
  File "/home/namvq/.cache/pypoetry/virtualenvs/niid-bench-orV17zke-py3.10/lib/python3.10/site-packages/ray/_private/auto_init_hook.py", line 24, in auto_init_wrapper
    return fn(*args, **kwargs)
  File "/home/namvq/.cache/pypoetry/virtualenvs/niid-bench-orV17zke-py3.10/lib/python3.10/site-packages/ray/_private/client_mode_hook.py", line 103, in wrapper
    return func(*args, **kwargs)
  File "/home/namvq/.cache/pypoetry/virtualenvs/niid-bench-orV17zke-py3.10/lib/python3.10/site-packages/ray/_private/worker.py", line 2524, in get
    raise value.as_instanceof_cause()
ray.exceptions.RayTaskError(ClientException): [36mray::DefaultActor.run()[39m (pid=25349, ip=192.168.1.29, actor_id=a184125d4faa0cad36fe8dc001000000, repr=<flwr.simulation.ray_transport.ray_actor.DefaultActor object at 0x7dab9199ae60>)
  File "/home/namvq/.cache/pypoetry/virtualenvs/niid-bench-orV17zke-py3.10/lib/python3.10/site-packages/flwr/simulation/ray_transport/ray_client_proxy.py", line 196, in fit
    return maybe_call_fit(
  File "/home/namvq/.cache/pypoetry/virtualenvs/niid-bench-orV17zke-py3.10/lib/python3.10/site-packages/flwr/client/client.py", line 217, in maybe_call_fit
    return client.fit(fit_ins)
  File "/home/namvq/.cache/pypoetry/virtualenvs/niid-bench-orV17zke-py3.10/lib/python3.10/site-packages/flwr/client/app.py", line 333, in _fit
    results = self.numpy_client.fit(parameters, ins.config)  # type: ignore
  File "/media/namvq/Data/code_flwr/niid_bench/niid_bench/client_scaffold.py", line 78, in fit
    train_scaffold(
  File "/media/namvq/Data/code_flwr/niid_bench/niid_bench/models.py", line 146, in train_scaffold
    net = _train_one_epoch_scaffold(
  File "/media/namvq/Data/code_flwr/niid_bench/niid_bench/models.py", line 168, in _train_one_epoch_scaffold
    optimizer.step_custom(server_cv, client_cv)
  File "/media/namvq/Data/code_flwr/niid_bench/niid_bench/models.py", line 98, in step_custom
    par.data.add_(s_cv - c_cv, alpha=-group["lr"])
RuntimeError: The size of tensor a (1280) must match the size of tensor b (3) at non-singleton dimension 3

The above exception was the direct cause of the following exception:

[36mray::DefaultActor.run()[39m (pid=25349, ip=192.168.1.29, actor_id=a184125d4faa0cad36fe8dc001000000, repr=<flwr.simulation.ray_transport.ray_actor.DefaultActor object at 0x7dab9199ae60>)
  File "/home/namvq/.cache/pypoetry/virtualenvs/niid-bench-orV17zke-py3.10/lib/python3.10/site-packages/flwr/simulation/ray_transport/ray_actor.py", line 72, in run
    raise ClientException(str(message)) from ex
flwr.simulation.ray_transport.ray_actor.ClientException: 
>>>>>>>A ClientException occurred.('\n\tSomething went wrong when running your client workload.\n\tClient 14 crashed when the DefaultActor was running its workload.\n\tException triggered on the client side: Traceback (most recent call last):\n  File "/home/namvq/.cache/pypoetry/virtualenvs/niid-bench-orV17zke-py3.10/lib/python3.10/site-packages/flwr/simulation/ray_transport/ray_actor.py", line 60, in run\n    job_results = job_fn()\n  File "/home/namvq/.cache/pypoetry/virtualenvs/niid-bench-orV17zke-py3.10/lib/python3.10/site-packages/flwr/simulation/ray_transport/ray_client_proxy.py", line 196, in fit\n    return maybe_call_fit(\n  File "/home/namvq/.cache/pypoetry/virtualenvs/niid-bench-orV17zke-py3.10/lib/python3.10/site-packages/flwr/client/client.py", line 217, in maybe_call_fit\n    return client.fit(fit_ins)\n  File "/home/namvq/.cache/pypoetry/virtualenvs/niid-bench-orV17zke-py3.10/lib/python3.10/site-packages/flwr/client/app.py", line 333, in _fit\n    results = self.numpy_client.fit(parameters, ins.config)  # type: ignore\n  File "/media/namvq/Data/code_flwr/niid_bench/niid_bench/client_scaffold.py", line 78, in fit\n    train_scaffold(\n  File "/media/namvq/Data/code_flwr/niid_bench/niid_bench/models.py", line 146, in train_scaffold\n    net = _train_one_epoch_scaffold(\n  File "/media/namvq/Data/code_flwr/niid_bench/niid_bench/models.py", line 168, in _train_one_epoch_scaffold\n    optimizer.step_custom(server_cv, client_cv)\n  File "/media/namvq/Data/code_flwr/niid_bench/niid_bench/models.py", line 98, in step_custom\n    par.data.add_(s_cv - c_cv, alpha=-group["lr"])\nRuntimeError: The size of tensor a (1280) must match the size of tensor b (3) at non-singleton dimension 3\n',)

[2024-11-19 00:41:48,429][flwr][ERROR] - [36mray::DefaultActor.run()[39m (pid=25349, ip=192.168.1.29, actor_id=a184125d4faa0cad36fe8dc001000000, repr=<flwr.simulation.ray_transport.ray_actor.DefaultActor object at 0x7dab9199ae60>)
  File "/home/namvq/.cache/pypoetry/virtualenvs/niid-bench-orV17zke-py3.10/lib/python3.10/site-packages/flwr/simulation/ray_transport/ray_client_proxy.py", line 196, in fit
    return maybe_call_fit(
  File "/home/namvq/.cache/pypoetry/virtualenvs/niid-bench-orV17zke-py3.10/lib/python3.10/site-packages/flwr/client/client.py", line 217, in maybe_call_fit
    return client.fit(fit_ins)
  File "/home/namvq/.cache/pypoetry/virtualenvs/niid-bench-orV17zke-py3.10/lib/python3.10/site-packages/flwr/client/app.py", line 333, in _fit
    results = self.numpy_client.fit(parameters, ins.config)  # type: ignore
  File "/media/namvq/Data/code_flwr/niid_bench/niid_bench/client_scaffold.py", line 78, in fit
    train_scaffold(
  File "/media/namvq/Data/code_flwr/niid_bench/niid_bench/models.py", line 146, in train_scaffold
    net = _train_one_epoch_scaffold(
  File "/media/namvq/Data/code_flwr/niid_bench/niid_bench/models.py", line 168, in _train_one_epoch_scaffold
    optimizer.step_custom(server_cv, client_cv)
  File "/media/namvq/Data/code_flwr/niid_bench/niid_bench/models.py", line 98, in step_custom
    par.data.add_(s_cv - c_cv, alpha=-group["lr"])
RuntimeError: The size of tensor a (1280) must match the size of tensor b (3) at non-singleton dimension 3

The above exception was the direct cause of the following exception:

[36mray::DefaultActor.run()[39m (pid=25349, ip=192.168.1.29, actor_id=a184125d4faa0cad36fe8dc001000000, repr=<flwr.simulation.ray_transport.ray_actor.DefaultActor object at 0x7dab9199ae60>)
  File "/home/namvq/.cache/pypoetry/virtualenvs/niid-bench-orV17zke-py3.10/lib/python3.10/site-packages/flwr/simulation/ray_transport/ray_actor.py", line 72, in run
    raise ClientException(str(message)) from ex
flwr.simulation.ray_transport.ray_actor.ClientException: 
>>>>>>>A ClientException occurred.('\n\tSomething went wrong when running your client workload.\n\tClient 14 crashed when the DefaultActor was running its workload.\n\tException triggered on the client side: Traceback (most recent call last):\n  File "/home/namvq/.cache/pypoetry/virtualenvs/niid-bench-orV17zke-py3.10/lib/python3.10/site-packages/flwr/simulation/ray_transport/ray_actor.py", line 60, in run\n    job_results = job_fn()\n  File "/home/namvq/.cache/pypoetry/virtualenvs/niid-bench-orV17zke-py3.10/lib/python3.10/site-packages/flwr/simulation/ray_transport/ray_client_proxy.py", line 196, in fit\n    return maybe_call_fit(\n  File "/home/namvq/.cache/pypoetry/virtualenvs/niid-bench-orV17zke-py3.10/lib/python3.10/site-packages/flwr/client/client.py", line 217, in maybe_call_fit\n    return client.fit(fit_ins)\n  File "/home/namvq/.cache/pypoetry/virtualenvs/niid-bench-orV17zke-py3.10/lib/python3.10/site-packages/flwr/client/app.py", line 333, in _fit\n    results = self.numpy_client.fit(parameters, ins.config)  # type: ignore\n  File "/media/namvq/Data/code_flwr/niid_bench/niid_bench/client_scaffold.py", line 78, in fit\n    train_scaffold(\n  File "/media/namvq/Data/code_flwr/niid_bench/niid_bench/models.py", line 146, in train_scaffold\n    net = _train_one_epoch_scaffold(\n  File "/media/namvq/Data/code_flwr/niid_bench/niid_bench/models.py", line 168, in _train_one_epoch_scaffold\n    optimizer.step_custom(server_cv, client_cv)\n  File "/media/namvq/Data/code_flwr/niid_bench/niid_bench/models.py", line 98, in step_custom\n    par.data.add_(s_cv - c_cv, alpha=-group["lr"])\nRuntimeError: The size of tensor a (1280) must match the size of tensor b (3) at non-singleton dimension 3\n',)
[2024-11-19 00:41:48,668][flwr][ERROR] - Traceback (most recent call last):
  File "/home/namvq/.cache/pypoetry/virtualenvs/niid-bench-orV17zke-py3.10/lib/python3.10/site-packages/flwr/simulation/ray_transport/ray_client_proxy.py", line 140, in _submit_job
    res = self.actor_pool.get_client_result(self.cid, timeout)
  File "/home/namvq/.cache/pypoetry/virtualenvs/niid-bench-orV17zke-py3.10/lib/python3.10/site-packages/flwr/simulation/ray_transport/ray_actor.py", line 402, in get_client_result
    return self._fetch_future_result(cid)
  File "/home/namvq/.cache/pypoetry/virtualenvs/niid-bench-orV17zke-py3.10/lib/python3.10/site-packages/flwr/simulation/ray_transport/ray_actor.py", line 288, in _fetch_future_result
    res_cid, res = ray.get(future)  # type: (str, ClientRes)
  File "/home/namvq/.cache/pypoetry/virtualenvs/niid-bench-orV17zke-py3.10/lib/python3.10/site-packages/ray/_private/auto_init_hook.py", line 24, in auto_init_wrapper
    return fn(*args, **kwargs)
  File "/home/namvq/.cache/pypoetry/virtualenvs/niid-bench-orV17zke-py3.10/lib/python3.10/site-packages/ray/_private/client_mode_hook.py", line 103, in wrapper
    return func(*args, **kwargs)
  File "/home/namvq/.cache/pypoetry/virtualenvs/niid-bench-orV17zke-py3.10/lib/python3.10/site-packages/ray/_private/worker.py", line 2524, in get
    raise value.as_instanceof_cause()
ray.exceptions.RayTaskError(ClientException): [36mray::DefaultActor.run()[39m (pid=25348, ip=192.168.1.29, actor_id=9fe6e3fbd5ce6028ac1aedb801000000, repr=<flwr.simulation.ray_transport.ray_actor.DefaultActor object at 0x7125e499ae60>)
  File "/home/namvq/.cache/pypoetry/virtualenvs/niid-bench-orV17zke-py3.10/lib/python3.10/site-packages/flwr/simulation/ray_transport/ray_client_proxy.py", line 196, in fit
    return maybe_call_fit(
  File "/home/namvq/.cache/pypoetry/virtualenvs/niid-bench-orV17zke-py3.10/lib/python3.10/site-packages/flwr/client/client.py", line 217, in maybe_call_fit
    return client.fit(fit_ins)
  File "/home/namvq/.cache/pypoetry/virtualenvs/niid-bench-orV17zke-py3.10/lib/python3.10/site-packages/flwr/client/app.py", line 333, in _fit
    results = self.numpy_client.fit(parameters, ins.config)  # type: ignore
  File "/media/namvq/Data/code_flwr/niid_bench/niid_bench/client_scaffold.py", line 78, in fit
    train_scaffold(
  File "/media/namvq/Data/code_flwr/niid_bench/niid_bench/models.py", line 146, in train_scaffold
    net = _train_one_epoch_scaffold(
  File "/media/namvq/Data/code_flwr/niid_bench/niid_bench/models.py", line 168, in _train_one_epoch_scaffold
    optimizer.step_custom(server_cv, client_cv)
  File "/media/namvq/Data/code_flwr/niid_bench/niid_bench/models.py", line 98, in step_custom
    par.data.add_(s_cv - c_cv, alpha=-group["lr"])
RuntimeError: The size of tensor a (1280) must match the size of tensor b (3) at non-singleton dimension 3

The above exception was the direct cause of the following exception:

[36mray::DefaultActor.run()[39m (pid=25348, ip=192.168.1.29, actor_id=9fe6e3fbd5ce6028ac1aedb801000000, repr=<flwr.simulation.ray_transport.ray_actor.DefaultActor object at 0x7125e499ae60>)
  File "/home/namvq/.cache/pypoetry/virtualenvs/niid-bench-orV17zke-py3.10/lib/python3.10/site-packages/flwr/simulation/ray_transport/ray_actor.py", line 72, in run
    raise ClientException(str(message)) from ex
flwr.simulation.ray_transport.ray_actor.ClientException: 
>>>>>>>A ClientException occurred.('\n\tSomething went wrong when running your client workload.\n\tClient 2 crashed when the DefaultActor was running its workload.\n\tException triggered on the client side: Traceback (most recent call last):\n  File "/home/namvq/.cache/pypoetry/virtualenvs/niid-bench-orV17zke-py3.10/lib/python3.10/site-packages/flwr/simulation/ray_transport/ray_actor.py", line 60, in run\n    job_results = job_fn()\n  File "/home/namvq/.cache/pypoetry/virtualenvs/niid-bench-orV17zke-py3.10/lib/python3.10/site-packages/flwr/simulation/ray_transport/ray_client_proxy.py", line 196, in fit\n    return maybe_call_fit(\n  File "/home/namvq/.cache/pypoetry/virtualenvs/niid-bench-orV17zke-py3.10/lib/python3.10/site-packages/flwr/client/client.py", line 217, in maybe_call_fit\n    return client.fit(fit_ins)\n  File "/home/namvq/.cache/pypoetry/virtualenvs/niid-bench-orV17zke-py3.10/lib/python3.10/site-packages/flwr/client/app.py", line 333, in _fit\n    results = self.numpy_client.fit(parameters, ins.config)  # type: ignore\n  File "/media/namvq/Data/code_flwr/niid_bench/niid_bench/client_scaffold.py", line 78, in fit\n    train_scaffold(\n  File "/media/namvq/Data/code_flwr/niid_bench/niid_bench/models.py", line 146, in train_scaffold\n    net = _train_one_epoch_scaffold(\n  File "/media/namvq/Data/code_flwr/niid_bench/niid_bench/models.py", line 168, in _train_one_epoch_scaffold\n    optimizer.step_custom(server_cv, client_cv)\n  File "/media/namvq/Data/code_flwr/niid_bench/niid_bench/models.py", line 98, in step_custom\n    par.data.add_(s_cv - c_cv, alpha=-group["lr"])\nRuntimeError: The size of tensor a (1280) must match the size of tensor b (3) at non-singleton dimension 3\n',)

[2024-11-19 00:41:48,669][flwr][ERROR] - [36mray::DefaultActor.run()[39m (pid=25348, ip=192.168.1.29, actor_id=9fe6e3fbd5ce6028ac1aedb801000000, repr=<flwr.simulation.ray_transport.ray_actor.DefaultActor object at 0x7125e499ae60>)
  File "/home/namvq/.cache/pypoetry/virtualenvs/niid-bench-orV17zke-py3.10/lib/python3.10/site-packages/flwr/simulation/ray_transport/ray_client_proxy.py", line 196, in fit
    return maybe_call_fit(
  File "/home/namvq/.cache/pypoetry/virtualenvs/niid-bench-orV17zke-py3.10/lib/python3.10/site-packages/flwr/client/client.py", line 217, in maybe_call_fit
    return client.fit(fit_ins)
  File "/home/namvq/.cache/pypoetry/virtualenvs/niid-bench-orV17zke-py3.10/lib/python3.10/site-packages/flwr/client/app.py", line 333, in _fit
    results = self.numpy_client.fit(parameters, ins.config)  # type: ignore
  File "/media/namvq/Data/code_flwr/niid_bench/niid_bench/client_scaffold.py", line 78, in fit
    train_scaffold(
  File "/media/namvq/Data/code_flwr/niid_bench/niid_bench/models.py", line 146, in train_scaffold
    net = _train_one_epoch_scaffold(
  File "/media/namvq/Data/code_flwr/niid_bench/niid_bench/models.py", line 168, in _train_one_epoch_scaffold
    optimizer.step_custom(server_cv, client_cv)
  File "/media/namvq/Data/code_flwr/niid_bench/niid_bench/models.py", line 98, in step_custom
    par.data.add_(s_cv - c_cv, alpha=-group["lr"])
RuntimeError: The size of tensor a (1280) must match the size of tensor b (3) at non-singleton dimension 3

The above exception was the direct cause of the following exception:

[36mray::DefaultActor.run()[39m (pid=25348, ip=192.168.1.29, actor_id=9fe6e3fbd5ce6028ac1aedb801000000, repr=<flwr.simulation.ray_transport.ray_actor.DefaultActor object at 0x7125e499ae60>)
  File "/home/namvq/.cache/pypoetry/virtualenvs/niid-bench-orV17zke-py3.10/lib/python3.10/site-packages/flwr/simulation/ray_transport/ray_actor.py", line 72, in run
    raise ClientException(str(message)) from ex
flwr.simulation.ray_transport.ray_actor.ClientException: 
>>>>>>>A ClientException occurred.('\n\tSomething went wrong when running your client workload.\n\tClient 2 crashed when the DefaultActor was running its workload.\n\tException triggered on the client side: Traceback (most recent call last):\n  File "/home/namvq/.cache/pypoetry/virtualenvs/niid-bench-orV17zke-py3.10/lib/python3.10/site-packages/flwr/simulation/ray_transport/ray_actor.py", line 60, in run\n    job_results = job_fn()\n  File "/home/namvq/.cache/pypoetry/virtualenvs/niid-bench-orV17zke-py3.10/lib/python3.10/site-packages/flwr/simulation/ray_transport/ray_client_proxy.py", line 196, in fit\n    return maybe_call_fit(\n  File "/home/namvq/.cache/pypoetry/virtualenvs/niid-bench-orV17zke-py3.10/lib/python3.10/site-packages/flwr/client/client.py", line 217, in maybe_call_fit\n    return client.fit(fit_ins)\n  File "/home/namvq/.cache/pypoetry/virtualenvs/niid-bench-orV17zke-py3.10/lib/python3.10/site-packages/flwr/client/app.py", line 333, in _fit\n    results = self.numpy_client.fit(parameters, ins.config)  # type: ignore\n  File "/media/namvq/Data/code_flwr/niid_bench/niid_bench/client_scaffold.py", line 78, in fit\n    train_scaffold(\n  File "/media/namvq/Data/code_flwr/niid_bench/niid_bench/models.py", line 146, in train_scaffold\n    net = _train_one_epoch_scaffold(\n  File "/media/namvq/Data/code_flwr/niid_bench/niid_bench/models.py", line 168, in _train_one_epoch_scaffold\n    optimizer.step_custom(server_cv, client_cv)\n  File "/media/namvq/Data/code_flwr/niid_bench/niid_bench/models.py", line 98, in step_custom\n    par.data.add_(s_cv - c_cv, alpha=-group["lr"])\nRuntimeError: The size of tensor a (1280) must match the size of tensor b (3) at non-singleton dimension 3\n',)
[2024-11-19 00:41:48,669][flwr][DEBUG] - fit_round 1 received 0 results and 10 failures
[2024-11-19 00:41:48,669][flwr][ERROR] - list index out of range
[2024-11-19 00:41:48,669][flwr][ERROR] - Your simulation crashed :(. This could be because of several reasons.The most common are: 
	 > Your system couldn't fit a single VirtualClient: try lowering `client_resources`.
	 > All the actors in your pool crashed. This could be because: 
		 - You clients hit an out-of-memory (OOM) error and actors couldn't recover from it. Try launching your simulation with more generous `client_resources` setting (i.e. it seems {'num_cpus': 4, 'num_gpus': 0} is not enough for your workload). Use fewer concurrent actors. 
		 - You were running a multi-node simulation and all worker nodes disconnected. The head node might still be alive but cannot accommodate any actor with resources: {'num_cpus': 4, 'num_gpus': 0}.
