[2024-11-25 22:22:12,748][flwr][WARNING] - Both server and strategy were provided, ignoring strategy
[2024-11-25 22:22:12,749][flwr][INFO] - Starting Flower simulation, config: ServerConfig(num_rounds=1, round_timeout=None)
[2024-11-25 22:22:18,987][flwr][INFO] - Flower VCE: Ray initialized with resources: {'object_store_memory': 3004273459.0, 'node:192.168.1.62': 1.0, 'CPU': 12.0, 'memory': 6008546919.0, 'accelerator_type:G': 1.0, 'GPU': 1.0, 'node:__internal_head__': 1.0}
[2024-11-25 22:22:18,987][flwr][INFO] - Flower VCE: Resources for each Virtual Client: {'num_cpus': 4, 'num_gpus': 1}
[2024-11-25 22:22:18,996][flwr][INFO] - Flower VCE: Creating VirtualClientEngineActorPool with 1 actors
[2024-11-25 22:22:18,996][flwr][INFO] - Initializing global parameters
[2024-11-25 22:22:18,996][flwr][INFO] - Requesting initial parameters from one random client
[2024-11-25 22:22:24,924][flwr][INFO] - Received initial parameters from one random client
[2024-11-25 22:22:24,938][flwr][INFO] - Evaluating initial parameters
[2024-11-25 22:22:29,884][flwr][INFO] - initial parameters (loss, other metrics): 0.677150892656903, {'accuracy': 0.5348837209302325}
[2024-11-25 22:22:29,884][flwr][INFO] - FL starting
[2024-11-25 22:22:29,924][flwr][DEBUG] - fit_round 1: strategy sampled 10 clients (out of 20)
[2024-11-25 22:22:33,438][flwr][ERROR] - Traceback (most recent call last):
  File "/home/namvq/.cache/pypoetry/virtualenvs/niid-bench-orV17zke-py3.10/lib/python3.10/site-packages/flwr/simulation/ray_transport/ray_client_proxy.py", line 140, in _submit_job
    res = self.actor_pool.get_client_result(self.cid, timeout)
  File "/home/namvq/.cache/pypoetry/virtualenvs/niid-bench-orV17zke-py3.10/lib/python3.10/site-packages/flwr/simulation/ray_transport/ray_actor.py", line 402, in get_client_result
    return self._fetch_future_result(cid)
  File "/home/namvq/.cache/pypoetry/virtualenvs/niid-bench-orV17zke-py3.10/lib/python3.10/site-packages/flwr/simulation/ray_transport/ray_actor.py", line 288, in _fetch_future_result
    res_cid, res = ray.get(future)  # type: (str, ClientRes)
  File "/home/namvq/.cache/pypoetry/virtualenvs/niid-bench-orV17zke-py3.10/lib/python3.10/site-packages/ray/_private/auto_init_hook.py", line 24, in auto_init_wrapper
    return fn(*args, **kwargs)
  File "/home/namvq/.cache/pypoetry/virtualenvs/niid-bench-orV17zke-py3.10/lib/python3.10/site-packages/ray/_private/client_mode_hook.py", line 103, in wrapper
    return func(*args, **kwargs)
  File "/home/namvq/.cache/pypoetry/virtualenvs/niid-bench-orV17zke-py3.10/lib/python3.10/site-packages/ray/_private/worker.py", line 2524, in get
    raise value.as_instanceof_cause()
ray.exceptions.RayTaskError(ClientException): [36mray::DefaultActor.run()[39m (pid=54501, ip=192.168.1.62, actor_id=92fad4022c9447ce5fa980af01000000, repr=<flwr.simulation.ray_transport.ray_actor.DefaultActor object at 0x7a82b8193100>)
  File "/home/namvq/.cache/pypoetry/virtualenvs/niid-bench-orV17zke-py3.10/lib/python3.10/site-packages/flwr/simulation/ray_transport/ray_client_proxy.py", line 196, in fit
    return maybe_call_fit(
  File "/home/namvq/.cache/pypoetry/virtualenvs/niid-bench-orV17zke-py3.10/lib/python3.10/site-packages/flwr/client/client.py", line 217, in maybe_call_fit
    return client.fit(fit_ins)
  File "/home/namvq/.cache/pypoetry/virtualenvs/niid-bench-orV17zke-py3.10/lib/python3.10/site-packages/flwr/client/app.py", line 333, in _fit
    results = self.numpy_client.fit(parameters, ins.config)  # type: ignore
  File "/media/namvq/Data/code_flwr/niid_bench/niid_bench/client_scaffold.py", line 78, in fit
    train_scaffold(
  File "/media/namvq/Data/code_flwr/niid_bench/niid_bench/models.py", line 205, in train_scaffold
    net = _train_one_epoch_scaffold(
  File "/media/namvq/Data/code_flwr/niid_bench/niid_bench/models.py", line 227, in _train_one_epoch_scaffold
    optimizer.step_custom(server_cv, client_cv)
  File "/media/namvq/Data/code_flwr/niid_bench/niid_bench/models.py", line 157, in step_custom
    par.data.add_(s_cv - c_cv, alpha=-group["lr"])
RuntimeError: Expected all tensors to be on the same device, but found at least two devices, cuda:0 and cpu!

The above exception was the direct cause of the following exception:

[36mray::DefaultActor.run()[39m (pid=54501, ip=192.168.1.62, actor_id=92fad4022c9447ce5fa980af01000000, repr=<flwr.simulation.ray_transport.ray_actor.DefaultActor object at 0x7a82b8193100>)
  File "/home/namvq/.cache/pypoetry/virtualenvs/niid-bench-orV17zke-py3.10/lib/python3.10/site-packages/flwr/simulation/ray_transport/ray_actor.py", line 72, in run
    raise ClientException(str(message)) from ex
flwr.simulation.ray_transport.ray_actor.ClientException: 
>>>>>>>A ClientException occurred.('\n\tSomething went wrong when running your client workload.\n\tClient 10 crashed when the DefaultActor was running its workload.\n\tException triggered on the client side: Traceback (most recent call last):\n  File "/home/namvq/.cache/pypoetry/virtualenvs/niid-bench-orV17zke-py3.10/lib/python3.10/site-packages/flwr/simulation/ray_transport/ray_actor.py", line 60, in run\n    job_results = job_fn()\n  File "/home/namvq/.cache/pypoetry/virtualenvs/niid-bench-orV17zke-py3.10/lib/python3.10/site-packages/flwr/simulation/ray_transport/ray_client_proxy.py", line 196, in fit\n    return maybe_call_fit(\n  File "/home/namvq/.cache/pypoetry/virtualenvs/niid-bench-orV17zke-py3.10/lib/python3.10/site-packages/flwr/client/client.py", line 217, in maybe_call_fit\n    return client.fit(fit_ins)\n  File "/home/namvq/.cache/pypoetry/virtualenvs/niid-bench-orV17zke-py3.10/lib/python3.10/site-packages/flwr/client/app.py", line 333, in _fit\n    results = self.numpy_client.fit(parameters, ins.config)  # type: ignore\n  File "/media/namvq/Data/code_flwr/niid_bench/niid_bench/client_scaffold.py", line 78, in fit\n    train_scaffold(\n  File "/media/namvq/Data/code_flwr/niid_bench/niid_bench/models.py", line 205, in train_scaffold\n    net = _train_one_epoch_scaffold(\n  File "/media/namvq/Data/code_flwr/niid_bench/niid_bench/models.py", line 227, in _train_one_epoch_scaffold\n    optimizer.step_custom(server_cv, client_cv)\n  File "/media/namvq/Data/code_flwr/niid_bench/niid_bench/models.py", line 157, in step_custom\n    par.data.add_(s_cv - c_cv, alpha=-group["lr"])\nRuntimeError: Expected all tensors to be on the same device, but found at least two devices, cuda:0 and cpu!\n',)

[2024-11-25 22:22:33,439][flwr][ERROR] - [36mray::DefaultActor.run()[39m (pid=54501, ip=192.168.1.62, actor_id=92fad4022c9447ce5fa980af01000000, repr=<flwr.simulation.ray_transport.ray_actor.DefaultActor object at 0x7a82b8193100>)
  File "/home/namvq/.cache/pypoetry/virtualenvs/niid-bench-orV17zke-py3.10/lib/python3.10/site-packages/flwr/simulation/ray_transport/ray_client_proxy.py", line 196, in fit
    return maybe_call_fit(
  File "/home/namvq/.cache/pypoetry/virtualenvs/niid-bench-orV17zke-py3.10/lib/python3.10/site-packages/flwr/client/client.py", line 217, in maybe_call_fit
    return client.fit(fit_ins)
  File "/home/namvq/.cache/pypoetry/virtualenvs/niid-bench-orV17zke-py3.10/lib/python3.10/site-packages/flwr/client/app.py", line 333, in _fit
    results = self.numpy_client.fit(parameters, ins.config)  # type: ignore
  File "/media/namvq/Data/code_flwr/niid_bench/niid_bench/client_scaffold.py", line 78, in fit
    train_scaffold(
  File "/media/namvq/Data/code_flwr/niid_bench/niid_bench/models.py", line 205, in train_scaffold
    net = _train_one_epoch_scaffold(
  File "/media/namvq/Data/code_flwr/niid_bench/niid_bench/models.py", line 227, in _train_one_epoch_scaffold
    optimizer.step_custom(server_cv, client_cv)
  File "/media/namvq/Data/code_flwr/niid_bench/niid_bench/models.py", line 157, in step_custom
    par.data.add_(s_cv - c_cv, alpha=-group["lr"])
RuntimeError: Expected all tensors to be on the same device, but found at least two devices, cuda:0 and cpu!

The above exception was the direct cause of the following exception:

[36mray::DefaultActor.run()[39m (pid=54501, ip=192.168.1.62, actor_id=92fad4022c9447ce5fa980af01000000, repr=<flwr.simulation.ray_transport.ray_actor.DefaultActor object at 0x7a82b8193100>)
  File "/home/namvq/.cache/pypoetry/virtualenvs/niid-bench-orV17zke-py3.10/lib/python3.10/site-packages/flwr/simulation/ray_transport/ray_actor.py", line 72, in run
    raise ClientException(str(message)) from ex
flwr.simulation.ray_transport.ray_actor.ClientException: 
>>>>>>>A ClientException occurred.('\n\tSomething went wrong when running your client workload.\n\tClient 10 crashed when the DefaultActor was running its workload.\n\tException triggered on the client side: Traceback (most recent call last):\n  File "/home/namvq/.cache/pypoetry/virtualenvs/niid-bench-orV17zke-py3.10/lib/python3.10/site-packages/flwr/simulation/ray_transport/ray_actor.py", line 60, in run\n    job_results = job_fn()\n  File "/home/namvq/.cache/pypoetry/virtualenvs/niid-bench-orV17zke-py3.10/lib/python3.10/site-packages/flwr/simulation/ray_transport/ray_client_proxy.py", line 196, in fit\n    return maybe_call_fit(\n  File "/home/namvq/.cache/pypoetry/virtualenvs/niid-bench-orV17zke-py3.10/lib/python3.10/site-packages/flwr/client/client.py", line 217, in maybe_call_fit\n    return client.fit(fit_ins)\n  File "/home/namvq/.cache/pypoetry/virtualenvs/niid-bench-orV17zke-py3.10/lib/python3.10/site-packages/flwr/client/app.py", line 333, in _fit\n    results = self.numpy_client.fit(parameters, ins.config)  # type: ignore\n  File "/media/namvq/Data/code_flwr/niid_bench/niid_bench/client_scaffold.py", line 78, in fit\n    train_scaffold(\n  File "/media/namvq/Data/code_flwr/niid_bench/niid_bench/models.py", line 205, in train_scaffold\n    net = _train_one_epoch_scaffold(\n  File "/media/namvq/Data/code_flwr/niid_bench/niid_bench/models.py", line 227, in _train_one_epoch_scaffold\n    optimizer.step_custom(server_cv, client_cv)\n  File "/media/namvq/Data/code_flwr/niid_bench/niid_bench/models.py", line 157, in step_custom\n    par.data.add_(s_cv - c_cv, alpha=-group["lr"])\nRuntimeError: Expected all tensors to be on the same device, but found at least two devices, cuda:0 and cpu!\n',)
[2024-11-25 22:22:35,396][flwr][ERROR] - Traceback (most recent call last):
  File "/home/namvq/.cache/pypoetry/virtualenvs/niid-bench-orV17zke-py3.10/lib/python3.10/site-packages/flwr/simulation/ray_transport/ray_client_proxy.py", line 140, in _submit_job
    res = self.actor_pool.get_client_result(self.cid, timeout)
  File "/home/namvq/.cache/pypoetry/virtualenvs/niid-bench-orV17zke-py3.10/lib/python3.10/site-packages/flwr/simulation/ray_transport/ray_actor.py", line 402, in get_client_result
    return self._fetch_future_result(cid)
  File "/home/namvq/.cache/pypoetry/virtualenvs/niid-bench-orV17zke-py3.10/lib/python3.10/site-packages/flwr/simulation/ray_transport/ray_actor.py", line 288, in _fetch_future_result
    res_cid, res = ray.get(future)  # type: (str, ClientRes)
  File "/home/namvq/.cache/pypoetry/virtualenvs/niid-bench-orV17zke-py3.10/lib/python3.10/site-packages/ray/_private/auto_init_hook.py", line 24, in auto_init_wrapper
    return fn(*args, **kwargs)
  File "/home/namvq/.cache/pypoetry/virtualenvs/niid-bench-orV17zke-py3.10/lib/python3.10/site-packages/ray/_private/client_mode_hook.py", line 103, in wrapper
    return func(*args, **kwargs)
  File "/home/namvq/.cache/pypoetry/virtualenvs/niid-bench-orV17zke-py3.10/lib/python3.10/site-packages/ray/_private/worker.py", line 2524, in get
    raise value.as_instanceof_cause()
ray.exceptions.RayTaskError(ClientException): [36mray::DefaultActor.run()[39m (pid=54501, ip=192.168.1.62, actor_id=92fad4022c9447ce5fa980af01000000, repr=<flwr.simulation.ray_transport.ray_actor.DefaultActor object at 0x7a82b8193100>)
  File "/home/namvq/.cache/pypoetry/virtualenvs/niid-bench-orV17zke-py3.10/lib/python3.10/site-packages/flwr/simulation/ray_transport/ray_client_proxy.py", line 196, in fit
    return maybe_call_fit(
  File "/home/namvq/.cache/pypoetry/virtualenvs/niid-bench-orV17zke-py3.10/lib/python3.10/site-packages/flwr/client/client.py", line 217, in maybe_call_fit
    return client.fit(fit_ins)
  File "/home/namvq/.cache/pypoetry/virtualenvs/niid-bench-orV17zke-py3.10/lib/python3.10/site-packages/flwr/client/app.py", line 333, in _fit
    results = self.numpy_client.fit(parameters, ins.config)  # type: ignore
  File "/media/namvq/Data/code_flwr/niid_bench/niid_bench/client_scaffold.py", line 78, in fit
    train_scaffold(
  File "/media/namvq/Data/code_flwr/niid_bench/niid_bench/models.py", line 205, in train_scaffold
    net = _train_one_epoch_scaffold(
  File "/media/namvq/Data/code_flwr/niid_bench/niid_bench/models.py", line 227, in _train_one_epoch_scaffold
    optimizer.step_custom(server_cv, client_cv)
  File "/media/namvq/Data/code_flwr/niid_bench/niid_bench/models.py", line 157, in step_custom
    par.data.add_(s_cv - c_cv, alpha=-group["lr"])
RuntimeError: Expected all tensors to be on the same device, but found at least two devices, cuda:0 and cpu!

The above exception was the direct cause of the following exception:

[36mray::DefaultActor.run()[39m (pid=54501, ip=192.168.1.62, actor_id=92fad4022c9447ce5fa980af01000000, repr=<flwr.simulation.ray_transport.ray_actor.DefaultActor object at 0x7a82b8193100>)
  File "/home/namvq/.cache/pypoetry/virtualenvs/niid-bench-orV17zke-py3.10/lib/python3.10/site-packages/flwr/simulation/ray_transport/ray_actor.py", line 72, in run
    raise ClientException(str(message)) from ex
flwr.simulation.ray_transport.ray_actor.ClientException: 
>>>>>>>A ClientException occurred.('\n\tSomething went wrong when running your client workload.\n\tClient 6 crashed when the DefaultActor was running its workload.\n\tException triggered on the client side: Traceback (most recent call last):\n  File "/home/namvq/.cache/pypoetry/virtualenvs/niid-bench-orV17zke-py3.10/lib/python3.10/site-packages/flwr/simulation/ray_transport/ray_actor.py", line 60, in run\n    job_results = job_fn()\n  File "/home/namvq/.cache/pypoetry/virtualenvs/niid-bench-orV17zke-py3.10/lib/python3.10/site-packages/flwr/simulation/ray_transport/ray_client_proxy.py", line 196, in fit\n    return maybe_call_fit(\n  File "/home/namvq/.cache/pypoetry/virtualenvs/niid-bench-orV17zke-py3.10/lib/python3.10/site-packages/flwr/client/client.py", line 217, in maybe_call_fit\n    return client.fit(fit_ins)\n  File "/home/namvq/.cache/pypoetry/virtualenvs/niid-bench-orV17zke-py3.10/lib/python3.10/site-packages/flwr/client/app.py", line 333, in _fit\n    results = self.numpy_client.fit(parameters, ins.config)  # type: ignore\n  File "/media/namvq/Data/code_flwr/niid_bench/niid_bench/client_scaffold.py", line 78, in fit\n    train_scaffold(\n  File "/media/namvq/Data/code_flwr/niid_bench/niid_bench/models.py", line 205, in train_scaffold\n    net = _train_one_epoch_scaffold(\n  File "/media/namvq/Data/code_flwr/niid_bench/niid_bench/models.py", line 227, in _train_one_epoch_scaffold\n    optimizer.step_custom(server_cv, client_cv)\n  File "/media/namvq/Data/code_flwr/niid_bench/niid_bench/models.py", line 157, in step_custom\n    par.data.add_(s_cv - c_cv, alpha=-group["lr"])\nRuntimeError: Expected all tensors to be on the same device, but found at least two devices, cuda:0 and cpu!\n',)

[2024-11-25 22:22:35,396][flwr][ERROR] - [36mray::DefaultActor.run()[39m (pid=54501, ip=192.168.1.62, actor_id=92fad4022c9447ce5fa980af01000000, repr=<flwr.simulation.ray_transport.ray_actor.DefaultActor object at 0x7a82b8193100>)
  File "/home/namvq/.cache/pypoetry/virtualenvs/niid-bench-orV17zke-py3.10/lib/python3.10/site-packages/flwr/simulation/ray_transport/ray_client_proxy.py", line 196, in fit
    return maybe_call_fit(
  File "/home/namvq/.cache/pypoetry/virtualenvs/niid-bench-orV17zke-py3.10/lib/python3.10/site-packages/flwr/client/client.py", line 217, in maybe_call_fit
    return client.fit(fit_ins)
  File "/home/namvq/.cache/pypoetry/virtualenvs/niid-bench-orV17zke-py3.10/lib/python3.10/site-packages/flwr/client/app.py", line 333, in _fit
    results = self.numpy_client.fit(parameters, ins.config)  # type: ignore
  File "/media/namvq/Data/code_flwr/niid_bench/niid_bench/client_scaffold.py", line 78, in fit
    train_scaffold(
  File "/media/namvq/Data/code_flwr/niid_bench/niid_bench/models.py", line 205, in train_scaffold
    net = _train_one_epoch_scaffold(
  File "/media/namvq/Data/code_flwr/niid_bench/niid_bench/models.py", line 227, in _train_one_epoch_scaffold
    optimizer.step_custom(server_cv, client_cv)
  File "/media/namvq/Data/code_flwr/niid_bench/niid_bench/models.py", line 157, in step_custom
    par.data.add_(s_cv - c_cv, alpha=-group["lr"])
RuntimeError: Expected all tensors to be on the same device, but found at least two devices, cuda:0 and cpu!

The above exception was the direct cause of the following exception:

[36mray::DefaultActor.run()[39m (pid=54501, ip=192.168.1.62, actor_id=92fad4022c9447ce5fa980af01000000, repr=<flwr.simulation.ray_transport.ray_actor.DefaultActor object at 0x7a82b8193100>)
  File "/home/namvq/.cache/pypoetry/virtualenvs/niid-bench-orV17zke-py3.10/lib/python3.10/site-packages/flwr/simulation/ray_transport/ray_actor.py", line 72, in run
    raise ClientException(str(message)) from ex
flwr.simulation.ray_transport.ray_actor.ClientException: 
>>>>>>>A ClientException occurred.('\n\tSomething went wrong when running your client workload.\n\tClient 6 crashed when the DefaultActor was running its workload.\n\tException triggered on the client side: Traceback (most recent call last):\n  File "/home/namvq/.cache/pypoetry/virtualenvs/niid-bench-orV17zke-py3.10/lib/python3.10/site-packages/flwr/simulation/ray_transport/ray_actor.py", line 60, in run\n    job_results = job_fn()\n  File "/home/namvq/.cache/pypoetry/virtualenvs/niid-bench-orV17zke-py3.10/lib/python3.10/site-packages/flwr/simulation/ray_transport/ray_client_proxy.py", line 196, in fit\n    return maybe_call_fit(\n  File "/home/namvq/.cache/pypoetry/virtualenvs/niid-bench-orV17zke-py3.10/lib/python3.10/site-packages/flwr/client/client.py", line 217, in maybe_call_fit\n    return client.fit(fit_ins)\n  File "/home/namvq/.cache/pypoetry/virtualenvs/niid-bench-orV17zke-py3.10/lib/python3.10/site-packages/flwr/client/app.py", line 333, in _fit\n    results = self.numpy_client.fit(parameters, ins.config)  # type: ignore\n  File "/media/namvq/Data/code_flwr/niid_bench/niid_bench/client_scaffold.py", line 78, in fit\n    train_scaffold(\n  File "/media/namvq/Data/code_flwr/niid_bench/niid_bench/models.py", line 205, in train_scaffold\n    net = _train_one_epoch_scaffold(\n  File "/media/namvq/Data/code_flwr/niid_bench/niid_bench/models.py", line 227, in _train_one_epoch_scaffold\n    optimizer.step_custom(server_cv, client_cv)\n  File "/media/namvq/Data/code_flwr/niid_bench/niid_bench/models.py", line 157, in step_custom\n    par.data.add_(s_cv - c_cv, alpha=-group["lr"])\nRuntimeError: Expected all tensors to be on the same device, but found at least two devices, cuda:0 and cpu!\n',)
[2024-11-25 22:22:37,374][flwr][ERROR] - Traceback (most recent call last):
  File "/home/namvq/.cache/pypoetry/virtualenvs/niid-bench-orV17zke-py3.10/lib/python3.10/site-packages/flwr/simulation/ray_transport/ray_client_proxy.py", line 140, in _submit_job
    res = self.actor_pool.get_client_result(self.cid, timeout)
  File "/home/namvq/.cache/pypoetry/virtualenvs/niid-bench-orV17zke-py3.10/lib/python3.10/site-packages/flwr/simulation/ray_transport/ray_actor.py", line 402, in get_client_result
    return self._fetch_future_result(cid)
  File "/home/namvq/.cache/pypoetry/virtualenvs/niid-bench-orV17zke-py3.10/lib/python3.10/site-packages/flwr/simulation/ray_transport/ray_actor.py", line 288, in _fetch_future_result
    res_cid, res = ray.get(future)  # type: (str, ClientRes)
  File "/home/namvq/.cache/pypoetry/virtualenvs/niid-bench-orV17zke-py3.10/lib/python3.10/site-packages/ray/_private/auto_init_hook.py", line 24, in auto_init_wrapper
    return fn(*args, **kwargs)
  File "/home/namvq/.cache/pypoetry/virtualenvs/niid-bench-orV17zke-py3.10/lib/python3.10/site-packages/ray/_private/client_mode_hook.py", line 103, in wrapper
    return func(*args, **kwargs)
  File "/home/namvq/.cache/pypoetry/virtualenvs/niid-bench-orV17zke-py3.10/lib/python3.10/site-packages/ray/_private/worker.py", line 2524, in get
    raise value.as_instanceof_cause()
ray.exceptions.RayTaskError(ClientException): [36mray::DefaultActor.run()[39m (pid=54501, ip=192.168.1.62, actor_id=92fad4022c9447ce5fa980af01000000, repr=<flwr.simulation.ray_transport.ray_actor.DefaultActor object at 0x7a82b8193100>)
  File "/home/namvq/.cache/pypoetry/virtualenvs/niid-bench-orV17zke-py3.10/lib/python3.10/site-packages/flwr/simulation/ray_transport/ray_client_proxy.py", line 196, in fit
    return maybe_call_fit(
  File "/home/namvq/.cache/pypoetry/virtualenvs/niid-bench-orV17zke-py3.10/lib/python3.10/site-packages/flwr/client/client.py", line 217, in maybe_call_fit
    return client.fit(fit_ins)
  File "/home/namvq/.cache/pypoetry/virtualenvs/niid-bench-orV17zke-py3.10/lib/python3.10/site-packages/flwr/client/app.py", line 333, in _fit
    results = self.numpy_client.fit(parameters, ins.config)  # type: ignore
  File "/media/namvq/Data/code_flwr/niid_bench/niid_bench/client_scaffold.py", line 78, in fit
    train_scaffold(
  File "/media/namvq/Data/code_flwr/niid_bench/niid_bench/models.py", line 205, in train_scaffold
    net = _train_one_epoch_scaffold(
  File "/media/namvq/Data/code_flwr/niid_bench/niid_bench/models.py", line 227, in _train_one_epoch_scaffold
    optimizer.step_custom(server_cv, client_cv)
  File "/media/namvq/Data/code_flwr/niid_bench/niid_bench/models.py", line 157, in step_custom
    par.data.add_(s_cv - c_cv, alpha=-group["lr"])
RuntimeError: Expected all tensors to be on the same device, but found at least two devices, cuda:0 and cpu!

The above exception was the direct cause of the following exception:

[36mray::DefaultActor.run()[39m (pid=54501, ip=192.168.1.62, actor_id=92fad4022c9447ce5fa980af01000000, repr=<flwr.simulation.ray_transport.ray_actor.DefaultActor object at 0x7a82b8193100>)
  File "/home/namvq/.cache/pypoetry/virtualenvs/niid-bench-orV17zke-py3.10/lib/python3.10/site-packages/flwr/simulation/ray_transport/ray_actor.py", line 72, in run
    raise ClientException(str(message)) from ex
flwr.simulation.ray_transport.ray_actor.ClientException: 
>>>>>>>A ClientException occurred.('\n\tSomething went wrong when running your client workload.\n\tClient 4 crashed when the DefaultActor was running its workload.\n\tException triggered on the client side: Traceback (most recent call last):\n  File "/home/namvq/.cache/pypoetry/virtualenvs/niid-bench-orV17zke-py3.10/lib/python3.10/site-packages/flwr/simulation/ray_transport/ray_actor.py", line 60, in run\n    job_results = job_fn()\n  File "/home/namvq/.cache/pypoetry/virtualenvs/niid-bench-orV17zke-py3.10/lib/python3.10/site-packages/flwr/simulation/ray_transport/ray_client_proxy.py", line 196, in fit\n    return maybe_call_fit(\n  File "/home/namvq/.cache/pypoetry/virtualenvs/niid-bench-orV17zke-py3.10/lib/python3.10/site-packages/flwr/client/client.py", line 217, in maybe_call_fit\n    return client.fit(fit_ins)\n  File "/home/namvq/.cache/pypoetry/virtualenvs/niid-bench-orV17zke-py3.10/lib/python3.10/site-packages/flwr/client/app.py", line 333, in _fit\n    results = self.numpy_client.fit(parameters, ins.config)  # type: ignore\n  File "/media/namvq/Data/code_flwr/niid_bench/niid_bench/client_scaffold.py", line 78, in fit\n    train_scaffold(\n  File "/media/namvq/Data/code_flwr/niid_bench/niid_bench/models.py", line 205, in train_scaffold\n    net = _train_one_epoch_scaffold(\n  File "/media/namvq/Data/code_flwr/niid_bench/niid_bench/models.py", line 227, in _train_one_epoch_scaffold\n    optimizer.step_custom(server_cv, client_cv)\n  File "/media/namvq/Data/code_flwr/niid_bench/niid_bench/models.py", line 157, in step_custom\n    par.data.add_(s_cv - c_cv, alpha=-group["lr"])\nRuntimeError: Expected all tensors to be on the same device, but found at least two devices, cuda:0 and cpu!\n',)

[2024-11-25 22:22:37,375][flwr][ERROR] - [36mray::DefaultActor.run()[39m (pid=54501, ip=192.168.1.62, actor_id=92fad4022c9447ce5fa980af01000000, repr=<flwr.simulation.ray_transport.ray_actor.DefaultActor object at 0x7a82b8193100>)
  File "/home/namvq/.cache/pypoetry/virtualenvs/niid-bench-orV17zke-py3.10/lib/python3.10/site-packages/flwr/simulation/ray_transport/ray_client_proxy.py", line 196, in fit
    return maybe_call_fit(
  File "/home/namvq/.cache/pypoetry/virtualenvs/niid-bench-orV17zke-py3.10/lib/python3.10/site-packages/flwr/client/client.py", line 217, in maybe_call_fit
    return client.fit(fit_ins)
  File "/home/namvq/.cache/pypoetry/virtualenvs/niid-bench-orV17zke-py3.10/lib/python3.10/site-packages/flwr/client/app.py", line 333, in _fit
    results = self.numpy_client.fit(parameters, ins.config)  # type: ignore
  File "/media/namvq/Data/code_flwr/niid_bench/niid_bench/client_scaffold.py", line 78, in fit
    train_scaffold(
  File "/media/namvq/Data/code_flwr/niid_bench/niid_bench/models.py", line 205, in train_scaffold
    net = _train_one_epoch_scaffold(
  File "/media/namvq/Data/code_flwr/niid_bench/niid_bench/models.py", line 227, in _train_one_epoch_scaffold
    optimizer.step_custom(server_cv, client_cv)
  File "/media/namvq/Data/code_flwr/niid_bench/niid_bench/models.py", line 157, in step_custom
    par.data.add_(s_cv - c_cv, alpha=-group["lr"])
RuntimeError: Expected all tensors to be on the same device, but found at least two devices, cuda:0 and cpu!

The above exception was the direct cause of the following exception:

[36mray::DefaultActor.run()[39m (pid=54501, ip=192.168.1.62, actor_id=92fad4022c9447ce5fa980af01000000, repr=<flwr.simulation.ray_transport.ray_actor.DefaultActor object at 0x7a82b8193100>)
  File "/home/namvq/.cache/pypoetry/virtualenvs/niid-bench-orV17zke-py3.10/lib/python3.10/site-packages/flwr/simulation/ray_transport/ray_actor.py", line 72, in run
    raise ClientException(str(message)) from ex
flwr.simulation.ray_transport.ray_actor.ClientException: 
>>>>>>>A ClientException occurred.('\n\tSomething went wrong when running your client workload.\n\tClient 4 crashed when the DefaultActor was running its workload.\n\tException triggered on the client side: Traceback (most recent call last):\n  File "/home/namvq/.cache/pypoetry/virtualenvs/niid-bench-orV17zke-py3.10/lib/python3.10/site-packages/flwr/simulation/ray_transport/ray_actor.py", line 60, in run\n    job_results = job_fn()\n  File "/home/namvq/.cache/pypoetry/virtualenvs/niid-bench-orV17zke-py3.10/lib/python3.10/site-packages/flwr/simulation/ray_transport/ray_client_proxy.py", line 196, in fit\n    return maybe_call_fit(\n  File "/home/namvq/.cache/pypoetry/virtualenvs/niid-bench-orV17zke-py3.10/lib/python3.10/site-packages/flwr/client/client.py", line 217, in maybe_call_fit\n    return client.fit(fit_ins)\n  File "/home/namvq/.cache/pypoetry/virtualenvs/niid-bench-orV17zke-py3.10/lib/python3.10/site-packages/flwr/client/app.py", line 333, in _fit\n    results = self.numpy_client.fit(parameters, ins.config)  # type: ignore\n  File "/media/namvq/Data/code_flwr/niid_bench/niid_bench/client_scaffold.py", line 78, in fit\n    train_scaffold(\n  File "/media/namvq/Data/code_flwr/niid_bench/niid_bench/models.py", line 205, in train_scaffold\n    net = _train_one_epoch_scaffold(\n  File "/media/namvq/Data/code_flwr/niid_bench/niid_bench/models.py", line 227, in _train_one_epoch_scaffold\n    optimizer.step_custom(server_cv, client_cv)\n  File "/media/namvq/Data/code_flwr/niid_bench/niid_bench/models.py", line 157, in step_custom\n    par.data.add_(s_cv - c_cv, alpha=-group["lr"])\nRuntimeError: Expected all tensors to be on the same device, but found at least two devices, cuda:0 and cpu!\n',)
[2024-11-25 22:22:39,302][flwr][ERROR] - Traceback (most recent call last):
  File "/home/namvq/.cache/pypoetry/virtualenvs/niid-bench-orV17zke-py3.10/lib/python3.10/site-packages/flwr/simulation/ray_transport/ray_client_proxy.py", line 140, in _submit_job
    res = self.actor_pool.get_client_result(self.cid, timeout)
  File "/home/namvq/.cache/pypoetry/virtualenvs/niid-bench-orV17zke-py3.10/lib/python3.10/site-packages/flwr/simulation/ray_transport/ray_actor.py", line 402, in get_client_result
    return self._fetch_future_result(cid)
  File "/home/namvq/.cache/pypoetry/virtualenvs/niid-bench-orV17zke-py3.10/lib/python3.10/site-packages/flwr/simulation/ray_transport/ray_actor.py", line 288, in _fetch_future_result
    res_cid, res = ray.get(future)  # type: (str, ClientRes)
  File "/home/namvq/.cache/pypoetry/virtualenvs/niid-bench-orV17zke-py3.10/lib/python3.10/site-packages/ray/_private/auto_init_hook.py", line 24, in auto_init_wrapper
    return fn(*args, **kwargs)
  File "/home/namvq/.cache/pypoetry/virtualenvs/niid-bench-orV17zke-py3.10/lib/python3.10/site-packages/ray/_private/client_mode_hook.py", line 103, in wrapper
    return func(*args, **kwargs)
  File "/home/namvq/.cache/pypoetry/virtualenvs/niid-bench-orV17zke-py3.10/lib/python3.10/site-packages/ray/_private/worker.py", line 2524, in get
    raise value.as_instanceof_cause()
ray.exceptions.RayTaskError(ClientException): [36mray::DefaultActor.run()[39m (pid=54501, ip=192.168.1.62, actor_id=92fad4022c9447ce5fa980af01000000, repr=<flwr.simulation.ray_transport.ray_actor.DefaultActor object at 0x7a82b8193100>)
  File "/home/namvq/.cache/pypoetry/virtualenvs/niid-bench-orV17zke-py3.10/lib/python3.10/site-packages/flwr/simulation/ray_transport/ray_client_proxy.py", line 196, in fit
    return maybe_call_fit(
  File "/home/namvq/.cache/pypoetry/virtualenvs/niid-bench-orV17zke-py3.10/lib/python3.10/site-packages/flwr/client/client.py", line 217, in maybe_call_fit
    return client.fit(fit_ins)
  File "/home/namvq/.cache/pypoetry/virtualenvs/niid-bench-orV17zke-py3.10/lib/python3.10/site-packages/flwr/client/app.py", line 333, in _fit
    results = self.numpy_client.fit(parameters, ins.config)  # type: ignore
  File "/media/namvq/Data/code_flwr/niid_bench/niid_bench/client_scaffold.py", line 78, in fit
    train_scaffold(
  File "/media/namvq/Data/code_flwr/niid_bench/niid_bench/models.py", line 205, in train_scaffold
    net = _train_one_epoch_scaffold(
  File "/media/namvq/Data/code_flwr/niid_bench/niid_bench/models.py", line 227, in _train_one_epoch_scaffold
    optimizer.step_custom(server_cv, client_cv)
  File "/media/namvq/Data/code_flwr/niid_bench/niid_bench/models.py", line 157, in step_custom
    par.data.add_(s_cv - c_cv, alpha=-group["lr"])
RuntimeError: Expected all tensors to be on the same device, but found at least two devices, cuda:0 and cpu!

The above exception was the direct cause of the following exception:

[36mray::DefaultActor.run()[39m (pid=54501, ip=192.168.1.62, actor_id=92fad4022c9447ce5fa980af01000000, repr=<flwr.simulation.ray_transport.ray_actor.DefaultActor object at 0x7a82b8193100>)
  File "/home/namvq/.cache/pypoetry/virtualenvs/niid-bench-orV17zke-py3.10/lib/python3.10/site-packages/flwr/simulation/ray_transport/ray_actor.py", line 72, in run
    raise ClientException(str(message)) from ex
flwr.simulation.ray_transport.ray_actor.ClientException: 
>>>>>>>A ClientException occurred.('\n\tSomething went wrong when running your client workload.\n\tClient 18 crashed when the DefaultActor was running its workload.\n\tException triggered on the client side: Traceback (most recent call last):\n  File "/home/namvq/.cache/pypoetry/virtualenvs/niid-bench-orV17zke-py3.10/lib/python3.10/site-packages/flwr/simulation/ray_transport/ray_actor.py", line 60, in run\n    job_results = job_fn()\n  File "/home/namvq/.cache/pypoetry/virtualenvs/niid-bench-orV17zke-py3.10/lib/python3.10/site-packages/flwr/simulation/ray_transport/ray_client_proxy.py", line 196, in fit\n    return maybe_call_fit(\n  File "/home/namvq/.cache/pypoetry/virtualenvs/niid-bench-orV17zke-py3.10/lib/python3.10/site-packages/flwr/client/client.py", line 217, in maybe_call_fit\n    return client.fit(fit_ins)\n  File "/home/namvq/.cache/pypoetry/virtualenvs/niid-bench-orV17zke-py3.10/lib/python3.10/site-packages/flwr/client/app.py", line 333, in _fit\n    results = self.numpy_client.fit(parameters, ins.config)  # type: ignore\n  File "/media/namvq/Data/code_flwr/niid_bench/niid_bench/client_scaffold.py", line 78, in fit\n    train_scaffold(\n  File "/media/namvq/Data/code_flwr/niid_bench/niid_bench/models.py", line 205, in train_scaffold\n    net = _train_one_epoch_scaffold(\n  File "/media/namvq/Data/code_flwr/niid_bench/niid_bench/models.py", line 227, in _train_one_epoch_scaffold\n    optimizer.step_custom(server_cv, client_cv)\n  File "/media/namvq/Data/code_flwr/niid_bench/niid_bench/models.py", line 157, in step_custom\n    par.data.add_(s_cv - c_cv, alpha=-group["lr"])\nRuntimeError: Expected all tensors to be on the same device, but found at least two devices, cuda:0 and cpu!\n',)

[2024-11-25 22:22:39,303][flwr][ERROR] - [36mray::DefaultActor.run()[39m (pid=54501, ip=192.168.1.62, actor_id=92fad4022c9447ce5fa980af01000000, repr=<flwr.simulation.ray_transport.ray_actor.DefaultActor object at 0x7a82b8193100>)
  File "/home/namvq/.cache/pypoetry/virtualenvs/niid-bench-orV17zke-py3.10/lib/python3.10/site-packages/flwr/simulation/ray_transport/ray_client_proxy.py", line 196, in fit
    return maybe_call_fit(
  File "/home/namvq/.cache/pypoetry/virtualenvs/niid-bench-orV17zke-py3.10/lib/python3.10/site-packages/flwr/client/client.py", line 217, in maybe_call_fit
    return client.fit(fit_ins)
  File "/home/namvq/.cache/pypoetry/virtualenvs/niid-bench-orV17zke-py3.10/lib/python3.10/site-packages/flwr/client/app.py", line 333, in _fit
    results = self.numpy_client.fit(parameters, ins.config)  # type: ignore
  File "/media/namvq/Data/code_flwr/niid_bench/niid_bench/client_scaffold.py", line 78, in fit
    train_scaffold(
  File "/media/namvq/Data/code_flwr/niid_bench/niid_bench/models.py", line 205, in train_scaffold
    net = _train_one_epoch_scaffold(
  File "/media/namvq/Data/code_flwr/niid_bench/niid_bench/models.py", line 227, in _train_one_epoch_scaffold
    optimizer.step_custom(server_cv, client_cv)
  File "/media/namvq/Data/code_flwr/niid_bench/niid_bench/models.py", line 157, in step_custom
    par.data.add_(s_cv - c_cv, alpha=-group["lr"])
RuntimeError: Expected all tensors to be on the same device, but found at least two devices, cuda:0 and cpu!

The above exception was the direct cause of the following exception:

[36mray::DefaultActor.run()[39m (pid=54501, ip=192.168.1.62, actor_id=92fad4022c9447ce5fa980af01000000, repr=<flwr.simulation.ray_transport.ray_actor.DefaultActor object at 0x7a82b8193100>)
  File "/home/namvq/.cache/pypoetry/virtualenvs/niid-bench-orV17zke-py3.10/lib/python3.10/site-packages/flwr/simulation/ray_transport/ray_actor.py", line 72, in run
    raise ClientException(str(message)) from ex
flwr.simulation.ray_transport.ray_actor.ClientException: 
>>>>>>>A ClientException occurred.('\n\tSomething went wrong when running your client workload.\n\tClient 18 crashed when the DefaultActor was running its workload.\n\tException triggered on the client side: Traceback (most recent call last):\n  File "/home/namvq/.cache/pypoetry/virtualenvs/niid-bench-orV17zke-py3.10/lib/python3.10/site-packages/flwr/simulation/ray_transport/ray_actor.py", line 60, in run\n    job_results = job_fn()\n  File "/home/namvq/.cache/pypoetry/virtualenvs/niid-bench-orV17zke-py3.10/lib/python3.10/site-packages/flwr/simulation/ray_transport/ray_client_proxy.py", line 196, in fit\n    return maybe_call_fit(\n  File "/home/namvq/.cache/pypoetry/virtualenvs/niid-bench-orV17zke-py3.10/lib/python3.10/site-packages/flwr/client/client.py", line 217, in maybe_call_fit\n    return client.fit(fit_ins)\n  File "/home/namvq/.cache/pypoetry/virtualenvs/niid-bench-orV17zke-py3.10/lib/python3.10/site-packages/flwr/client/app.py", line 333, in _fit\n    results = self.numpy_client.fit(parameters, ins.config)  # type: ignore\n  File "/media/namvq/Data/code_flwr/niid_bench/niid_bench/client_scaffold.py", line 78, in fit\n    train_scaffold(\n  File "/media/namvq/Data/code_flwr/niid_bench/niid_bench/models.py", line 205, in train_scaffold\n    net = _train_one_epoch_scaffold(\n  File "/media/namvq/Data/code_flwr/niid_bench/niid_bench/models.py", line 227, in _train_one_epoch_scaffold\n    optimizer.step_custom(server_cv, client_cv)\n  File "/media/namvq/Data/code_flwr/niid_bench/niid_bench/models.py", line 157, in step_custom\n    par.data.add_(s_cv - c_cv, alpha=-group["lr"])\nRuntimeError: Expected all tensors to be on the same device, but found at least two devices, cuda:0 and cpu!\n',)
[2024-11-25 22:22:41,200][flwr][ERROR] - Traceback (most recent call last):
  File "/home/namvq/.cache/pypoetry/virtualenvs/niid-bench-orV17zke-py3.10/lib/python3.10/site-packages/flwr/simulation/ray_transport/ray_client_proxy.py", line 140, in _submit_job
    res = self.actor_pool.get_client_result(self.cid, timeout)
  File "/home/namvq/.cache/pypoetry/virtualenvs/niid-bench-orV17zke-py3.10/lib/python3.10/site-packages/flwr/simulation/ray_transport/ray_actor.py", line 402, in get_client_result
    return self._fetch_future_result(cid)
  File "/home/namvq/.cache/pypoetry/virtualenvs/niid-bench-orV17zke-py3.10/lib/python3.10/site-packages/flwr/simulation/ray_transport/ray_actor.py", line 288, in _fetch_future_result
    res_cid, res = ray.get(future)  # type: (str, ClientRes)
  File "/home/namvq/.cache/pypoetry/virtualenvs/niid-bench-orV17zke-py3.10/lib/python3.10/site-packages/ray/_private/auto_init_hook.py", line 24, in auto_init_wrapper
    return fn(*args, **kwargs)
  File "/home/namvq/.cache/pypoetry/virtualenvs/niid-bench-orV17zke-py3.10/lib/python3.10/site-packages/ray/_private/client_mode_hook.py", line 103, in wrapper
    return func(*args, **kwargs)
  File "/home/namvq/.cache/pypoetry/virtualenvs/niid-bench-orV17zke-py3.10/lib/python3.10/site-packages/ray/_private/worker.py", line 2524, in get
    raise value.as_instanceof_cause()
ray.exceptions.RayTaskError(ClientException): [36mray::DefaultActor.run()[39m (pid=54501, ip=192.168.1.62, actor_id=92fad4022c9447ce5fa980af01000000, repr=<flwr.simulation.ray_transport.ray_actor.DefaultActor object at 0x7a82b8193100>)
  File "/home/namvq/.cache/pypoetry/virtualenvs/niid-bench-orV17zke-py3.10/lib/python3.10/site-packages/flwr/simulation/ray_transport/ray_client_proxy.py", line 196, in fit
    return maybe_call_fit(
  File "/home/namvq/.cache/pypoetry/virtualenvs/niid-bench-orV17zke-py3.10/lib/python3.10/site-packages/flwr/client/client.py", line 217, in maybe_call_fit
    return client.fit(fit_ins)
  File "/home/namvq/.cache/pypoetry/virtualenvs/niid-bench-orV17zke-py3.10/lib/python3.10/site-packages/flwr/client/app.py", line 333, in _fit
    results = self.numpy_client.fit(parameters, ins.config)  # type: ignore
  File "/media/namvq/Data/code_flwr/niid_bench/niid_bench/client_scaffold.py", line 78, in fit
    train_scaffold(
  File "/media/namvq/Data/code_flwr/niid_bench/niid_bench/models.py", line 205, in train_scaffold
    net = _train_one_epoch_scaffold(
  File "/media/namvq/Data/code_flwr/niid_bench/niid_bench/models.py", line 227, in _train_one_epoch_scaffold
    optimizer.step_custom(server_cv, client_cv)
  File "/media/namvq/Data/code_flwr/niid_bench/niid_bench/models.py", line 157, in step_custom
    par.data.add_(s_cv - c_cv, alpha=-group["lr"])
RuntimeError: Expected all tensors to be on the same device, but found at least two devices, cuda:0 and cpu!

The above exception was the direct cause of the following exception:

[36mray::DefaultActor.run()[39m (pid=54501, ip=192.168.1.62, actor_id=92fad4022c9447ce5fa980af01000000, repr=<flwr.simulation.ray_transport.ray_actor.DefaultActor object at 0x7a82b8193100>)
  File "/home/namvq/.cache/pypoetry/virtualenvs/niid-bench-orV17zke-py3.10/lib/python3.10/site-packages/flwr/simulation/ray_transport/ray_actor.py", line 72, in run
    raise ClientException(str(message)) from ex
flwr.simulation.ray_transport.ray_actor.ClientException: 
>>>>>>>A ClientException occurred.('\n\tSomething went wrong when running your client workload.\n\tClient 17 crashed when the DefaultActor was running its workload.\n\tException triggered on the client side: Traceback (most recent call last):\n  File "/home/namvq/.cache/pypoetry/virtualenvs/niid-bench-orV17zke-py3.10/lib/python3.10/site-packages/flwr/simulation/ray_transport/ray_actor.py", line 60, in run\n    job_results = job_fn()\n  File "/home/namvq/.cache/pypoetry/virtualenvs/niid-bench-orV17zke-py3.10/lib/python3.10/site-packages/flwr/simulation/ray_transport/ray_client_proxy.py", line 196, in fit\n    return maybe_call_fit(\n  File "/home/namvq/.cache/pypoetry/virtualenvs/niid-bench-orV17zke-py3.10/lib/python3.10/site-packages/flwr/client/client.py", line 217, in maybe_call_fit\n    return client.fit(fit_ins)\n  File "/home/namvq/.cache/pypoetry/virtualenvs/niid-bench-orV17zke-py3.10/lib/python3.10/site-packages/flwr/client/app.py", line 333, in _fit\n    results = self.numpy_client.fit(parameters, ins.config)  # type: ignore\n  File "/media/namvq/Data/code_flwr/niid_bench/niid_bench/client_scaffold.py", line 78, in fit\n    train_scaffold(\n  File "/media/namvq/Data/code_flwr/niid_bench/niid_bench/models.py", line 205, in train_scaffold\n    net = _train_one_epoch_scaffold(\n  File "/media/namvq/Data/code_flwr/niid_bench/niid_bench/models.py", line 227, in _train_one_epoch_scaffold\n    optimizer.step_custom(server_cv, client_cv)\n  File "/media/namvq/Data/code_flwr/niid_bench/niid_bench/models.py", line 157, in step_custom\n    par.data.add_(s_cv - c_cv, alpha=-group["lr"])\nRuntimeError: Expected all tensors to be on the same device, but found at least two devices, cuda:0 and cpu!\n',)

[2024-11-25 22:22:41,200][flwr][ERROR] - [36mray::DefaultActor.run()[39m (pid=54501, ip=192.168.1.62, actor_id=92fad4022c9447ce5fa980af01000000, repr=<flwr.simulation.ray_transport.ray_actor.DefaultActor object at 0x7a82b8193100>)
  File "/home/namvq/.cache/pypoetry/virtualenvs/niid-bench-orV17zke-py3.10/lib/python3.10/site-packages/flwr/simulation/ray_transport/ray_client_proxy.py", line 196, in fit
    return maybe_call_fit(
  File "/home/namvq/.cache/pypoetry/virtualenvs/niid-bench-orV17zke-py3.10/lib/python3.10/site-packages/flwr/client/client.py", line 217, in maybe_call_fit
    return client.fit(fit_ins)
  File "/home/namvq/.cache/pypoetry/virtualenvs/niid-bench-orV17zke-py3.10/lib/python3.10/site-packages/flwr/client/app.py", line 333, in _fit
    results = self.numpy_client.fit(parameters, ins.config)  # type: ignore
  File "/media/namvq/Data/code_flwr/niid_bench/niid_bench/client_scaffold.py", line 78, in fit
    train_scaffold(
  File "/media/namvq/Data/code_flwr/niid_bench/niid_bench/models.py", line 205, in train_scaffold
    net = _train_one_epoch_scaffold(
  File "/media/namvq/Data/code_flwr/niid_bench/niid_bench/models.py", line 227, in _train_one_epoch_scaffold
    optimizer.step_custom(server_cv, client_cv)
  File "/media/namvq/Data/code_flwr/niid_bench/niid_bench/models.py", line 157, in step_custom
    par.data.add_(s_cv - c_cv, alpha=-group["lr"])
RuntimeError: Expected all tensors to be on the same device, but found at least two devices, cuda:0 and cpu!

The above exception was the direct cause of the following exception:

[36mray::DefaultActor.run()[39m (pid=54501, ip=192.168.1.62, actor_id=92fad4022c9447ce5fa980af01000000, repr=<flwr.simulation.ray_transport.ray_actor.DefaultActor object at 0x7a82b8193100>)
  File "/home/namvq/.cache/pypoetry/virtualenvs/niid-bench-orV17zke-py3.10/lib/python3.10/site-packages/flwr/simulation/ray_transport/ray_actor.py", line 72, in run
    raise ClientException(str(message)) from ex
flwr.simulation.ray_transport.ray_actor.ClientException: 
>>>>>>>A ClientException occurred.('\n\tSomething went wrong when running your client workload.\n\tClient 17 crashed when the DefaultActor was running its workload.\n\tException triggered on the client side: Traceback (most recent call last):\n  File "/home/namvq/.cache/pypoetry/virtualenvs/niid-bench-orV17zke-py3.10/lib/python3.10/site-packages/flwr/simulation/ray_transport/ray_actor.py", line 60, in run\n    job_results = job_fn()\n  File "/home/namvq/.cache/pypoetry/virtualenvs/niid-bench-orV17zke-py3.10/lib/python3.10/site-packages/flwr/simulation/ray_transport/ray_client_proxy.py", line 196, in fit\n    return maybe_call_fit(\n  File "/home/namvq/.cache/pypoetry/virtualenvs/niid-bench-orV17zke-py3.10/lib/python3.10/site-packages/flwr/client/client.py", line 217, in maybe_call_fit\n    return client.fit(fit_ins)\n  File "/home/namvq/.cache/pypoetry/virtualenvs/niid-bench-orV17zke-py3.10/lib/python3.10/site-packages/flwr/client/app.py", line 333, in _fit\n    results = self.numpy_client.fit(parameters, ins.config)  # type: ignore\n  File "/media/namvq/Data/code_flwr/niid_bench/niid_bench/client_scaffold.py", line 78, in fit\n    train_scaffold(\n  File "/media/namvq/Data/code_flwr/niid_bench/niid_bench/models.py", line 205, in train_scaffold\n    net = _train_one_epoch_scaffold(\n  File "/media/namvq/Data/code_flwr/niid_bench/niid_bench/models.py", line 227, in _train_one_epoch_scaffold\n    optimizer.step_custom(server_cv, client_cv)\n  File "/media/namvq/Data/code_flwr/niid_bench/niid_bench/models.py", line 157, in step_custom\n    par.data.add_(s_cv - c_cv, alpha=-group["lr"])\nRuntimeError: Expected all tensors to be on the same device, but found at least two devices, cuda:0 and cpu!\n',)
[2024-11-25 22:22:43,129][flwr][ERROR] - Traceback (most recent call last):
  File "/home/namvq/.cache/pypoetry/virtualenvs/niid-bench-orV17zke-py3.10/lib/python3.10/site-packages/flwr/simulation/ray_transport/ray_client_proxy.py", line 140, in _submit_job
    res = self.actor_pool.get_client_result(self.cid, timeout)
  File "/home/namvq/.cache/pypoetry/virtualenvs/niid-bench-orV17zke-py3.10/lib/python3.10/site-packages/flwr/simulation/ray_transport/ray_actor.py", line 402, in get_client_result
    return self._fetch_future_result(cid)
  File "/home/namvq/.cache/pypoetry/virtualenvs/niid-bench-orV17zke-py3.10/lib/python3.10/site-packages/flwr/simulation/ray_transport/ray_actor.py", line 288, in _fetch_future_result
    res_cid, res = ray.get(future)  # type: (str, ClientRes)
  File "/home/namvq/.cache/pypoetry/virtualenvs/niid-bench-orV17zke-py3.10/lib/python3.10/site-packages/ray/_private/auto_init_hook.py", line 24, in auto_init_wrapper
    return fn(*args, **kwargs)
  File "/home/namvq/.cache/pypoetry/virtualenvs/niid-bench-orV17zke-py3.10/lib/python3.10/site-packages/ray/_private/client_mode_hook.py", line 103, in wrapper
    return func(*args, **kwargs)
  File "/home/namvq/.cache/pypoetry/virtualenvs/niid-bench-orV17zke-py3.10/lib/python3.10/site-packages/ray/_private/worker.py", line 2524, in get
    raise value.as_instanceof_cause()
ray.exceptions.RayTaskError(ClientException): [36mray::DefaultActor.run()[39m (pid=54501, ip=192.168.1.62, actor_id=92fad4022c9447ce5fa980af01000000, repr=<flwr.simulation.ray_transport.ray_actor.DefaultActor object at 0x7a82b8193100>)
  File "/home/namvq/.cache/pypoetry/virtualenvs/niid-bench-orV17zke-py3.10/lib/python3.10/site-packages/flwr/simulation/ray_transport/ray_client_proxy.py", line 196, in fit
    return maybe_call_fit(
  File "/home/namvq/.cache/pypoetry/virtualenvs/niid-bench-orV17zke-py3.10/lib/python3.10/site-packages/flwr/client/client.py", line 217, in maybe_call_fit
    return client.fit(fit_ins)
  File "/home/namvq/.cache/pypoetry/virtualenvs/niid-bench-orV17zke-py3.10/lib/python3.10/site-packages/flwr/client/app.py", line 333, in _fit
    results = self.numpy_client.fit(parameters, ins.config)  # type: ignore
  File "/media/namvq/Data/code_flwr/niid_bench/niid_bench/client_scaffold.py", line 78, in fit
    train_scaffold(
  File "/media/namvq/Data/code_flwr/niid_bench/niid_bench/models.py", line 205, in train_scaffold
    net = _train_one_epoch_scaffold(
  File "/media/namvq/Data/code_flwr/niid_bench/niid_bench/models.py", line 227, in _train_one_epoch_scaffold
    optimizer.step_custom(server_cv, client_cv)
  File "/media/namvq/Data/code_flwr/niid_bench/niid_bench/models.py", line 157, in step_custom
    par.data.add_(s_cv - c_cv, alpha=-group["lr"])
RuntimeError: Expected all tensors to be on the same device, but found at least two devices, cuda:0 and cpu!

The above exception was the direct cause of the following exception:

[36mray::DefaultActor.run()[39m (pid=54501, ip=192.168.1.62, actor_id=92fad4022c9447ce5fa980af01000000, repr=<flwr.simulation.ray_transport.ray_actor.DefaultActor object at 0x7a82b8193100>)
  File "/home/namvq/.cache/pypoetry/virtualenvs/niid-bench-orV17zke-py3.10/lib/python3.10/site-packages/flwr/simulation/ray_transport/ray_actor.py", line 72, in run
    raise ClientException(str(message)) from ex
flwr.simulation.ray_transport.ray_actor.ClientException: 
>>>>>>>A ClientException occurred.('\n\tSomething went wrong when running your client workload.\n\tClient 2 crashed when the DefaultActor was running its workload.\n\tException triggered on the client side: Traceback (most recent call last):\n  File "/home/namvq/.cache/pypoetry/virtualenvs/niid-bench-orV17zke-py3.10/lib/python3.10/site-packages/flwr/simulation/ray_transport/ray_actor.py", line 60, in run\n    job_results = job_fn()\n  File "/home/namvq/.cache/pypoetry/virtualenvs/niid-bench-orV17zke-py3.10/lib/python3.10/site-packages/flwr/simulation/ray_transport/ray_client_proxy.py", line 196, in fit\n    return maybe_call_fit(\n  File "/home/namvq/.cache/pypoetry/virtualenvs/niid-bench-orV17zke-py3.10/lib/python3.10/site-packages/flwr/client/client.py", line 217, in maybe_call_fit\n    return client.fit(fit_ins)\n  File "/home/namvq/.cache/pypoetry/virtualenvs/niid-bench-orV17zke-py3.10/lib/python3.10/site-packages/flwr/client/app.py", line 333, in _fit\n    results = self.numpy_client.fit(parameters, ins.config)  # type: ignore\n  File "/media/namvq/Data/code_flwr/niid_bench/niid_bench/client_scaffold.py", line 78, in fit\n    train_scaffold(\n  File "/media/namvq/Data/code_flwr/niid_bench/niid_bench/models.py", line 205, in train_scaffold\n    net = _train_one_epoch_scaffold(\n  File "/media/namvq/Data/code_flwr/niid_bench/niid_bench/models.py", line 227, in _train_one_epoch_scaffold\n    optimizer.step_custom(server_cv, client_cv)\n  File "/media/namvq/Data/code_flwr/niid_bench/niid_bench/models.py", line 157, in step_custom\n    par.data.add_(s_cv - c_cv, alpha=-group["lr"])\nRuntimeError: Expected all tensors to be on the same device, but found at least two devices, cuda:0 and cpu!\n',)

[2024-11-25 22:22:43,130][flwr][ERROR] - [36mray::DefaultActor.run()[39m (pid=54501, ip=192.168.1.62, actor_id=92fad4022c9447ce5fa980af01000000, repr=<flwr.simulation.ray_transport.ray_actor.DefaultActor object at 0x7a82b8193100>)
  File "/home/namvq/.cache/pypoetry/virtualenvs/niid-bench-orV17zke-py3.10/lib/python3.10/site-packages/flwr/simulation/ray_transport/ray_client_proxy.py", line 196, in fit
    return maybe_call_fit(
  File "/home/namvq/.cache/pypoetry/virtualenvs/niid-bench-orV17zke-py3.10/lib/python3.10/site-packages/flwr/client/client.py", line 217, in maybe_call_fit
    return client.fit(fit_ins)
  File "/home/namvq/.cache/pypoetry/virtualenvs/niid-bench-orV17zke-py3.10/lib/python3.10/site-packages/flwr/client/app.py", line 333, in _fit
    results = self.numpy_client.fit(parameters, ins.config)  # type: ignore
  File "/media/namvq/Data/code_flwr/niid_bench/niid_bench/client_scaffold.py", line 78, in fit
    train_scaffold(
  File "/media/namvq/Data/code_flwr/niid_bench/niid_bench/models.py", line 205, in train_scaffold
    net = _train_one_epoch_scaffold(
  File "/media/namvq/Data/code_flwr/niid_bench/niid_bench/models.py", line 227, in _train_one_epoch_scaffold
    optimizer.step_custom(server_cv, client_cv)
  File "/media/namvq/Data/code_flwr/niid_bench/niid_bench/models.py", line 157, in step_custom
    par.data.add_(s_cv - c_cv, alpha=-group["lr"])
RuntimeError: Expected all tensors to be on the same device, but found at least two devices, cuda:0 and cpu!

The above exception was the direct cause of the following exception:

[36mray::DefaultActor.run()[39m (pid=54501, ip=192.168.1.62, actor_id=92fad4022c9447ce5fa980af01000000, repr=<flwr.simulation.ray_transport.ray_actor.DefaultActor object at 0x7a82b8193100>)
  File "/home/namvq/.cache/pypoetry/virtualenvs/niid-bench-orV17zke-py3.10/lib/python3.10/site-packages/flwr/simulation/ray_transport/ray_actor.py", line 72, in run
    raise ClientException(str(message)) from ex
flwr.simulation.ray_transport.ray_actor.ClientException: 
>>>>>>>A ClientException occurred.('\n\tSomething went wrong when running your client workload.\n\tClient 2 crashed when the DefaultActor was running its workload.\n\tException triggered on the client side: Traceback (most recent call last):\n  File "/home/namvq/.cache/pypoetry/virtualenvs/niid-bench-orV17zke-py3.10/lib/python3.10/site-packages/flwr/simulation/ray_transport/ray_actor.py", line 60, in run\n    job_results = job_fn()\n  File "/home/namvq/.cache/pypoetry/virtualenvs/niid-bench-orV17zke-py3.10/lib/python3.10/site-packages/flwr/simulation/ray_transport/ray_client_proxy.py", line 196, in fit\n    return maybe_call_fit(\n  File "/home/namvq/.cache/pypoetry/virtualenvs/niid-bench-orV17zke-py3.10/lib/python3.10/site-packages/flwr/client/client.py", line 217, in maybe_call_fit\n    return client.fit(fit_ins)\n  File "/home/namvq/.cache/pypoetry/virtualenvs/niid-bench-orV17zke-py3.10/lib/python3.10/site-packages/flwr/client/app.py", line 333, in _fit\n    results = self.numpy_client.fit(parameters, ins.config)  # type: ignore\n  File "/media/namvq/Data/code_flwr/niid_bench/niid_bench/client_scaffold.py", line 78, in fit\n    train_scaffold(\n  File "/media/namvq/Data/code_flwr/niid_bench/niid_bench/models.py", line 205, in train_scaffold\n    net = _train_one_epoch_scaffold(\n  File "/media/namvq/Data/code_flwr/niid_bench/niid_bench/models.py", line 227, in _train_one_epoch_scaffold\n    optimizer.step_custom(server_cv, client_cv)\n  File "/media/namvq/Data/code_flwr/niid_bench/niid_bench/models.py", line 157, in step_custom\n    par.data.add_(s_cv - c_cv, alpha=-group["lr"])\nRuntimeError: Expected all tensors to be on the same device, but found at least two devices, cuda:0 and cpu!\n',)
[2024-11-25 22:22:45,157][flwr][ERROR] - Traceback (most recent call last):
  File "/home/namvq/.cache/pypoetry/virtualenvs/niid-bench-orV17zke-py3.10/lib/python3.10/site-packages/flwr/simulation/ray_transport/ray_client_proxy.py", line 140, in _submit_job
    res = self.actor_pool.get_client_result(self.cid, timeout)
  File "/home/namvq/.cache/pypoetry/virtualenvs/niid-bench-orV17zke-py3.10/lib/python3.10/site-packages/flwr/simulation/ray_transport/ray_actor.py", line 402, in get_client_result
    return self._fetch_future_result(cid)
  File "/home/namvq/.cache/pypoetry/virtualenvs/niid-bench-orV17zke-py3.10/lib/python3.10/site-packages/flwr/simulation/ray_transport/ray_actor.py", line 288, in _fetch_future_result
    res_cid, res = ray.get(future)  # type: (str, ClientRes)
  File "/home/namvq/.cache/pypoetry/virtualenvs/niid-bench-orV17zke-py3.10/lib/python3.10/site-packages/ray/_private/auto_init_hook.py", line 24, in auto_init_wrapper
    return fn(*args, **kwargs)
  File "/home/namvq/.cache/pypoetry/virtualenvs/niid-bench-orV17zke-py3.10/lib/python3.10/site-packages/ray/_private/client_mode_hook.py", line 103, in wrapper
    return func(*args, **kwargs)
  File "/home/namvq/.cache/pypoetry/virtualenvs/niid-bench-orV17zke-py3.10/lib/python3.10/site-packages/ray/_private/worker.py", line 2524, in get
    raise value.as_instanceof_cause()
ray.exceptions.RayTaskError(ClientException): [36mray::DefaultActor.run()[39m (pid=54501, ip=192.168.1.62, actor_id=92fad4022c9447ce5fa980af01000000, repr=<flwr.simulation.ray_transport.ray_actor.DefaultActor object at 0x7a82b8193100>)
  File "/home/namvq/.cache/pypoetry/virtualenvs/niid-bench-orV17zke-py3.10/lib/python3.10/site-packages/flwr/simulation/ray_transport/ray_client_proxy.py", line 196, in fit
    return maybe_call_fit(
  File "/home/namvq/.cache/pypoetry/virtualenvs/niid-bench-orV17zke-py3.10/lib/python3.10/site-packages/flwr/client/client.py", line 217, in maybe_call_fit
    return client.fit(fit_ins)
  File "/home/namvq/.cache/pypoetry/virtualenvs/niid-bench-orV17zke-py3.10/lib/python3.10/site-packages/flwr/client/app.py", line 333, in _fit
    results = self.numpy_client.fit(parameters, ins.config)  # type: ignore
  File "/media/namvq/Data/code_flwr/niid_bench/niid_bench/client_scaffold.py", line 78, in fit
    train_scaffold(
  File "/media/namvq/Data/code_flwr/niid_bench/niid_bench/models.py", line 205, in train_scaffold
    net = _train_one_epoch_scaffold(
  File "/media/namvq/Data/code_flwr/niid_bench/niid_bench/models.py", line 227, in _train_one_epoch_scaffold
    optimizer.step_custom(server_cv, client_cv)
  File "/media/namvq/Data/code_flwr/niid_bench/niid_bench/models.py", line 157, in step_custom
    par.data.add_(s_cv - c_cv, alpha=-group["lr"])
RuntimeError: Expected all tensors to be on the same device, but found at least two devices, cuda:0 and cpu!

The above exception was the direct cause of the following exception:

[36mray::DefaultActor.run()[39m (pid=54501, ip=192.168.1.62, actor_id=92fad4022c9447ce5fa980af01000000, repr=<flwr.simulation.ray_transport.ray_actor.DefaultActor object at 0x7a82b8193100>)
  File "/home/namvq/.cache/pypoetry/virtualenvs/niid-bench-orV17zke-py3.10/lib/python3.10/site-packages/flwr/simulation/ray_transport/ray_actor.py", line 72, in run
    raise ClientException(str(message)) from ex
flwr.simulation.ray_transport.ray_actor.ClientException: 
>>>>>>>A ClientException occurred.('\n\tSomething went wrong when running your client workload.\n\tClient 16 crashed when the DefaultActor was running its workload.\n\tException triggered on the client side: Traceback (most recent call last):\n  File "/home/namvq/.cache/pypoetry/virtualenvs/niid-bench-orV17zke-py3.10/lib/python3.10/site-packages/flwr/simulation/ray_transport/ray_actor.py", line 60, in run\n    job_results = job_fn()\n  File "/home/namvq/.cache/pypoetry/virtualenvs/niid-bench-orV17zke-py3.10/lib/python3.10/site-packages/flwr/simulation/ray_transport/ray_client_proxy.py", line 196, in fit\n    return maybe_call_fit(\n  File "/home/namvq/.cache/pypoetry/virtualenvs/niid-bench-orV17zke-py3.10/lib/python3.10/site-packages/flwr/client/client.py", line 217, in maybe_call_fit\n    return client.fit(fit_ins)\n  File "/home/namvq/.cache/pypoetry/virtualenvs/niid-bench-orV17zke-py3.10/lib/python3.10/site-packages/flwr/client/app.py", line 333, in _fit\n    results = self.numpy_client.fit(parameters, ins.config)  # type: ignore\n  File "/media/namvq/Data/code_flwr/niid_bench/niid_bench/client_scaffold.py", line 78, in fit\n    train_scaffold(\n  File "/media/namvq/Data/code_flwr/niid_bench/niid_bench/models.py", line 205, in train_scaffold\n    net = _train_one_epoch_scaffold(\n  File "/media/namvq/Data/code_flwr/niid_bench/niid_bench/models.py", line 227, in _train_one_epoch_scaffold\n    optimizer.step_custom(server_cv, client_cv)\n  File "/media/namvq/Data/code_flwr/niid_bench/niid_bench/models.py", line 157, in step_custom\n    par.data.add_(s_cv - c_cv, alpha=-group["lr"])\nRuntimeError: Expected all tensors to be on the same device, but found at least two devices, cuda:0 and cpu!\n',)

[2024-11-25 22:22:45,157][flwr][ERROR] - [36mray::DefaultActor.run()[39m (pid=54501, ip=192.168.1.62, actor_id=92fad4022c9447ce5fa980af01000000, repr=<flwr.simulation.ray_transport.ray_actor.DefaultActor object at 0x7a82b8193100>)
  File "/home/namvq/.cache/pypoetry/virtualenvs/niid-bench-orV17zke-py3.10/lib/python3.10/site-packages/flwr/simulation/ray_transport/ray_client_proxy.py", line 196, in fit
    return maybe_call_fit(
  File "/home/namvq/.cache/pypoetry/virtualenvs/niid-bench-orV17zke-py3.10/lib/python3.10/site-packages/flwr/client/client.py", line 217, in maybe_call_fit
    return client.fit(fit_ins)
  File "/home/namvq/.cache/pypoetry/virtualenvs/niid-bench-orV17zke-py3.10/lib/python3.10/site-packages/flwr/client/app.py", line 333, in _fit
    results = self.numpy_client.fit(parameters, ins.config)  # type: ignore
  File "/media/namvq/Data/code_flwr/niid_bench/niid_bench/client_scaffold.py", line 78, in fit
    train_scaffold(
  File "/media/namvq/Data/code_flwr/niid_bench/niid_bench/models.py", line 205, in train_scaffold
    net = _train_one_epoch_scaffold(
  File "/media/namvq/Data/code_flwr/niid_bench/niid_bench/models.py", line 227, in _train_one_epoch_scaffold
    optimizer.step_custom(server_cv, client_cv)
  File "/media/namvq/Data/code_flwr/niid_bench/niid_bench/models.py", line 157, in step_custom
    par.data.add_(s_cv - c_cv, alpha=-group["lr"])
RuntimeError: Expected all tensors to be on the same device, but found at least two devices, cuda:0 and cpu!

The above exception was the direct cause of the following exception:

[36mray::DefaultActor.run()[39m (pid=54501, ip=192.168.1.62, actor_id=92fad4022c9447ce5fa980af01000000, repr=<flwr.simulation.ray_transport.ray_actor.DefaultActor object at 0x7a82b8193100>)
  File "/home/namvq/.cache/pypoetry/virtualenvs/niid-bench-orV17zke-py3.10/lib/python3.10/site-packages/flwr/simulation/ray_transport/ray_actor.py", line 72, in run
    raise ClientException(str(message)) from ex
flwr.simulation.ray_transport.ray_actor.ClientException: 
>>>>>>>A ClientException occurred.('\n\tSomething went wrong when running your client workload.\n\tClient 16 crashed when the DefaultActor was running its workload.\n\tException triggered on the client side: Traceback (most recent call last):\n  File "/home/namvq/.cache/pypoetry/virtualenvs/niid-bench-orV17zke-py3.10/lib/python3.10/site-packages/flwr/simulation/ray_transport/ray_actor.py", line 60, in run\n    job_results = job_fn()\n  File "/home/namvq/.cache/pypoetry/virtualenvs/niid-bench-orV17zke-py3.10/lib/python3.10/site-packages/flwr/simulation/ray_transport/ray_client_proxy.py", line 196, in fit\n    return maybe_call_fit(\n  File "/home/namvq/.cache/pypoetry/virtualenvs/niid-bench-orV17zke-py3.10/lib/python3.10/site-packages/flwr/client/client.py", line 217, in maybe_call_fit\n    return client.fit(fit_ins)\n  File "/home/namvq/.cache/pypoetry/virtualenvs/niid-bench-orV17zke-py3.10/lib/python3.10/site-packages/flwr/client/app.py", line 333, in _fit\n    results = self.numpy_client.fit(parameters, ins.config)  # type: ignore\n  File "/media/namvq/Data/code_flwr/niid_bench/niid_bench/client_scaffold.py", line 78, in fit\n    train_scaffold(\n  File "/media/namvq/Data/code_flwr/niid_bench/niid_bench/models.py", line 205, in train_scaffold\n    net = _train_one_epoch_scaffold(\n  File "/media/namvq/Data/code_flwr/niid_bench/niid_bench/models.py", line 227, in _train_one_epoch_scaffold\n    optimizer.step_custom(server_cv, client_cv)\n  File "/media/namvq/Data/code_flwr/niid_bench/niid_bench/models.py", line 157, in step_custom\n    par.data.add_(s_cv - c_cv, alpha=-group["lr"])\nRuntimeError: Expected all tensors to be on the same device, but found at least two devices, cuda:0 and cpu!\n',)
[2024-11-25 22:22:47,176][flwr][ERROR] - Traceback (most recent call last):
  File "/home/namvq/.cache/pypoetry/virtualenvs/niid-bench-orV17zke-py3.10/lib/python3.10/site-packages/flwr/simulation/ray_transport/ray_client_proxy.py", line 140, in _submit_job
    res = self.actor_pool.get_client_result(self.cid, timeout)
  File "/home/namvq/.cache/pypoetry/virtualenvs/niid-bench-orV17zke-py3.10/lib/python3.10/site-packages/flwr/simulation/ray_transport/ray_actor.py", line 402, in get_client_result
    return self._fetch_future_result(cid)
  File "/home/namvq/.cache/pypoetry/virtualenvs/niid-bench-orV17zke-py3.10/lib/python3.10/site-packages/flwr/simulation/ray_transport/ray_actor.py", line 288, in _fetch_future_result
    res_cid, res = ray.get(future)  # type: (str, ClientRes)
  File "/home/namvq/.cache/pypoetry/virtualenvs/niid-bench-orV17zke-py3.10/lib/python3.10/site-packages/ray/_private/auto_init_hook.py", line 24, in auto_init_wrapper
    return fn(*args, **kwargs)
  File "/home/namvq/.cache/pypoetry/virtualenvs/niid-bench-orV17zke-py3.10/lib/python3.10/site-packages/ray/_private/client_mode_hook.py", line 103, in wrapper
    return func(*args, **kwargs)
  File "/home/namvq/.cache/pypoetry/virtualenvs/niid-bench-orV17zke-py3.10/lib/python3.10/site-packages/ray/_private/worker.py", line 2524, in get
    raise value.as_instanceof_cause()
ray.exceptions.RayTaskError(ClientException): [36mray::DefaultActor.run()[39m (pid=54501, ip=192.168.1.62, actor_id=92fad4022c9447ce5fa980af01000000, repr=<flwr.simulation.ray_transport.ray_actor.DefaultActor object at 0x7a82b8193100>)
  File "/home/namvq/.cache/pypoetry/virtualenvs/niid-bench-orV17zke-py3.10/lib/python3.10/site-packages/flwr/simulation/ray_transport/ray_client_proxy.py", line 196, in fit
    return maybe_call_fit(
  File "/home/namvq/.cache/pypoetry/virtualenvs/niid-bench-orV17zke-py3.10/lib/python3.10/site-packages/flwr/client/client.py", line 217, in maybe_call_fit
    return client.fit(fit_ins)
  File "/home/namvq/.cache/pypoetry/virtualenvs/niid-bench-orV17zke-py3.10/lib/python3.10/site-packages/flwr/client/app.py", line 333, in _fit
    results = self.numpy_client.fit(parameters, ins.config)  # type: ignore
  File "/media/namvq/Data/code_flwr/niid_bench/niid_bench/client_scaffold.py", line 78, in fit
    train_scaffold(
  File "/media/namvq/Data/code_flwr/niid_bench/niid_bench/models.py", line 205, in train_scaffold
    net = _train_one_epoch_scaffold(
  File "/media/namvq/Data/code_flwr/niid_bench/niid_bench/models.py", line 227, in _train_one_epoch_scaffold
    optimizer.step_custom(server_cv, client_cv)
  File "/media/namvq/Data/code_flwr/niid_bench/niid_bench/models.py", line 157, in step_custom
    par.data.add_(s_cv - c_cv, alpha=-group["lr"])
RuntimeError: Expected all tensors to be on the same device, but found at least two devices, cuda:0 and cpu!

The above exception was the direct cause of the following exception:

[36mray::DefaultActor.run()[39m (pid=54501, ip=192.168.1.62, actor_id=92fad4022c9447ce5fa980af01000000, repr=<flwr.simulation.ray_transport.ray_actor.DefaultActor object at 0x7a82b8193100>)
  File "/home/namvq/.cache/pypoetry/virtualenvs/niid-bench-orV17zke-py3.10/lib/python3.10/site-packages/flwr/simulation/ray_transport/ray_actor.py", line 72, in run
    raise ClientException(str(message)) from ex
flwr.simulation.ray_transport.ray_actor.ClientException: 
>>>>>>>A ClientException occurred.('\n\tSomething went wrong when running your client workload.\n\tClient 7 crashed when the DefaultActor was running its workload.\n\tException triggered on the client side: Traceback (most recent call last):\n  File "/home/namvq/.cache/pypoetry/virtualenvs/niid-bench-orV17zke-py3.10/lib/python3.10/site-packages/flwr/simulation/ray_transport/ray_actor.py", line 60, in run\n    job_results = job_fn()\n  File "/home/namvq/.cache/pypoetry/virtualenvs/niid-bench-orV17zke-py3.10/lib/python3.10/site-packages/flwr/simulation/ray_transport/ray_client_proxy.py", line 196, in fit\n    return maybe_call_fit(\n  File "/home/namvq/.cache/pypoetry/virtualenvs/niid-bench-orV17zke-py3.10/lib/python3.10/site-packages/flwr/client/client.py", line 217, in maybe_call_fit\n    return client.fit(fit_ins)\n  File "/home/namvq/.cache/pypoetry/virtualenvs/niid-bench-orV17zke-py3.10/lib/python3.10/site-packages/flwr/client/app.py", line 333, in _fit\n    results = self.numpy_client.fit(parameters, ins.config)  # type: ignore\n  File "/media/namvq/Data/code_flwr/niid_bench/niid_bench/client_scaffold.py", line 78, in fit\n    train_scaffold(\n  File "/media/namvq/Data/code_flwr/niid_bench/niid_bench/models.py", line 205, in train_scaffold\n    net = _train_one_epoch_scaffold(\n  File "/media/namvq/Data/code_flwr/niid_bench/niid_bench/models.py", line 227, in _train_one_epoch_scaffold\n    optimizer.step_custom(server_cv, client_cv)\n  File "/media/namvq/Data/code_flwr/niid_bench/niid_bench/models.py", line 157, in step_custom\n    par.data.add_(s_cv - c_cv, alpha=-group["lr"])\nRuntimeError: Expected all tensors to be on the same device, but found at least two devices, cuda:0 and cpu!\n',)

[2024-11-25 22:22:47,176][flwr][ERROR] - [36mray::DefaultActor.run()[39m (pid=54501, ip=192.168.1.62, actor_id=92fad4022c9447ce5fa980af01000000, repr=<flwr.simulation.ray_transport.ray_actor.DefaultActor object at 0x7a82b8193100>)
  File "/home/namvq/.cache/pypoetry/virtualenvs/niid-bench-orV17zke-py3.10/lib/python3.10/site-packages/flwr/simulation/ray_transport/ray_client_proxy.py", line 196, in fit
    return maybe_call_fit(
  File "/home/namvq/.cache/pypoetry/virtualenvs/niid-bench-orV17zke-py3.10/lib/python3.10/site-packages/flwr/client/client.py", line 217, in maybe_call_fit
    return client.fit(fit_ins)
  File "/home/namvq/.cache/pypoetry/virtualenvs/niid-bench-orV17zke-py3.10/lib/python3.10/site-packages/flwr/client/app.py", line 333, in _fit
    results = self.numpy_client.fit(parameters, ins.config)  # type: ignore
  File "/media/namvq/Data/code_flwr/niid_bench/niid_bench/client_scaffold.py", line 78, in fit
    train_scaffold(
  File "/media/namvq/Data/code_flwr/niid_bench/niid_bench/models.py", line 205, in train_scaffold
    net = _train_one_epoch_scaffold(
  File "/media/namvq/Data/code_flwr/niid_bench/niid_bench/models.py", line 227, in _train_one_epoch_scaffold
    optimizer.step_custom(server_cv, client_cv)
  File "/media/namvq/Data/code_flwr/niid_bench/niid_bench/models.py", line 157, in step_custom
    par.data.add_(s_cv - c_cv, alpha=-group["lr"])
RuntimeError: Expected all tensors to be on the same device, but found at least two devices, cuda:0 and cpu!

The above exception was the direct cause of the following exception:

[36mray::DefaultActor.run()[39m (pid=54501, ip=192.168.1.62, actor_id=92fad4022c9447ce5fa980af01000000, repr=<flwr.simulation.ray_transport.ray_actor.DefaultActor object at 0x7a82b8193100>)
  File "/home/namvq/.cache/pypoetry/virtualenvs/niid-bench-orV17zke-py3.10/lib/python3.10/site-packages/flwr/simulation/ray_transport/ray_actor.py", line 72, in run
    raise ClientException(str(message)) from ex
flwr.simulation.ray_transport.ray_actor.ClientException: 
>>>>>>>A ClientException occurred.('\n\tSomething went wrong when running your client workload.\n\tClient 7 crashed when the DefaultActor was running its workload.\n\tException triggered on the client side: Traceback (most recent call last):\n  File "/home/namvq/.cache/pypoetry/virtualenvs/niid-bench-orV17zke-py3.10/lib/python3.10/site-packages/flwr/simulation/ray_transport/ray_actor.py", line 60, in run\n    job_results = job_fn()\n  File "/home/namvq/.cache/pypoetry/virtualenvs/niid-bench-orV17zke-py3.10/lib/python3.10/site-packages/flwr/simulation/ray_transport/ray_client_proxy.py", line 196, in fit\n    return maybe_call_fit(\n  File "/home/namvq/.cache/pypoetry/virtualenvs/niid-bench-orV17zke-py3.10/lib/python3.10/site-packages/flwr/client/client.py", line 217, in maybe_call_fit\n    return client.fit(fit_ins)\n  File "/home/namvq/.cache/pypoetry/virtualenvs/niid-bench-orV17zke-py3.10/lib/python3.10/site-packages/flwr/client/app.py", line 333, in _fit\n    results = self.numpy_client.fit(parameters, ins.config)  # type: ignore\n  File "/media/namvq/Data/code_flwr/niid_bench/niid_bench/client_scaffold.py", line 78, in fit\n    train_scaffold(\n  File "/media/namvq/Data/code_flwr/niid_bench/niid_bench/models.py", line 205, in train_scaffold\n    net = _train_one_epoch_scaffold(\n  File "/media/namvq/Data/code_flwr/niid_bench/niid_bench/models.py", line 227, in _train_one_epoch_scaffold\n    optimizer.step_custom(server_cv, client_cv)\n  File "/media/namvq/Data/code_flwr/niid_bench/niid_bench/models.py", line 157, in step_custom\n    par.data.add_(s_cv - c_cv, alpha=-group["lr"])\nRuntimeError: Expected all tensors to be on the same device, but found at least two devices, cuda:0 and cpu!\n',)
[2024-11-25 22:22:49,248][flwr][ERROR] - Traceback (most recent call last):
  File "/home/namvq/.cache/pypoetry/virtualenvs/niid-bench-orV17zke-py3.10/lib/python3.10/site-packages/flwr/simulation/ray_transport/ray_client_proxy.py", line 140, in _submit_job
    res = self.actor_pool.get_client_result(self.cid, timeout)
  File "/home/namvq/.cache/pypoetry/virtualenvs/niid-bench-orV17zke-py3.10/lib/python3.10/site-packages/flwr/simulation/ray_transport/ray_actor.py", line 402, in get_client_result
    return self._fetch_future_result(cid)
  File "/home/namvq/.cache/pypoetry/virtualenvs/niid-bench-orV17zke-py3.10/lib/python3.10/site-packages/flwr/simulation/ray_transport/ray_actor.py", line 288, in _fetch_future_result
    res_cid, res = ray.get(future)  # type: (str, ClientRes)
  File "/home/namvq/.cache/pypoetry/virtualenvs/niid-bench-orV17zke-py3.10/lib/python3.10/site-packages/ray/_private/auto_init_hook.py", line 24, in auto_init_wrapper
    return fn(*args, **kwargs)
  File "/home/namvq/.cache/pypoetry/virtualenvs/niid-bench-orV17zke-py3.10/lib/python3.10/site-packages/ray/_private/client_mode_hook.py", line 103, in wrapper
    return func(*args, **kwargs)
  File "/home/namvq/.cache/pypoetry/virtualenvs/niid-bench-orV17zke-py3.10/lib/python3.10/site-packages/ray/_private/worker.py", line 2524, in get
    raise value.as_instanceof_cause()
ray.exceptions.RayTaskError(ClientException): [36mray::DefaultActor.run()[39m (pid=54501, ip=192.168.1.62, actor_id=92fad4022c9447ce5fa980af01000000, repr=<flwr.simulation.ray_transport.ray_actor.DefaultActor object at 0x7a82b8193100>)
  File "/home/namvq/.cache/pypoetry/virtualenvs/niid-bench-orV17zke-py3.10/lib/python3.10/site-packages/flwr/simulation/ray_transport/ray_client_proxy.py", line 196, in fit
    return maybe_call_fit(
  File "/home/namvq/.cache/pypoetry/virtualenvs/niid-bench-orV17zke-py3.10/lib/python3.10/site-packages/flwr/client/client.py", line 217, in maybe_call_fit
    return client.fit(fit_ins)
  File "/home/namvq/.cache/pypoetry/virtualenvs/niid-bench-orV17zke-py3.10/lib/python3.10/site-packages/flwr/client/app.py", line 333, in _fit
    results = self.numpy_client.fit(parameters, ins.config)  # type: ignore
  File "/media/namvq/Data/code_flwr/niid_bench/niid_bench/client_scaffold.py", line 78, in fit
    train_scaffold(
  File "/media/namvq/Data/code_flwr/niid_bench/niid_bench/models.py", line 205, in train_scaffold
    net = _train_one_epoch_scaffold(
  File "/media/namvq/Data/code_flwr/niid_bench/niid_bench/models.py", line 227, in _train_one_epoch_scaffold
    optimizer.step_custom(server_cv, client_cv)
  File "/media/namvq/Data/code_flwr/niid_bench/niid_bench/models.py", line 157, in step_custom
    par.data.add_(s_cv - c_cv, alpha=-group["lr"])
RuntimeError: Expected all tensors to be on the same device, but found at least two devices, cuda:0 and cpu!

The above exception was the direct cause of the following exception:

[36mray::DefaultActor.run()[39m (pid=54501, ip=192.168.1.62, actor_id=92fad4022c9447ce5fa980af01000000, repr=<flwr.simulation.ray_transport.ray_actor.DefaultActor object at 0x7a82b8193100>)
  File "/home/namvq/.cache/pypoetry/virtualenvs/niid-bench-orV17zke-py3.10/lib/python3.10/site-packages/flwr/simulation/ray_transport/ray_actor.py", line 72, in run
    raise ClientException(str(message)) from ex
flwr.simulation.ray_transport.ray_actor.ClientException: 
>>>>>>>A ClientException occurred.('\n\tSomething went wrong when running your client workload.\n\tClient 11 crashed when the DefaultActor was running its workload.\n\tException triggered on the client side: Traceback (most recent call last):\n  File "/home/namvq/.cache/pypoetry/virtualenvs/niid-bench-orV17zke-py3.10/lib/python3.10/site-packages/flwr/simulation/ray_transport/ray_actor.py", line 60, in run\n    job_results = job_fn()\n  File "/home/namvq/.cache/pypoetry/virtualenvs/niid-bench-orV17zke-py3.10/lib/python3.10/site-packages/flwr/simulation/ray_transport/ray_client_proxy.py", line 196, in fit\n    return maybe_call_fit(\n  File "/home/namvq/.cache/pypoetry/virtualenvs/niid-bench-orV17zke-py3.10/lib/python3.10/site-packages/flwr/client/client.py", line 217, in maybe_call_fit\n    return client.fit(fit_ins)\n  File "/home/namvq/.cache/pypoetry/virtualenvs/niid-bench-orV17zke-py3.10/lib/python3.10/site-packages/flwr/client/app.py", line 333, in _fit\n    results = self.numpy_client.fit(parameters, ins.config)  # type: ignore\n  File "/media/namvq/Data/code_flwr/niid_bench/niid_bench/client_scaffold.py", line 78, in fit\n    train_scaffold(\n  File "/media/namvq/Data/code_flwr/niid_bench/niid_bench/models.py", line 205, in train_scaffold\n    net = _train_one_epoch_scaffold(\n  File "/media/namvq/Data/code_flwr/niid_bench/niid_bench/models.py", line 227, in _train_one_epoch_scaffold\n    optimizer.step_custom(server_cv, client_cv)\n  File "/media/namvq/Data/code_flwr/niid_bench/niid_bench/models.py", line 157, in step_custom\n    par.data.add_(s_cv - c_cv, alpha=-group["lr"])\nRuntimeError: Expected all tensors to be on the same device, but found at least two devices, cuda:0 and cpu!\n',)

[2024-11-25 22:22:49,248][flwr][ERROR] - [36mray::DefaultActor.run()[39m (pid=54501, ip=192.168.1.62, actor_id=92fad4022c9447ce5fa980af01000000, repr=<flwr.simulation.ray_transport.ray_actor.DefaultActor object at 0x7a82b8193100>)
  File "/home/namvq/.cache/pypoetry/virtualenvs/niid-bench-orV17zke-py3.10/lib/python3.10/site-packages/flwr/simulation/ray_transport/ray_client_proxy.py", line 196, in fit
    return maybe_call_fit(
  File "/home/namvq/.cache/pypoetry/virtualenvs/niid-bench-orV17zke-py3.10/lib/python3.10/site-packages/flwr/client/client.py", line 217, in maybe_call_fit
    return client.fit(fit_ins)
  File "/home/namvq/.cache/pypoetry/virtualenvs/niid-bench-orV17zke-py3.10/lib/python3.10/site-packages/flwr/client/app.py", line 333, in _fit
    results = self.numpy_client.fit(parameters, ins.config)  # type: ignore
  File "/media/namvq/Data/code_flwr/niid_bench/niid_bench/client_scaffold.py", line 78, in fit
    train_scaffold(
  File "/media/namvq/Data/code_flwr/niid_bench/niid_bench/models.py", line 205, in train_scaffold
    net = _train_one_epoch_scaffold(
  File "/media/namvq/Data/code_flwr/niid_bench/niid_bench/models.py", line 227, in _train_one_epoch_scaffold
    optimizer.step_custom(server_cv, client_cv)
  File "/media/namvq/Data/code_flwr/niid_bench/niid_bench/models.py", line 157, in step_custom
    par.data.add_(s_cv - c_cv, alpha=-group["lr"])
RuntimeError: Expected all tensors to be on the same device, but found at least two devices, cuda:0 and cpu!

The above exception was the direct cause of the following exception:

[36mray::DefaultActor.run()[39m (pid=54501, ip=192.168.1.62, actor_id=92fad4022c9447ce5fa980af01000000, repr=<flwr.simulation.ray_transport.ray_actor.DefaultActor object at 0x7a82b8193100>)
  File "/home/namvq/.cache/pypoetry/virtualenvs/niid-bench-orV17zke-py3.10/lib/python3.10/site-packages/flwr/simulation/ray_transport/ray_actor.py", line 72, in run
    raise ClientException(str(message)) from ex
flwr.simulation.ray_transport.ray_actor.ClientException: 
>>>>>>>A ClientException occurred.('\n\tSomething went wrong when running your client workload.\n\tClient 11 crashed when the DefaultActor was running its workload.\n\tException triggered on the client side: Traceback (most recent call last):\n  File "/home/namvq/.cache/pypoetry/virtualenvs/niid-bench-orV17zke-py3.10/lib/python3.10/site-packages/flwr/simulation/ray_transport/ray_actor.py", line 60, in run\n    job_results = job_fn()\n  File "/home/namvq/.cache/pypoetry/virtualenvs/niid-bench-orV17zke-py3.10/lib/python3.10/site-packages/flwr/simulation/ray_transport/ray_client_proxy.py", line 196, in fit\n    return maybe_call_fit(\n  File "/home/namvq/.cache/pypoetry/virtualenvs/niid-bench-orV17zke-py3.10/lib/python3.10/site-packages/flwr/client/client.py", line 217, in maybe_call_fit\n    return client.fit(fit_ins)\n  File "/home/namvq/.cache/pypoetry/virtualenvs/niid-bench-orV17zke-py3.10/lib/python3.10/site-packages/flwr/client/app.py", line 333, in _fit\n    results = self.numpy_client.fit(parameters, ins.config)  # type: ignore\n  File "/media/namvq/Data/code_flwr/niid_bench/niid_bench/client_scaffold.py", line 78, in fit\n    train_scaffold(\n  File "/media/namvq/Data/code_flwr/niid_bench/niid_bench/models.py", line 205, in train_scaffold\n    net = _train_one_epoch_scaffold(\n  File "/media/namvq/Data/code_flwr/niid_bench/niid_bench/models.py", line 227, in _train_one_epoch_scaffold\n    optimizer.step_custom(server_cv, client_cv)\n  File "/media/namvq/Data/code_flwr/niid_bench/niid_bench/models.py", line 157, in step_custom\n    par.data.add_(s_cv - c_cv, alpha=-group["lr"])\nRuntimeError: Expected all tensors to be on the same device, but found at least two devices, cuda:0 and cpu!\n',)
[2024-11-25 22:22:51,234][flwr][ERROR] - Traceback (most recent call last):
  File "/home/namvq/.cache/pypoetry/virtualenvs/niid-bench-orV17zke-py3.10/lib/python3.10/site-packages/flwr/simulation/ray_transport/ray_client_proxy.py", line 140, in _submit_job
    res = self.actor_pool.get_client_result(self.cid, timeout)
  File "/home/namvq/.cache/pypoetry/virtualenvs/niid-bench-orV17zke-py3.10/lib/python3.10/site-packages/flwr/simulation/ray_transport/ray_actor.py", line 402, in get_client_result
    return self._fetch_future_result(cid)
  File "/home/namvq/.cache/pypoetry/virtualenvs/niid-bench-orV17zke-py3.10/lib/python3.10/site-packages/flwr/simulation/ray_transport/ray_actor.py", line 288, in _fetch_future_result
    res_cid, res = ray.get(future)  # type: (str, ClientRes)
  File "/home/namvq/.cache/pypoetry/virtualenvs/niid-bench-orV17zke-py3.10/lib/python3.10/site-packages/ray/_private/auto_init_hook.py", line 24, in auto_init_wrapper
    return fn(*args, **kwargs)
  File "/home/namvq/.cache/pypoetry/virtualenvs/niid-bench-orV17zke-py3.10/lib/python3.10/site-packages/ray/_private/client_mode_hook.py", line 103, in wrapper
    return func(*args, **kwargs)
  File "/home/namvq/.cache/pypoetry/virtualenvs/niid-bench-orV17zke-py3.10/lib/python3.10/site-packages/ray/_private/worker.py", line 2524, in get
    raise value.as_instanceof_cause()
ray.exceptions.RayTaskError(ClientException): [36mray::DefaultActor.run()[39m (pid=54501, ip=192.168.1.62, actor_id=92fad4022c9447ce5fa980af01000000, repr=<flwr.simulation.ray_transport.ray_actor.DefaultActor object at 0x7a82b8193100>)
  File "/home/namvq/.cache/pypoetry/virtualenvs/niid-bench-orV17zke-py3.10/lib/python3.10/site-packages/flwr/simulation/ray_transport/ray_client_proxy.py", line 196, in fit
    return maybe_call_fit(
  File "/home/namvq/.cache/pypoetry/virtualenvs/niid-bench-orV17zke-py3.10/lib/python3.10/site-packages/flwr/client/client.py", line 217, in maybe_call_fit
    return client.fit(fit_ins)
  File "/home/namvq/.cache/pypoetry/virtualenvs/niid-bench-orV17zke-py3.10/lib/python3.10/site-packages/flwr/client/app.py", line 333, in _fit
    results = self.numpy_client.fit(parameters, ins.config)  # type: ignore
  File "/media/namvq/Data/code_flwr/niid_bench/niid_bench/client_scaffold.py", line 78, in fit
    train_scaffold(
  File "/media/namvq/Data/code_flwr/niid_bench/niid_bench/models.py", line 205, in train_scaffold
    net = _train_one_epoch_scaffold(
  File "/media/namvq/Data/code_flwr/niid_bench/niid_bench/models.py", line 227, in _train_one_epoch_scaffold
    optimizer.step_custom(server_cv, client_cv)
  File "/media/namvq/Data/code_flwr/niid_bench/niid_bench/models.py", line 157, in step_custom
    par.data.add_(s_cv - c_cv, alpha=-group["lr"])
RuntimeError: Expected all tensors to be on the same device, but found at least two devices, cuda:0 and cpu!

The above exception was the direct cause of the following exception:

[36mray::DefaultActor.run()[39m (pid=54501, ip=192.168.1.62, actor_id=92fad4022c9447ce5fa980af01000000, repr=<flwr.simulation.ray_transport.ray_actor.DefaultActor object at 0x7a82b8193100>)
  File "/home/namvq/.cache/pypoetry/virtualenvs/niid-bench-orV17zke-py3.10/lib/python3.10/site-packages/flwr/simulation/ray_transport/ray_actor.py", line 72, in run
    raise ClientException(str(message)) from ex
flwr.simulation.ray_transport.ray_actor.ClientException: 
>>>>>>>A ClientException occurred.('\n\tSomething went wrong when running your client workload.\n\tClient 0 crashed when the DefaultActor was running its workload.\n\tException triggered on the client side: Traceback (most recent call last):\n  File "/home/namvq/.cache/pypoetry/virtualenvs/niid-bench-orV17zke-py3.10/lib/python3.10/site-packages/flwr/simulation/ray_transport/ray_actor.py", line 60, in run\n    job_results = job_fn()\n  File "/home/namvq/.cache/pypoetry/virtualenvs/niid-bench-orV17zke-py3.10/lib/python3.10/site-packages/flwr/simulation/ray_transport/ray_client_proxy.py", line 196, in fit\n    return maybe_call_fit(\n  File "/home/namvq/.cache/pypoetry/virtualenvs/niid-bench-orV17zke-py3.10/lib/python3.10/site-packages/flwr/client/client.py", line 217, in maybe_call_fit\n    return client.fit(fit_ins)\n  File "/home/namvq/.cache/pypoetry/virtualenvs/niid-bench-orV17zke-py3.10/lib/python3.10/site-packages/flwr/client/app.py", line 333, in _fit\n    results = self.numpy_client.fit(parameters, ins.config)  # type: ignore\n  File "/media/namvq/Data/code_flwr/niid_bench/niid_bench/client_scaffold.py", line 78, in fit\n    train_scaffold(\n  File "/media/namvq/Data/code_flwr/niid_bench/niid_bench/models.py", line 205, in train_scaffold\n    net = _train_one_epoch_scaffold(\n  File "/media/namvq/Data/code_flwr/niid_bench/niid_bench/models.py", line 227, in _train_one_epoch_scaffold\n    optimizer.step_custom(server_cv, client_cv)\n  File "/media/namvq/Data/code_flwr/niid_bench/niid_bench/models.py", line 157, in step_custom\n    par.data.add_(s_cv - c_cv, alpha=-group["lr"])\nRuntimeError: Expected all tensors to be on the same device, but found at least two devices, cuda:0 and cpu!\n',)

[2024-11-25 22:22:51,234][flwr][ERROR] - [36mray::DefaultActor.run()[39m (pid=54501, ip=192.168.1.62, actor_id=92fad4022c9447ce5fa980af01000000, repr=<flwr.simulation.ray_transport.ray_actor.DefaultActor object at 0x7a82b8193100>)
  File "/home/namvq/.cache/pypoetry/virtualenvs/niid-bench-orV17zke-py3.10/lib/python3.10/site-packages/flwr/simulation/ray_transport/ray_client_proxy.py", line 196, in fit
    return maybe_call_fit(
  File "/home/namvq/.cache/pypoetry/virtualenvs/niid-bench-orV17zke-py3.10/lib/python3.10/site-packages/flwr/client/client.py", line 217, in maybe_call_fit
    return client.fit(fit_ins)
  File "/home/namvq/.cache/pypoetry/virtualenvs/niid-bench-orV17zke-py3.10/lib/python3.10/site-packages/flwr/client/app.py", line 333, in _fit
    results = self.numpy_client.fit(parameters, ins.config)  # type: ignore
  File "/media/namvq/Data/code_flwr/niid_bench/niid_bench/client_scaffold.py", line 78, in fit
    train_scaffold(
  File "/media/namvq/Data/code_flwr/niid_bench/niid_bench/models.py", line 205, in train_scaffold
    net = _train_one_epoch_scaffold(
  File "/media/namvq/Data/code_flwr/niid_bench/niid_bench/models.py", line 227, in _train_one_epoch_scaffold
    optimizer.step_custom(server_cv, client_cv)
  File "/media/namvq/Data/code_flwr/niid_bench/niid_bench/models.py", line 157, in step_custom
    par.data.add_(s_cv - c_cv, alpha=-group["lr"])
RuntimeError: Expected all tensors to be on the same device, but found at least two devices, cuda:0 and cpu!

The above exception was the direct cause of the following exception:

[36mray::DefaultActor.run()[39m (pid=54501, ip=192.168.1.62, actor_id=92fad4022c9447ce5fa980af01000000, repr=<flwr.simulation.ray_transport.ray_actor.DefaultActor object at 0x7a82b8193100>)
  File "/home/namvq/.cache/pypoetry/virtualenvs/niid-bench-orV17zke-py3.10/lib/python3.10/site-packages/flwr/simulation/ray_transport/ray_actor.py", line 72, in run
    raise ClientException(str(message)) from ex
flwr.simulation.ray_transport.ray_actor.ClientException: 
>>>>>>>A ClientException occurred.('\n\tSomething went wrong when running your client workload.\n\tClient 0 crashed when the DefaultActor was running its workload.\n\tException triggered on the client side: Traceback (most recent call last):\n  File "/home/namvq/.cache/pypoetry/virtualenvs/niid-bench-orV17zke-py3.10/lib/python3.10/site-packages/flwr/simulation/ray_transport/ray_actor.py", line 60, in run\n    job_results = job_fn()\n  File "/home/namvq/.cache/pypoetry/virtualenvs/niid-bench-orV17zke-py3.10/lib/python3.10/site-packages/flwr/simulation/ray_transport/ray_client_proxy.py", line 196, in fit\n    return maybe_call_fit(\n  File "/home/namvq/.cache/pypoetry/virtualenvs/niid-bench-orV17zke-py3.10/lib/python3.10/site-packages/flwr/client/client.py", line 217, in maybe_call_fit\n    return client.fit(fit_ins)\n  File "/home/namvq/.cache/pypoetry/virtualenvs/niid-bench-orV17zke-py3.10/lib/python3.10/site-packages/flwr/client/app.py", line 333, in _fit\n    results = self.numpy_client.fit(parameters, ins.config)  # type: ignore\n  File "/media/namvq/Data/code_flwr/niid_bench/niid_bench/client_scaffold.py", line 78, in fit\n    train_scaffold(\n  File "/media/namvq/Data/code_flwr/niid_bench/niid_bench/models.py", line 205, in train_scaffold\n    net = _train_one_epoch_scaffold(\n  File "/media/namvq/Data/code_flwr/niid_bench/niid_bench/models.py", line 227, in _train_one_epoch_scaffold\n    optimizer.step_custom(server_cv, client_cv)\n  File "/media/namvq/Data/code_flwr/niid_bench/niid_bench/models.py", line 157, in step_custom\n    par.data.add_(s_cv - c_cv, alpha=-group["lr"])\nRuntimeError: Expected all tensors to be on the same device, but found at least two devices, cuda:0 and cpu!\n',)
