[2024-11-17 01:53:14,672][flwr][WARNING] - Both server and strategy were provided, ignoring strategy
[2024-11-17 01:53:14,672][flwr][INFO] - Starting Flower simulation, config: ServerConfig(num_rounds=2, round_timeout=None)
[2024-11-17 01:53:20,501][flwr][INFO] - Flower VCE: Ray initialized with resources: {'GPU': 1.0, 'accelerator_type:G': 1.0, 'node:__internal_head__': 1.0, 'node:192.168.1.29': 1.0, 'memory': 6658063566.0, 'CPU': 12.0, 'object_store_memory': 3329031782.0}
[2024-11-17 01:53:20,501][flwr][INFO] - Flower VCE: Resources for each Virtual Client: {'num_cpus': 4, 'num_gpus': 0.0}
[2024-11-17 01:53:20,509][flwr][INFO] - Flower VCE: Creating VirtualClientEngineActorPool with 3 actors
[2024-11-17 01:53:20,510][flwr][INFO] - Initializing global parameters
[2024-11-17 01:53:20,510][flwr][INFO] - Requesting initial parameters from one random client
[2024-11-17 01:53:22,705][flwr][ERROR] - Traceback (most recent call last):
  File "/home/namvq/.cache/pypoetry/virtualenvs/niid-bench-orV17zke-py3.10/lib/python3.10/site-packages/flwr/simulation/ray_transport/ray_client_proxy.py", line 140, in _submit_job
    res = self.actor_pool.get_client_result(self.cid, timeout)
  File "/home/namvq/.cache/pypoetry/virtualenvs/niid-bench-orV17zke-py3.10/lib/python3.10/site-packages/flwr/simulation/ray_transport/ray_actor.py", line 402, in get_client_result
    return self._fetch_future_result(cid)
  File "/home/namvq/.cache/pypoetry/virtualenvs/niid-bench-orV17zke-py3.10/lib/python3.10/site-packages/flwr/simulation/ray_transport/ray_actor.py", line 288, in _fetch_future_result
    res_cid, res = ray.get(future)  # type: (str, ClientRes)
  File "/home/namvq/.cache/pypoetry/virtualenvs/niid-bench-orV17zke-py3.10/lib/python3.10/site-packages/ray/_private/auto_init_hook.py", line 24, in auto_init_wrapper
    return fn(*args, **kwargs)
  File "/home/namvq/.cache/pypoetry/virtualenvs/niid-bench-orV17zke-py3.10/lib/python3.10/site-packages/ray/_private/client_mode_hook.py", line 103, in wrapper
    return func(*args, **kwargs)
  File "/home/namvq/.cache/pypoetry/virtualenvs/niid-bench-orV17zke-py3.10/lib/python3.10/site-packages/ray/_private/worker.py", line 2524, in get
    raise value.as_instanceof_cause()
ray.exceptions.RayTaskError(ClientException): [36mray::DefaultActor.run()[39m (pid=139462, ip=192.168.1.29, actor_id=bfd5fa6f157822995390a57501000000, repr=<flwr.simulation.ray_transport.ray_actor.DefaultActor object at 0x7ecaa919eda0>)
  File "/home/namvq/.pyenv/versions/3.10.6/lib/python3.10/importlib/__init__.py", line 126, in import_module
    return _bootstrap._gcd_import(name[level:], package, level)
  File "<frozen importlib._bootstrap>", line 1050, in _gcd_import
  File "<frozen importlib._bootstrap>", line 1027, in _find_and_load
  File "<frozen importlib._bootstrap>", line 1001, in _find_and_load_unlocked
ModuleNotFoundError: No module named 'niid_bench.models.CNN'; 'niid_bench.models' is not a package

The above exception was the direct cause of the following exception:

[36mray::DefaultActor.run()[39m (pid=139462, ip=192.168.1.29, actor_id=bfd5fa6f157822995390a57501000000, repr=<flwr.simulation.ray_transport.ray_actor.DefaultActor object at 0x7ecaa919eda0>)
  File "/home/namvq/.cache/pypoetry/virtualenvs/niid-bench-orV17zke-py3.10/lib/python3.10/site-packages/hydra/_internal/instantiate/_instantiate2.py", line 134, in _resolve_target
    target = _locate(target)
  File "/home/namvq/.cache/pypoetry/virtualenvs/niid-bench-orV17zke-py3.10/lib/python3.10/site-packages/hydra/_internal/utils.py", line 653, in _locate
    raise ImportError(
ImportError: Error loading 'niid_bench.models.CNN':
ModuleNotFoundError("No module named 'niid_bench.models.CNN'; 'niid_bench.models' is not a package")
Are you sure that 'CNN' is importable from module 'niid_bench.models'?

The above exception was the direct cause of the following exception:

[36mray::DefaultActor.run()[39m (pid=139462, ip=192.168.1.29, actor_id=bfd5fa6f157822995390a57501000000, repr=<flwr.simulation.ray_transport.ray_actor.DefaultActor object at 0x7ecaa919eda0>)
  File "/home/namvq/.cache/pypoetry/virtualenvs/niid-bench-orV17zke-py3.10/lib/python3.10/site-packages/flwr/simulation/ray_transport/ray_actor.py", line 60, in run
    job_results = job_fn()
  File "/home/namvq/.cache/pypoetry/virtualenvs/niid-bench-orV17zke-py3.10/lib/python3.10/site-packages/flwr/simulation/ray_transport/ray_client_proxy.py", line 178, in get_parameters
    client: Client = _create_client(self.client_fn, self.cid)
  File "/home/namvq/.cache/pypoetry/virtualenvs/niid-bench-orV17zke-py3.10/lib/python3.10/site-packages/flwr/simulation/ray_transport/ray_client_proxy.py", line 284, in _create_client
    client_like: ClientLike = client_fn(cid)
  File "/media/namvq/Data/code_flwr/niid_bench/niid_bench/client_fednova.py", line 115, in client_fn
    net = instantiate(model).to(device)
  File "/home/namvq/.cache/pypoetry/virtualenvs/niid-bench-orV17zke-py3.10/lib/python3.10/site-packages/hydra/_internal/instantiate/_instantiate2.py", line 226, in instantiate
    return instantiate_node(
  File "/home/namvq/.cache/pypoetry/virtualenvs/niid-bench-orV17zke-py3.10/lib/python3.10/site-packages/hydra/_internal/instantiate/_instantiate2.py", line 333, in instantiate_node
    _target_ = _resolve_target(node.get(_Keys.TARGET), full_key)
  File "/home/namvq/.cache/pypoetry/virtualenvs/niid-bench-orV17zke-py3.10/lib/python3.10/site-packages/hydra/_internal/instantiate/_instantiate2.py", line 139, in _resolve_target
    raise InstantiationException(msg) from e
hydra.errors.InstantiationException: Error locating target 'niid_bench.models.CNN', set env var HYDRA_FULL_ERROR=1 to see chained exception.
full_key: model

The above exception was the direct cause of the following exception:

[36mray::DefaultActor.run()[39m (pid=139462, ip=192.168.1.29, actor_id=bfd5fa6f157822995390a57501000000, repr=<flwr.simulation.ray_transport.ray_actor.DefaultActor object at 0x7ecaa919eda0>)
  File "/home/namvq/.cache/pypoetry/virtualenvs/niid-bench-orV17zke-py3.10/lib/python3.10/site-packages/flwr/simulation/ray_transport/ray_actor.py", line 72, in run
    raise ClientException(str(message)) from ex
flwr.simulation.ray_transport.ray_actor.ClientException: 
>>>>>>>A ClientException occurred.('\n\tSomething went wrong when running your client workload.\n\tClient 9 crashed when the DefaultActor was running its workload.\n\tException triggered on the client side: Traceback (most recent call last):\n  File "/home/namvq/.cache/pypoetry/virtualenvs/niid-bench-orV17zke-py3.10/lib/python3.10/site-packages/hydra/_internal/utils.py", line 650, in _locate\n    obj = import_module(mod)\n  File "/home/namvq/.pyenv/versions/3.10.6/lib/python3.10/importlib/__init__.py", line 126, in import_module\n    return _bootstrap._gcd_import(name[level:], package, level)\n  File "<frozen importlib._bootstrap>", line 1050, in _gcd_import\n  File "<frozen importlib._bootstrap>", line 1027, in _find_and_load\n  File "<frozen importlib._bootstrap>", line 1001, in _find_and_load_unlocked\nModuleNotFoundError: No module named \'niid_bench.models.CNN\'; \'niid_bench.models\' is not a package\n\nThe above exception was the direct cause of the following exception:\n\nTraceback (most recent call last):\n  File "/home/namvq/.cache/pypoetry/virtualenvs/niid-bench-orV17zke-py3.10/lib/python3.10/site-packages/hydra/_internal/instantiate/_instantiate2.py", line 134, in _resolve_target\n    target = _locate(target)\n  File "/home/namvq/.cache/pypoetry/virtualenvs/niid-bench-orV17zke-py3.10/lib/python3.10/site-packages/hydra/_internal/utils.py", line 653, in _locate\n    raise ImportError(\nImportError: Error loading \'niid_bench.models.CNN\':\nModuleNotFoundError("No module named \'niid_bench.models.CNN\'; \'niid_bench.models\' is not a package")\nAre you sure that \'CNN\' is importable from module \'niid_bench.models\'?\n\nThe above exception was the direct cause of the following exception:\n\nTraceback (most recent call last):\n  File "/home/namvq/.cache/pypoetry/virtualenvs/niid-bench-orV17zke-py3.10/lib/python3.10/site-packages/flwr/simulation/ray_transport/ray_actor.py", line 60, in run\n    job_results = job_fn()\n  File "/home/namvq/.cache/pypoetry/virtualenvs/niid-bench-orV17zke-py3.10/lib/python3.10/site-packages/flwr/simulation/ray_transport/ray_client_proxy.py", line 178, in get_parameters\n    client: Client = _create_client(self.client_fn, self.cid)\n  File "/home/namvq/.cache/pypoetry/virtualenvs/niid-bench-orV17zke-py3.10/lib/python3.10/site-packages/flwr/simulation/ray_transport/ray_client_proxy.py", line 284, in _create_client\n    client_like: ClientLike = client_fn(cid)\n  File "/media/namvq/Data/code_flwr/niid_bench/niid_bench/client_fednova.py", line 115, in client_fn\n    net = instantiate(model).to(device)\n  File "/home/namvq/.cache/pypoetry/virtualenvs/niid-bench-orV17zke-py3.10/lib/python3.10/site-packages/hydra/_internal/instantiate/_instantiate2.py", line 226, in instantiate\n    return instantiate_node(\n  File "/home/namvq/.cache/pypoetry/virtualenvs/niid-bench-orV17zke-py3.10/lib/python3.10/site-packages/hydra/_internal/instantiate/_instantiate2.py", line 333, in instantiate_node\n    _target_ = _resolve_target(node.get(_Keys.TARGET), full_key)\n  File "/home/namvq/.cache/pypoetry/virtualenvs/niid-bench-orV17zke-py3.10/lib/python3.10/site-packages/hydra/_internal/instantiate/_instantiate2.py", line 139, in _resolve_target\n    raise InstantiationException(msg) from e\nhydra.errors.InstantiationException: Error locating target \'niid_bench.models.CNN\', set env var HYDRA_FULL_ERROR=1 to see chained exception.\nfull_key: model\n',)

[2024-11-17 01:53:22,705][flwr][ERROR] - [36mray::DefaultActor.run()[39m (pid=139462, ip=192.168.1.29, actor_id=bfd5fa6f157822995390a57501000000, repr=<flwr.simulation.ray_transport.ray_actor.DefaultActor object at 0x7ecaa919eda0>)
  File "/home/namvq/.pyenv/versions/3.10.6/lib/python3.10/importlib/__init__.py", line 126, in import_module
    return _bootstrap._gcd_import(name[level:], package, level)
  File "<frozen importlib._bootstrap>", line 1050, in _gcd_import
  File "<frozen importlib._bootstrap>", line 1027, in _find_and_load
  File "<frozen importlib._bootstrap>", line 1001, in _find_and_load_unlocked
ModuleNotFoundError: No module named 'niid_bench.models.CNN'; 'niid_bench.models' is not a package

The above exception was the direct cause of the following exception:

[36mray::DefaultActor.run()[39m (pid=139462, ip=192.168.1.29, actor_id=bfd5fa6f157822995390a57501000000, repr=<flwr.simulation.ray_transport.ray_actor.DefaultActor object at 0x7ecaa919eda0>)
  File "/home/namvq/.cache/pypoetry/virtualenvs/niid-bench-orV17zke-py3.10/lib/python3.10/site-packages/hydra/_internal/instantiate/_instantiate2.py", line 134, in _resolve_target
    target = _locate(target)
  File "/home/namvq/.cache/pypoetry/virtualenvs/niid-bench-orV17zke-py3.10/lib/python3.10/site-packages/hydra/_internal/utils.py", line 653, in _locate
    raise ImportError(
ImportError: Error loading 'niid_bench.models.CNN':
ModuleNotFoundError("No module named 'niid_bench.models.CNN'; 'niid_bench.models' is not a package")
Are you sure that 'CNN' is importable from module 'niid_bench.models'?

The above exception was the direct cause of the following exception:

[36mray::DefaultActor.run()[39m (pid=139462, ip=192.168.1.29, actor_id=bfd5fa6f157822995390a57501000000, repr=<flwr.simulation.ray_transport.ray_actor.DefaultActor object at 0x7ecaa919eda0>)
  File "/home/namvq/.cache/pypoetry/virtualenvs/niid-bench-orV17zke-py3.10/lib/python3.10/site-packages/flwr/simulation/ray_transport/ray_actor.py", line 60, in run
    job_results = job_fn()
  File "/home/namvq/.cache/pypoetry/virtualenvs/niid-bench-orV17zke-py3.10/lib/python3.10/site-packages/flwr/simulation/ray_transport/ray_client_proxy.py", line 178, in get_parameters
    client: Client = _create_client(self.client_fn, self.cid)
  File "/home/namvq/.cache/pypoetry/virtualenvs/niid-bench-orV17zke-py3.10/lib/python3.10/site-packages/flwr/simulation/ray_transport/ray_client_proxy.py", line 284, in _create_client
    client_like: ClientLike = client_fn(cid)
  File "/media/namvq/Data/code_flwr/niid_bench/niid_bench/client_fednova.py", line 115, in client_fn
    net = instantiate(model).to(device)
  File "/home/namvq/.cache/pypoetry/virtualenvs/niid-bench-orV17zke-py3.10/lib/python3.10/site-packages/hydra/_internal/instantiate/_instantiate2.py", line 226, in instantiate
    return instantiate_node(
  File "/home/namvq/.cache/pypoetry/virtualenvs/niid-bench-orV17zke-py3.10/lib/python3.10/site-packages/hydra/_internal/instantiate/_instantiate2.py", line 333, in instantiate_node
    _target_ = _resolve_target(node.get(_Keys.TARGET), full_key)
  File "/home/namvq/.cache/pypoetry/virtualenvs/niid-bench-orV17zke-py3.10/lib/python3.10/site-packages/hydra/_internal/instantiate/_instantiate2.py", line 139, in _resolve_target
    raise InstantiationException(msg) from e
hydra.errors.InstantiationException: Error locating target 'niid_bench.models.CNN', set env var HYDRA_FULL_ERROR=1 to see chained exception.
full_key: model

The above exception was the direct cause of the following exception:

[36mray::DefaultActor.run()[39m (pid=139462, ip=192.168.1.29, actor_id=bfd5fa6f157822995390a57501000000, repr=<flwr.simulation.ray_transport.ray_actor.DefaultActor object at 0x7ecaa919eda0>)
  File "/home/namvq/.cache/pypoetry/virtualenvs/niid-bench-orV17zke-py3.10/lib/python3.10/site-packages/flwr/simulation/ray_transport/ray_actor.py", line 72, in run
    raise ClientException(str(message)) from ex
flwr.simulation.ray_transport.ray_actor.ClientException: 
>>>>>>>A ClientException occurred.('\n\tSomething went wrong when running your client workload.\n\tClient 9 crashed when the DefaultActor was running its workload.\n\tException triggered on the client side: Traceback (most recent call last):\n  File "/home/namvq/.cache/pypoetry/virtualenvs/niid-bench-orV17zke-py3.10/lib/python3.10/site-packages/hydra/_internal/utils.py", line 650, in _locate\n    obj = import_module(mod)\n  File "/home/namvq/.pyenv/versions/3.10.6/lib/python3.10/importlib/__init__.py", line 126, in import_module\n    return _bootstrap._gcd_import(name[level:], package, level)\n  File "<frozen importlib._bootstrap>", line 1050, in _gcd_import\n  File "<frozen importlib._bootstrap>", line 1027, in _find_and_load\n  File "<frozen importlib._bootstrap>", line 1001, in _find_and_load_unlocked\nModuleNotFoundError: No module named \'niid_bench.models.CNN\'; \'niid_bench.models\' is not a package\n\nThe above exception was the direct cause of the following exception:\n\nTraceback (most recent call last):\n  File "/home/namvq/.cache/pypoetry/virtualenvs/niid-bench-orV17zke-py3.10/lib/python3.10/site-packages/hydra/_internal/instantiate/_instantiate2.py", line 134, in _resolve_target\n    target = _locate(target)\n  File "/home/namvq/.cache/pypoetry/virtualenvs/niid-bench-orV17zke-py3.10/lib/python3.10/site-packages/hydra/_internal/utils.py", line 653, in _locate\n    raise ImportError(\nImportError: Error loading \'niid_bench.models.CNN\':\nModuleNotFoundError("No module named \'niid_bench.models.CNN\'; \'niid_bench.models\' is not a package")\nAre you sure that \'CNN\' is importable from module \'niid_bench.models\'?\n\nThe above exception was the direct cause of the following exception:\n\nTraceback (most recent call last):\n  File "/home/namvq/.cache/pypoetry/virtualenvs/niid-bench-orV17zke-py3.10/lib/python3.10/site-packages/flwr/simulation/ray_transport/ray_actor.py", line 60, in run\n    job_results = job_fn()\n  File "/home/namvq/.cache/pypoetry/virtualenvs/niid-bench-orV17zke-py3.10/lib/python3.10/site-packages/flwr/simulation/ray_transport/ray_client_proxy.py", line 178, in get_parameters\n    client: Client = _create_client(self.client_fn, self.cid)\n  File "/home/namvq/.cache/pypoetry/virtualenvs/niid-bench-orV17zke-py3.10/lib/python3.10/site-packages/flwr/simulation/ray_transport/ray_client_proxy.py", line 284, in _create_client\n    client_like: ClientLike = client_fn(cid)\n  File "/media/namvq/Data/code_flwr/niid_bench/niid_bench/client_fednova.py", line 115, in client_fn\n    net = instantiate(model).to(device)\n  File "/home/namvq/.cache/pypoetry/virtualenvs/niid-bench-orV17zke-py3.10/lib/python3.10/site-packages/hydra/_internal/instantiate/_instantiate2.py", line 226, in instantiate\n    return instantiate_node(\n  File "/home/namvq/.cache/pypoetry/virtualenvs/niid-bench-orV17zke-py3.10/lib/python3.10/site-packages/hydra/_internal/instantiate/_instantiate2.py", line 333, in instantiate_node\n    _target_ = _resolve_target(node.get(_Keys.TARGET), full_key)\n  File "/home/namvq/.cache/pypoetry/virtualenvs/niid-bench-orV17zke-py3.10/lib/python3.10/site-packages/hydra/_internal/instantiate/_instantiate2.py", line 139, in _resolve_target\n    raise InstantiationException(msg) from e\nhydra.errors.InstantiationException: Error locating target \'niid_bench.models.CNN\', set env var HYDRA_FULL_ERROR=1 to see chained exception.\nfull_key: model\n',)
[2024-11-17 01:53:22,705][flwr][ERROR] - [36mray::DefaultActor.run()[39m (pid=139462, ip=192.168.1.29, actor_id=bfd5fa6f157822995390a57501000000, repr=<flwr.simulation.ray_transport.ray_actor.DefaultActor object at 0x7ecaa919eda0>)
  File "/home/namvq/.pyenv/versions/3.10.6/lib/python3.10/importlib/__init__.py", line 126, in import_module
    return _bootstrap._gcd_import(name[level:], package, level)
  File "<frozen importlib._bootstrap>", line 1050, in _gcd_import
  File "<frozen importlib._bootstrap>", line 1027, in _find_and_load
  File "<frozen importlib._bootstrap>", line 1001, in _find_and_load_unlocked
ModuleNotFoundError: No module named 'niid_bench.models.CNN'; 'niid_bench.models' is not a package

The above exception was the direct cause of the following exception:

[36mray::DefaultActor.run()[39m (pid=139462, ip=192.168.1.29, actor_id=bfd5fa6f157822995390a57501000000, repr=<flwr.simulation.ray_transport.ray_actor.DefaultActor object at 0x7ecaa919eda0>)
  File "/home/namvq/.cache/pypoetry/virtualenvs/niid-bench-orV17zke-py3.10/lib/python3.10/site-packages/hydra/_internal/instantiate/_instantiate2.py", line 134, in _resolve_target
    target = _locate(target)
  File "/home/namvq/.cache/pypoetry/virtualenvs/niid-bench-orV17zke-py3.10/lib/python3.10/site-packages/hydra/_internal/utils.py", line 653, in _locate
    raise ImportError(
ImportError: Error loading 'niid_bench.models.CNN':
ModuleNotFoundError("No module named 'niid_bench.models.CNN'; 'niid_bench.models' is not a package")
Are you sure that 'CNN' is importable from module 'niid_bench.models'?

The above exception was the direct cause of the following exception:

[36mray::DefaultActor.run()[39m (pid=139462, ip=192.168.1.29, actor_id=bfd5fa6f157822995390a57501000000, repr=<flwr.simulation.ray_transport.ray_actor.DefaultActor object at 0x7ecaa919eda0>)
  File "/home/namvq/.cache/pypoetry/virtualenvs/niid-bench-orV17zke-py3.10/lib/python3.10/site-packages/flwr/simulation/ray_transport/ray_actor.py", line 60, in run
    job_results = job_fn()
  File "/home/namvq/.cache/pypoetry/virtualenvs/niid-bench-orV17zke-py3.10/lib/python3.10/site-packages/flwr/simulation/ray_transport/ray_client_proxy.py", line 178, in get_parameters
    client: Client = _create_client(self.client_fn, self.cid)
  File "/home/namvq/.cache/pypoetry/virtualenvs/niid-bench-orV17zke-py3.10/lib/python3.10/site-packages/flwr/simulation/ray_transport/ray_client_proxy.py", line 284, in _create_client
    client_like: ClientLike = client_fn(cid)
  File "/media/namvq/Data/code_flwr/niid_bench/niid_bench/client_fednova.py", line 115, in client_fn
    net = instantiate(model).to(device)
  File "/home/namvq/.cache/pypoetry/virtualenvs/niid-bench-orV17zke-py3.10/lib/python3.10/site-packages/hydra/_internal/instantiate/_instantiate2.py", line 226, in instantiate
    return instantiate_node(
  File "/home/namvq/.cache/pypoetry/virtualenvs/niid-bench-orV17zke-py3.10/lib/python3.10/site-packages/hydra/_internal/instantiate/_instantiate2.py", line 333, in instantiate_node
    _target_ = _resolve_target(node.get(_Keys.TARGET), full_key)
  File "/home/namvq/.cache/pypoetry/virtualenvs/niid-bench-orV17zke-py3.10/lib/python3.10/site-packages/hydra/_internal/instantiate/_instantiate2.py", line 139, in _resolve_target
    raise InstantiationException(msg) from e
hydra.errors.InstantiationException: Error locating target 'niid_bench.models.CNN', set env var HYDRA_FULL_ERROR=1 to see chained exception.
full_key: model

The above exception was the direct cause of the following exception:

[36mray::DefaultActor.run()[39m (pid=139462, ip=192.168.1.29, actor_id=bfd5fa6f157822995390a57501000000, repr=<flwr.simulation.ray_transport.ray_actor.DefaultActor object at 0x7ecaa919eda0>)
  File "/home/namvq/.cache/pypoetry/virtualenvs/niid-bench-orV17zke-py3.10/lib/python3.10/site-packages/flwr/simulation/ray_transport/ray_actor.py", line 72, in run
    raise ClientException(str(message)) from ex
flwr.simulation.ray_transport.ray_actor.ClientException: 
>>>>>>>A ClientException occurred.('\n\tSomething went wrong when running your client workload.\n\tClient 9 crashed when the DefaultActor was running its workload.\n\tException triggered on the client side: Traceback (most recent call last):\n  File "/home/namvq/.cache/pypoetry/virtualenvs/niid-bench-orV17zke-py3.10/lib/python3.10/site-packages/hydra/_internal/utils.py", line 650, in _locate\n    obj = import_module(mod)\n  File "/home/namvq/.pyenv/versions/3.10.6/lib/python3.10/importlib/__init__.py", line 126, in import_module\n    return _bootstrap._gcd_import(name[level:], package, level)\n  File "<frozen importlib._bootstrap>", line 1050, in _gcd_import\n  File "<frozen importlib._bootstrap>", line 1027, in _find_and_load\n  File "<frozen importlib._bootstrap>", line 1001, in _find_and_load_unlocked\nModuleNotFoundError: No module named \'niid_bench.models.CNN\'; \'niid_bench.models\' is not a package\n\nThe above exception was the direct cause of the following exception:\n\nTraceback (most recent call last):\n  File "/home/namvq/.cache/pypoetry/virtualenvs/niid-bench-orV17zke-py3.10/lib/python3.10/site-packages/hydra/_internal/instantiate/_instantiate2.py", line 134, in _resolve_target\n    target = _locate(target)\n  File "/home/namvq/.cache/pypoetry/virtualenvs/niid-bench-orV17zke-py3.10/lib/python3.10/site-packages/hydra/_internal/utils.py", line 653, in _locate\n    raise ImportError(\nImportError: Error loading \'niid_bench.models.CNN\':\nModuleNotFoundError("No module named \'niid_bench.models.CNN\'; \'niid_bench.models\' is not a package")\nAre you sure that \'CNN\' is importable from module \'niid_bench.models\'?\n\nThe above exception was the direct cause of the following exception:\n\nTraceback (most recent call last):\n  File "/home/namvq/.cache/pypoetry/virtualenvs/niid-bench-orV17zke-py3.10/lib/python3.10/site-packages/flwr/simulation/ray_transport/ray_actor.py", line 60, in run\n    job_results = job_fn()\n  File "/home/namvq/.cache/pypoetry/virtualenvs/niid-bench-orV17zke-py3.10/lib/python3.10/site-packages/flwr/simulation/ray_transport/ray_client_proxy.py", line 178, in get_parameters\n    client: Client = _create_client(self.client_fn, self.cid)\n  File "/home/namvq/.cache/pypoetry/virtualenvs/niid-bench-orV17zke-py3.10/lib/python3.10/site-packages/flwr/simulation/ray_transport/ray_client_proxy.py", line 284, in _create_client\n    client_like: ClientLike = client_fn(cid)\n  File "/media/namvq/Data/code_flwr/niid_bench/niid_bench/client_fednova.py", line 115, in client_fn\n    net = instantiate(model).to(device)\n  File "/home/namvq/.cache/pypoetry/virtualenvs/niid-bench-orV17zke-py3.10/lib/python3.10/site-packages/hydra/_internal/instantiate/_instantiate2.py", line 226, in instantiate\n    return instantiate_node(\n  File "/home/namvq/.cache/pypoetry/virtualenvs/niid-bench-orV17zke-py3.10/lib/python3.10/site-packages/hydra/_internal/instantiate/_instantiate2.py", line 333, in instantiate_node\n    _target_ = _resolve_target(node.get(_Keys.TARGET), full_key)\n  File "/home/namvq/.cache/pypoetry/virtualenvs/niid-bench-orV17zke-py3.10/lib/python3.10/site-packages/hydra/_internal/instantiate/_instantiate2.py", line 139, in _resolve_target\n    raise InstantiationException(msg) from e\nhydra.errors.InstantiationException: Error locating target \'niid_bench.models.CNN\', set env var HYDRA_FULL_ERROR=1 to see chained exception.\nfull_key: model\n',)
[2024-11-17 01:53:22,705][flwr][ERROR] - Your simulation crashed :(. This could be because of several reasons.The most common are: 
	 > Your system couldn't fit a single VirtualClient: try lowering `client_resources`.
	 > All the actors in your pool crashed. This could be because: 
		 - You clients hit an out-of-memory (OOM) error and actors couldn't recover from it. Try launching your simulation with more generous `client_resources` setting (i.e. it seems {'num_cpus': 4, 'num_gpus': 0.0} is not enough for your workload). Use fewer concurrent actors. 
		 - You were running a multi-node simulation and all worker nodes disconnected. The head node might still be alive but cannot accommodate any actor with resources: {'num_cpus': 4, 'num_gpus': 0.0}.
